Workbook

Sheet Summary
B1: No Vs111 FS | C1: No Vs111 CK | D1: No Vp111 FS | E1: No Vp111 CK | F1: No Vs100 FS | G1: No Vs100 CK | H1: No Vp100 FS | I1: No Vp100 CK | J1: Katahara 1979 | K1: Lenkkeri 1978 | L1: Greiner 1979
A2: C11 | B2: 240.68857 | C2: 240.7699 | D2: 240.81296 | E2: 240.99468 | F2: 240.78794 | G2: 240.92291 | H2: 235.2451 | I2: 236.49317 | J2: 230.9 | K2: 235.7 | L2: 235.89
A3: C12 | B3: 118.562 | C3: 118.60892 | D3: 125.02099 | E3: 125.17116 | F3: 122.91828 | G3: 122.9914 | H3: 120.00908 | I3: 120.75374 | J3: 120.02 | K3: 126.5 | L3: 120.76
A4: C44 | B4: 46.810575 | C4: 46.784777 | D4: 46.772536 | E4: 46.764877 | F4: 44.654454 | G4: 44.636918 | H4: 46.741586 | I4: 46.785207 | J4: 43.36 | K4: 43.6 | L4: 46.55
A5: C11' | B5: 5.4557566 | C5: 5.3557556 | D5: 5.3987483 | E5: 5.3083074 | F5: 5.4124572 | G5: 5.3235931 | H5: 5.8834438 | I5: 5.6166774 | J5: 5.65
A6: C12' | B6: 3.3289144 | C6: 3.2634976 | D6: 2.9006022 | E6: 2.8397931 | F6: 3.0316917 | G6: 2.9797998 | H6: 3.291741 | I6: 3.1320693 | J6: 3.566
A7: C44' | B7: 0.24950623 | C7: 0.25389862 | D7: 0.25718211 | E7: 0.25784735 | F7: 0.38546676 | G7: 0.38636279 | H7: 0.25780482 | I7: 0.25383641 | J7: 0.185
A9: All sumsq | B9: 2.2320965 | C9: 3.4005102 | D9: 1.2163311 | E9: 4.6925977 | F9: 1.0330482 | G9: 3.3664426 | H9: 0.62305048 | I9: 2.0863161
A10: P smsq | B10: 0.032047753 | C10: 0.24849359 | D10: 0.11286279 | E10: 0.17565705 | F10: 0.076281029 | G10: 0.19764435 | H10: 0.10102043 | I10: 0.24878189
A11: C11 smsq | B11: 0.65044919 | C11: 2.1684723 | D11: 0.26598059 | E11: 2.1907947 | F11: 0.12025488 | G11: 2.1832549 | H11: 0.13379478 | I11: 1.7155645
A12: C12 smsq | B12: 1.4999805 | C12: 0.93309414 | D12: 0.045780643 | E12: 2.2741652 | F12: 0.30345889 | G12: 0.51707785 | H12: 0.33250961 | I12: 0.071516193
A13: C44 smsq | B13: 0.04961909 | C13: 0.050450188 | D13: 0.79170705 | E13: 0.05198078 | F13: 0.53305345 | G13: 0.46846555 | H13: 0.055725655 | I13: 0.05045353

Sheet Cook updated
A1: V100 Pressure | B1: Oil P | C1: 2TP Au pressure corrected 111 | D1: 2TS Au pressure corrected 111 | E1: V100 Pressure | F1: 2TP Au 100 | G1: 2TS Au 100 high C44 | H1: L corrected v111 TP | I1: L correct v111 TS | J1: f(x) for cook Vp111-4/3C44 | K1: f(x) for cook C11+2/3C44-2pVs111 | L1: f(x) for cook Vp111-4/3C46 | M1: rect+triang | N1: Sum Cook (I) | O1: Cook's Length | P1: integ unc | Q1: trap uncert | R1: Trap add | S1: L uncert | T1: Volume | U1: V ncrt | V1: V/v0 | W1: v/v0 ncrt | X1: New density | Y1: rho ncrt | Z1: Strain | AA1: VP100 ncrt | AB1: VS100 ncrt | AC1: VP111 ncrt | AD1: VS111 ncrt | AE1: Vp 111 | AF1: Vp100 | AG1: Vs100 | AH1: pvs111^^2 | AI1: pvp111^2 | AJ1: C11 exp | AK1: C44 exp | AL1: C12 vp
A2: 0 | B2: 0 | C2: 0.21010882 | D2: 0.41441731 | E2: 0 | F2: 0.22919993 | G2: 0.51092692 | H2: =C2*$O$2/0.623 -> 0.24012437 | I2: =D2*$O$2/0.623 -> 0.47361979 | J2: =1/((1/(H2^2))-(1.33333333333333/(G2^2))) -> 0.08172952 | K2: =1/((-2/(I2^2))+(1/(F2^2))+(0.6666/(G2^2))) -> 0.078905675 | L2: =1/((0.33333333/(H2^2))-(1.33333333333333/(I2^2))+(0.66666666666667/(F2^2))) -> 0.079823938 | N2: =SUM(M2:$M$2) -> 0 | O2: =$B$38/((N2*$B$43+1)) -> 0.712 | P2: =(6*F2*G2*SQRT(9*(G2^6)*(0.0002^2)+16*(F2^6)*(0.0002)^2))/((4*F2^2 - 3*G2^2)^2) -> 0.00017248585 | Q2: =(((E2-E2)/2)^2)*(P2^2+P3^2) -> 0 | R2: =SUM(Q2:$Q$2) -> 0 | S2: 0.001 | T2: =O2^3 -> 0.36094413 | U2: =3*S2/O2*T2 -> 0.001520832 | V2: =T2/$T$2 -> 1 | W2: =V2*3*SQRT((S2/O2)^2)+(0.001/$O$2)^2 -> 0.0042154558 | X2: =$B$40/((O2/$O$2)^3) -> 6.09 | Y2: 0.01 | Z2: =(1-((X2/$B$40)^0.66666667))/2 -> 0 | AA2: =(SQRT((S2/O2)^2 + (0.0002/F2)^2))*AF2 -> 0.010273008 | AB2: =SQRT((S2/O2)^2 + (0.0002/G2)^2)*AG2 -> 0.0040636461 | AC2: =SQRT((S2/O2)^2 + (0.0002/H2)^2)*AE2 -> 0.0096834626 | AD2: =SQRT((S2/O2)^2 + (0.0002/I2)^2)*#REF! -> #REF! | AE2: =2*O2/H2 -> 5.9302602 | AF2: =2*O2/F2 -> 6.2129163 | AG2: =2*O2/G2 -> 2.7870914 | AH2: =X2*#REF!^2 -> #REF! | AI2: =X2*AE2*AE2 -> 214.17304 | AJ2: =X2*AF2^2 -> 235.076 | AK2: =X2*AG2^2 -> 47.306379 | AL2: =1.5*AI2-AJ2/2-2*AK2 -> 109.1088 | BR2: tttttttttttttttttttt | CR2: o | DK2: 0
A3: 0.12913291 | B3: 30 | C3: 0.2017768 | D3: 0.41395642 | E3: 0.12913291 | F3: 0.22474572 | G3: 0.50723365 | H3: =C3*$O$2/0.607 -> 0.23668053 | I3: =D3*$O$2/0.607 -> 0.48556338 | J3: =1/((1/(H3^2))-(1.33333333333333/(G3^2))) -> 0.07893153 | K3: =1/((-2/(I3^2))+(1/(F3^2))+(0.6666/(G3^2))) -> 0.071911808 | L3: =1/((0.33333333/(H3^2))-(1.33333333333333/(I3^2))+(0.66666666666667/(F3^2))) -> 0.074107797 | M3: =(J3*(E3-E2)+0.5*(E3-E2)*(J2-J3)) -> 0.010373314 | N3: =SUM(M$3:$M3) -> 0.010373314 | O3: =$B$38/((N3*$B$43+1)) -> 0.71179731 | P3: =(6*F3*G3*SQRT(9*(G3^6)*(0.0002^2)+16*(F3^6)*(0.0002)^2))/((4*F3^2 - 3*G3^2)^2) -> 0.00016605784 | Q3: =(((E3-E2)/2)^2)*(P3^2+P4^2) -> 2.216109e-10 | R3: =SUM(Q$2:$Q3) -> 2.216109e-10 | S3: =SQRT(((O30*0.001)^2)+((P30*0.02)^2)+((Q30*R3)^2)) -> 0.0010002847 | T3: =O3^3 -> 0.36063596 | U3: =3*S3/O3*T3 -> 0.001520399 | V3: =T3/$T$2 -> 0.99914623 | W3: =V3*3*SQRT((S3/O3)^2)+(0.001/$O$2)^2 -> 0.0042142561 | X3: =$B$40/((O3/$O$2)^3) -> 6.0952039 | Y3: =(SQRT((0.02/$X$2)^2+(9*(0.001/$O$2)^2)+(9*(S3/O3)^2))*X3) -> 0.04147975 | Z3: =(1-((X3/$B$40)^0.66666667))/2 -> -0.00028479391 | AA3: =(SQRT((S3/O3)^2 + (0.0002/F3)^2))*AF3 -> 0.010536127 | AB3: =SQRT((S3/O3)^2 + (0.0002/G3)^2)*AG3 -> 0.0040963855 | AC3: =SQRT((S3/O3)^2 + (0.0002/H3)^2)*AE3 -> 0.0098630706 | AD3: =SQRT((S3/O3)^2 + (0.0002/I3)^2)*#REF! -> #REF! | AE3: =2*O3/H3 -> 6.0148363 | AF3: =2*O3/F3 -> 6.3342458 | AG3: =2*O3/G3 -> 2.8065856 | AH3: =X3*#REF!^2 -> #REF! | AI3: =X3*AE3*AE3 -> 220.51384 | AJ3: =X3*AF3^2 -> 244.55585 | AK3: =X3*AG3^2 -> 48.011449 | AL3: =1.5*AI3-AJ3/2-2*AK3 -> 112.46994
A4: 1.6356835 | B4: 60 | C4: 0.19870445 | D4: 0.40424966 | E4: 1.6356835 | F4: 0.22094572 | G4: 0.50583365 | H4: =C4*$O$2/0.607 -> 0.23307672 | I4: =D4*$O$2/0.607 -> 0.47417753 | J4: =1/((1/(H4^2))-(1.33333333333333/(G4^2))) -> 0.075776026 | K4: =1/((-2/(I4^2))+(1/(F4^2))+(0.6666/(G4^2))) -> 0.070447974 | L4: =1/((0.33333333/(H4^2))-(1.33333333333333/(I4^2))+(0.66666666666667/(F4^2))) -> 0.072137838 | M4: =(J4*(E4-E3)+0.5*(E4-E3)*(J3-J4)) -> 0.11653738 | N4: =SUM(M$3:$M4) -> 0.12691069 | O4: =$B$38/((N4*$B$43+1)) -> 0.70952817 | P4: =(6*F4*G4*SQRT(9*(G4^6)*(0.0002^2)+16*(F4^6)*(0.0002)^2))/((4*F4^2 - 3*G4^2)^2) -> 0.00015994952 | Q4: =(((E4-E3)/2)^2)*(P4^2+P5^2) -> 2.8357893e-08 | R4: =SUM(Q$2:$Q4) -> 2.8579504e-08 | S4: =SQRT(((O31*0.001)^2)+((P31*0.02)^2)+((Q31*R4)^2)) -> 0.001003478 | T4: =O4^3 -> 0.35719792 | U4: =3*S4/O4*T4 -> 0.0015155435 | V4: =T4/$T$2 -> 0.98962109 | W4: =V4*3*SQRT((S4/O4)^2)+(0.001/$O$2)^2 -> 0.0042008039 | X4: =$B$40/((O4/$O$2)^3) -> 6.1538705 | Y4: =(SQRT((0.02/$X$2)^2+(9*(0.001/$O$2)^2)+(9*(S4/O4)^2))*X4) -> 0.041982071 | Z4: =(1-((X4/$B$40)^0.66666667))/2 -> -0.0034898389 | AA4: =(SQRT((S4/O4)^2 + (0.0002/F4)^2))*AF4 -> 0.010784694 | AB4: =SQRT((S4/O4)^2 + (0.0002/G4)^2)*AG4 -> 0.0041197529 | AC4: =SQRT((S4/O4)^2 + (0.0002/H4)^2)*AE4 -> 0.010071649 | AD4: =SQRT((S4/O4)^2 + (0.0002/I4)^2)*#REF! -> #REF! | AE4: =2*O4/H4 -> 6.0883657 | AF4: =2*O4/F4 -> 6.4226469 | AG4: =2*O4/G4 -> 2.8053815 | AH4: =X4*#REF!^2 -> #REF! | AI4: =X4*AE4*AE4 -> 228.11288 | AJ4: =X4*AF4^2 -> 253.84957 | AK4: =X4*AG4^2 -> 48.431977 | AL4: =1.5*AI4-AJ4/2-2*AK4 -> 118.38059
A5: 2.4965696 | B5: 90 | C5: 0.19712307 | D5: 0.40093724 | E5: 2.4965696 | F5: 0.21874572 | G5: 0.50583365 | H5: =C5*$O$2/0.607 -> 0.23122179 | I5: =D5*$O$2/0.607 -> 0.47029212 | J5: =1/((1/(H5^2))-(1.33333333333333/(G5^2))) -> 0.074110757 | K5: =1/((-2/(I5^2))+(1/(F5^2))+(0.6666/(G5^2))) -> 0.069149582 | L5: =1/((0.33333333/(H5^2))-(1.33333333333333/(I5^2))+(0.66666666666667/(F5^2))) -> 0.070726951 | M5: =(J5*(E5-E4)+0.5*(E5-E4)*(J4-J5)) -> 0.06451772 | N5: =SUM(M$3:$M5) -> 0.19142842 | O5: =$B$38/((N5*$B$43+1)) -> 0.70827813 | P5: =(6*F5*G5*SQRT(9*(G5^6)*(0.0002^2)+16*(F5^6)*(0.0002)^2))/((4*F5^2 - 3*G5^2)^2) -> 0.00015618171 | Q5: =(((E5-E4)/2)^2)*(P5^2+P6^2) -> 8.8434243e-09 | R5: =SUM(Q$2:$Q5) -> 3.7422929e-08 | S5: =SQRT(((O32*0.001)^2)+((P32*0.02)^2)+((Q32*R5)^2)) -> 0.0010052414 | T5: =O5^3 -> 0.35531332 | U5: =3*S5/O5*T5 -> 0.0015128619 | V5: =T5/$T$2 -> 0.98439978 | W5: =V5*3*SQRT((S5/O5)^2)+(0.001/$O$2)^2 -> 0.0041933745 | X5: =$B$40/((O5/$O$2)^3) -> 6.1865109 | Y5: =(SQRT((0.02/$X$2)^2+(9*(0.001/$O$2)^2)+(9*(S5/O5)^2))*X5) -> 0.042262358 | Z5: =(1-((X5/$B$40)^0.66666667))/2 -> -0.0052686252 | AA5: =(SQRT((S5/O5)^2 + (0.0002/F5)^2))*AF5 -> 0.010932991 | AB5: =SQRT((S5/O5)^2 + (0.0002/G5)^2)*AG5 -> 0.0041259431 | AC5: =SQRT((S5/O5)^2 + (0.0002/H5)^2)*AE5 -> 0.01018257 | AD5: =SQRT((S5/O5)^2 + (0.0002/I5)^2)*#REF! -> #REF! | AE5: =2*O5/H5 -> 6.1263961 | AF5: =2*O5/F5 -> 6.4758124 | AG5: =2*O5/G5 -> 2.800439 | AH5: =X5*#REF!^2 -> #REF! | AI5: =X5*AE5*AE5 -> 232.19664 | AJ5: =X5*AF5^2 -> 259.43843 | AK5: =X5*AG5^2 -> 48.517454 | AL5: =1.5*AI5-AJ5/2-2*AK5 -> 121.54084
A6: 3.4435442 | B6: 120 | C6: 0.19552144 | D6: 0.39786989 | E6: 3.4435442 | F6: 0.21654572 | G6: 0.50523365 | H6: =C6*$O$2/0.607 -> 0.22934311 | I6: =D6*$O$2/0.607 -> 0.46669417 | J6: =1/((1/(H6^2))-(1.33333333333333/(G6^2))) -> 0.072523552 | K6: =1/((-2/(I6^2))+(1/(F6^2))+(0.6666/(G6^2))) -> 0.067776252 | L6: =1/((0.33333333/(H6^2))-(1.33333333333333/(I6^2))+(0.66666666666667/(F6^2))) -> 0.069287253 | M6: =(J6*(E6-E5)+0.5*(E6-E5)*(J5-J6)) -> 0.069429487 | N6: =SUM(M$3:$M6) -> 0.2608579 | O6: =$B$38/((N6*$B$43+1)) -> 0.70693783 | P6: =(6*F6*G6*SQRT(9*(G6^6)*(0.0002^2)+16*(F6^6)*(0.0002)^2))/((4*F6^2 - 3*G6^2)^2) -> 0.00015276458 | Q6: =(((E6-E5)/2)^2)*(P6^2+P7^2) -> 1.0265501e-08 | R6: =SUM(Q$2:$Q6) -> 4.768843e-08 | S6: =SQRT(((O33*0.001)^2)+((P33*0.02)^2)+((Q33*R6)^2)) -> 0.0010071351 | T6: =O6^3 -> 0.35330003 | U6: =3*S6/O6*T6 -> 0.0015099808 | V6: =T6/$T$2 -> 0.97882193 | W6: =V6*3*SQRT((S6/O6)^2)+(0.001/$O$2)^2 -> 0.0041853924 | X6: =$B$40/((O6/$O$2)^3) -> 6.221765 | Y6: =(SQRT((0.02/$X$2)^2+(9*(0.001/$O$2)^2)+(9*(S6/O6)^2))*X6) -> 0.04256573 | Z6: =(1-((X6/$B$40)^0.66666667))/2 -> -0.0071863352 | AA6: =(SQRT((S6/O6)^2 + (0.0002/F6)^2))*AF6 -> 0.01108553 | AB6: =SQRT((S6/O6)^2 + (0.0002/G6)^2)*AG6 -> 0.0041378548 | AC6: =SQRT((S6/O6)^2 + (0.0002/H6)^2)*AE6 -> 0.010297573 | AD6: =SQRT((S6/O6)^2 + (0.0002/I6)^2)*#REF! -> #REF! | AE6: =2*O6/H6 -> 6.1648927 | AF6: =2*O6/F6 -> 6.5292247 | AG6: =2*O6/G6 -> 2.798459 | AH6: =X6*#REF!^2 -> #REF! | AI6: =X6*AE6*AE6 -> 236.46379 | AJ6: =X6*AF6^2 -> 265.23866 | AK6: =X6*AG6^2 -> 48.724962 | AL6: =1.5*AI6-AJ6/2-2*AK6 -> 124.62643
A7: 4.4335632 | B7: 150 | C7: 0.19396667 | D7: 0.39485534 | E7: 4.4335632 | F7: 0.21474572 | G7: 0.50523365 | H7: =C7*$O$2/0.607 -> 0.22751939 | I7: =D7*$O$2/0.607 -> 0.46315816 | J7: =1/((1/(H7^2))-(1.33333333333333/(G7^2))) -> 0.070948991 | K7: =1/((-2/(I7^2))+(1/(F7^2))+(0.6666/(G7^2))) -> 0.066788286 | L7: =1/((0.33333333/(H7^2))-(1.33333333333333/(I7^2))+(0.66666666666667/(F7^2))) -> 0.068119077 | M7: =(J7*(E7-E6)+0.5*(E7-E6)*(J6-J7)) -> 0.071020269 | N7: =SUM(M$3:$M7) -> 0.33187817 | O7: =$B$38/((N7*$B$43+1)) -> 0.70557207 | P7: =(6*F7*G7*SQRT(9*(G7^6)*(0.0002^2)+16*(F7^6)*(0.0002)^2))/((4*F7^2 - 3*G7^2)^2) -> 0.00014984065 | Q7: =(((E7-E6)/2)^2)*(P7^2+P8^2) -> 1.0840844e-08 | R7: =SUM(Q$2:$Q7) -> 5.8529274e-08 | S7: =SQRT(((O34*0.001)^2)+((P34*0.02)^2)+((Q34*R7)^2)) -> 0.0010090676 | T7: =O7^3 -> 0.35125631 | U7: =3*S7/O7*T7 -> 0.0015070383 | V7: =T7/$T$2 -> 0.97315979 | W7: =V7*3*SQRT((S7/O7)^2)+(0.001/$O$2)^2 -> 0.0041772401 | X7: =$B$40/((O7/$O$2)^3) -> 6.2579651 | Y7: =(SQRT((0.02/$X$2)^2+(9*(0.001/$O$2)^2)+(9*(S7/O7)^2))*X7) -> 0.042877933 | Z7: =(1-((X7/$B$40)^0.66666667))/2 -> -0.0091517424 | AA7: =(SQRT((S7/O7)^2 + (0.0002/F7)^2))*AF7 -> 0.011214857 | AB7: =SQRT((S7/O7)^2 + (0.0002/G7)^2)*AG7 -> 0.0041446547 | AC7: =SQRT((S7/O7)^2 + (0.0002/H7)^2)*AE7 -> 0.01041179 | AD7: =SQRT((S7/O7)^2 + (0.0002/I7)^2)*#REF! -> #REF! | AE7: =2*O7/H7 -> 6.2023026 | AF7: =2*O7/F7 -> 6.5712329 | AG7: =2*O7/G7 -> 2.7930526 | AH7: =X7*#REF!^2 -> #REF! | AI7: =X7*AE7*AE7 -> 240.73489 | AJ7: =X7*AF7^2 -> 270.22583 | AK7: =X7*AG7^2 -> 48.819278 | AL7: =1.5*AI7-AJ7/2-2*AK7 -> 128.35087
A8: 5.122272 | B8: 180 | C8: 0.19293671 | D8: 0.3928225 | E8: 5.122272 | F8: 0.21334572 | G8: 0.50523365 | H8: =C8*$O$2/0.607 -> 0.22631127 | I8: =D8*$O$2/0.607 -> 0.46077367 | J8: =1/((1/(H8^2))-(1.33333333333333/(G8^2))) -> 0.069923047 | K8: =1/((-2/(I8^2))+(1/(F8^2))+(0.6666/(G8^2))) -> 0.065956677 | L8: =1/((0.33333333/(H8^2))-(1.33333333333333/(I8^2))+(0.66666666666667/(F8^2))) -> 0.067227052 | M8: =(J8*(E8-E7)+0.5*(E8-E7)*(J7-J8)) -> 0.048509909 | N8: =SUM(M$3:$M8) -> 0.38038808 | O8: =$B$38/((N8*$B$43+1)) -> 0.70464222 | P8: =(6*F8*G8*SQRT(9*(G8^6)*(0.0002^2)+16*(F8^6)*(0.0002)^2))/((4*F8^2 - 3*G8^2)^2) -> 0.00014761407 | Q8: =(((E8-E7)/2)^2)*(P8^2+P9^2) -> 5.0935318e-09 | R8: =SUM(Q$2:$Q8) -> 6.3622806e-08 | S8: =SQRT(((O35*0.001)^2)+((P35*0.02)^2)+((Q35*R8)^2)) -> 0.0010103849 | T8: =O8^3 -> 0.34986942 | U8: =3*S8/O8*T8 -> 0.0015050309 | V8: =T8/$T$2 -> 0.96931738 | W8: =V8*3*SQRT((S8/O8)^2)+(0.001/$O$2)^2 -> 0.0041716785 | X8: =$B$40/((O8/$O$2)^3) -> 6.2827719 | Y8: =(SQRT((0.02/$X$2)^2+(9*(0.001/$O$2)^2)+(9*(S8/O8)^2))*X8) -> 0.043092275 | Z8: =(1-((X8/$B$40)^0.66666667))/2 -> -0.010496385 | AA8: =(SQRT((S8/O8)^2 + (0.0002/F8)^2))*AF8 -> 0.011316416 | AB8: =SQRT((S8/O8)^2 + (0.0002/G8)^2)*AG8 -> 0.0041492923 | AC8: =SQRT((S8/O8)^2 + (0.0002/H8)^2)*AE8 -> 0.010488816 | AD8: =SQRT((S8/O8)^2 + (0.0002/I8)^2)*#REF! -> #REF! | AE8: =2*O8/H8 -> 6.2271952 | AF8: =2*O8/F8 -> 6.6056373 | AG8: =2*O8/G8 -> 2.7893717 | AH8: =X8*#REF!^2 -> #REF! | AI8: =X8*AE8*AE8 -> 243.63308 | AJ8: =X8*AF8^2 -> 274.14526 | AK8: =X8*AG8^2 -> 48.8837 | AL8: =1.5*AI8-AJ8/2-2*AK8 -> 130.60959
A9: 5.7679366 | B9: 210 | C9: 0.1919993 | D9: 0.39099582 | E9: 5.7679366 | F9: 0.21174572 | G9: 0.50423365 | H9: =C9*$O$2/0.607 -> 0.2252117 | I9: =D9*$O$2/0.607 -> 0.45863102 | J9: =1/((1/(H9^2))-(1.33333333333333/(G9^2))) -> 0.06909982 | K9: =1/((-2/(I9^2))+(1/(F9^2))+(0.6666/(G9^2))) -> 0.064863932 | L9: =1/((0.33333333/(H9^2))-(1.33333333333333/(I9^2))+(0.66666666666667/(F9^2))) -> 0.066216222 | M9: =(J9*(E9-E8)+0.5*(E9-E8)*(J8-J9)) -> 0.044881068 | N9: =SUM(M$3:$M9) -> 0.42526915 | O9: =$B$38/((N9*$B$43+1)) -> 0.70378411 | P9: =(6*F9*G9*SQRT(9*(G9^6)*(0.0002^2)+16*(F9^6)*(0.0002)^2))/((4*F9^2 - 3*G9^2)^2) -> 0.00014548021 | Q9: =(((E9-E8)/2)^2)*(P9^2+P10^2) -> 4.3650511e-09 | R9: =SUM(Q$2:$Q9) -> 6.7987857e-08 | S9: =SQRT(((O36*0.001)^2)+((P36*0.02)^2)+((Q36*R9)^2)) -> 0.0010116014 | T9: =O9^3 -> 0.34859277 | U9: =3*S9/O9*T9 -> 0.0015031752 | V9: =T9/$T$2 -> 0.9657804 | W9: =V9*3*SQRT((S9/O9)^2)+(0.001/$O$2)^2 -> 0.0041665375 | X9: =$B$40/((O9/$O$2)^3) -> 6.3057813 | Y9: =(SQRT((0.02/$X$2)^2+(9*(0.001/$O$2)^2)+(9*(S9/O9)^2))*X9) -> 0.043291374 | Z9: =(1-((X9/$B$40)^0.66666667))/2 -> -0.011742019 | AA9: =(SQRT((S9/O9)^2 + (0.0002/F9)^2))*AF9 -> 0.011433184 | AB9: =SQRT((S9/O9)^2 + (0.0002/G9)^2)*AG9 -> 0.0041623974 | AC9: =SQRT((S9/O9)^2 + (0.0002/H9)^2)*AE9 -> 0.010559846 | AD9: =SQRT((S9/O9)^2 + (0.0002/I9)^2)*#REF! -> #REF! | AE9: =2*O9/H9 -> 6.2499782 | AF9: =2*O9/F9 -> 6.6474459 | AG9: =2*O9/G9 -> 2.7915 | AH9: =X9*#REF!^2 -> #REF! | AI9: =X9*AE9*AE9 -> 246.31786 | AJ9: =X9*AF9^2 -> 278.64325 | AK9: =X9*AG9^2 -> 49.137625 | AL9: =1.5*AI9-AJ9/2-2*AK9 -> 131.87991
A10: 6.5857783 | B10: 240 | C10: 0.19084422 | D10: 0.38885471 | E10: 6.5857783 | F10: 0.21074572 | G10: 0.50423365 | H10: =C10*$O$2/0.607 -> 0.22385681 | I10: =D10*$O$2/0.607 -> 0.45611952 | J10: =1/((1/(H10^2))-(1.33333333333333/(G10^2))) -> 0.067975417 | K10: =1/((-2/(I10^2))+(1/(F10^2))+(0.6666/(G10^2))) -> 0.064416162 | L10: =1/((0.33333333/(H10^2))-(1.33333333333333/(I10^2))+(0.66666666666667/(F10^2))) -> 0.065559679 | M10: =(J10*(E10-E9)+0.5*(E10-E9)*(J9-J10)) -> 0.056052926 | N10: =SUM(M$3:$M10) -> 0.48132207 | O10: =$B$38/((N10*$B$43+1)) -> 0.70271533 | P10: =(6*F10*G10*SQRT(9*(G10^6)*(0.0002^2)+16*(F10^6)*(0.0002)^2))/((4*F10^2 - 3*G10^2)^2) -> 0.00014393848 | Q10: =(((E10-E9)/2)^2)*(P10^2+P11^2) -> 6.8066341e-09 | R10: =SUM(Q$2:$Q10) -> 7.4794491e-08 | S10: =SQRT(((O37*0.001)^2)+((P37*0.02)^2)+((Q37*R10)^2)) -> 0.0010131179 | T10: =O10^3 -> 0.34700704 | U10: =3*S10/O10*T10 -> 0.0015008597 | V10: =T10/$T$2 -> 0.96138712 | W10: =V10*3*SQRT((S10/O10)^2)+(0.001/$O$2)^2 -> 0.0041601223 | X10: =$B$40/((O10/$O$2)^3) -> 6.334597 | Y10: =(SQRT((0.02/$X$2)^2+(9*(0.001/$O$2)^2)+(9*(S10/O10)^2))*X10) -> 0.043541105 | Z10: =(1-((X10/$B$40)^0.66666667))/2 -> -0.01329985 | AA10: =(SQRT((S10/O10)^2 + (0.0002/F10)^2))*AF10 -> 0.011510619 | AB10: =SQRT((S10/O10)^2 + (0.0002/G10)^2)*AG10 -> 0.0041677496 | AC10: =SQRT((S10/O10)^2 + (0.0002/H10)^2)*AE10 -> 0.010648574 | AD10: =SQRT((S10/O10)^2 + (0.0002/I10)^2)*#REF! -> #REF! | AE10: =2*O10/H10 -> 6.2782572 | AF10: =2*O10/F10 -> 6.6688456 | AG10: =2*O10/G10 -> 2.7872608 | AH10: =X10*#REF!^2 -> #REF! | AI10: =X10*AE10*AE10 -> 249.68773 | AJ10: =X10*AF10^2 -> 281.72171 | AK10: =X10*AG10^2 -> 49.21236 | AL10: =1.5*AI10-AJ10/2-2*AK10 -> 135.24602
A11: 7.2744872 | B11: 270 | C11: 0.18989876 | D11: 0.38724285 | E11: 7.2744872 | F11: 0.20914572 | G11: 0.50463365 | H11: =C11*$O$2/0.607 -> 0.2227478 | I11: =D11*$O$2/0.607 -> 0.45422884 | J11: =1/((1/(H11^2))-(1.33333333333333/(G11^2))) -> 0.067029912 | K11: =1/((-2/(I11^2))+(1/(F11^2))+(0.6666/(G11^2))) -> 0.063349206 | L11: =1/((0.33333333/(H11^2))-(1.33333333333333/(I11^2))+(0.66666666666667/(F11^2))) -> 0.06452963 | M11: =(J11*(E11-E10)+0.5*(E11-E10)*(J10-J11)) -> 0.046489682 | N11: =SUM(M$3:$M11) -> 0.52781176 | O11: =$B$38/((N11*$B$43+1)) -> 0.70183135 | P11: =(6*F11*G11*SQRT(9*(G11^6)*(0.0002^2)+16*(F11^6)*(0.0002)^2))/((4*F11^2 - 3*G11^2)^2) -> 0.00014137639 | Q11: =(((E11-E10)/2)^2)*(P11^2+P12^2) -> 4.6994312e-09 | R11: =SUM(Q$2:$Q11) -> 7.9493922e-08 | S11: =SQRT(((O38*0.001)^2)+((P38*0.02)^2)+((Q38*R11)^2)) -> 0.0010143731 | T11: =O11^3 -> 0.34569914 | U11: =3*S11/O11*T11 -> 0.0014989409 | V11: =T11/$T$2 -> 0.95776358 | W11: =V11*3*SQRT((S11/O11)^2)+(0.001/$O$2)^2 -> 0.0041548061 | X11: =$B$40/((O11/$O$2)^3) -> 6.358563 | Y11: =(SQRT((0.02/$X$2)^2+(9*(0.001/$O$2)^2)+(9*(S11/O11)^2))*X11) -> 0.043749132 | Z11: =(1-((X11/$B$40)^0.66666667))/2 -> -0.014593694 | AA11: =(SQRT((S11/O11)^2 + (0.0002/F11)^2))*AF11 -> 0.011631114 | AB11: =SQRT((S11/O11)^2 + (0.0002/G11)^2)*AG11 -> 0.0041686433 | AC11: =SQRT((S11/O11)^2 + (0.0002/H11)^2)*AE11 -> 0.010722207 | AD11: =SQRT((S11/O11)^2 + (0.0002/I11)^2)*#REF! -> #REF! | AE11: =2*O11/H11 -> 6.3015783 | AF11: =2*O11/F11 -> 6.7114101 | AG11: =2*O11/G11 -> 2.781548 | AH11: =X11*#REF!^2 -> #REF! | AI11: =X11*AE11*AE11 -> 252.49783 | AJ11: =X11*AF11^2 -> 286.40892 | AK11: =X11*AG11^2 -> 49.19626 | AL11: =1.5*AI11-AJ11/2-2*AK11 -> 137.14977
A12: 7.8340631 | B12: 300 | C12: 0.18915085 | D12: 0.3860701 | E12: 7.8340631 | F12: 0.20814572 | G12: 0.50383365 | H12: =C12*$O$2/0.607 -> 0.22187052 | I12: =D12*$O$2/0.607 -> 0.45285323 | J12: =1/((1/(H12^2))-(1.33333333333333/(G12^2))) -> 0.066393261 | K12: =1/((-2/(I12^2))+(1/(F12^2))+(0.6666/(G12^2))) -> 0.062676078 | L12: =1/((0.33333333/(H12^2))-(1.33333333333333/(I12^2))+(0.66666666666667/(F12^2))) -> 0.063867298 | M12: =(J12*(E12-E11)+0.5*(E12-E11)*(J11-J12)) -> 0.037330198 | N12: =SUM(M$3:$M12) -> 0.56514196 | O12: =$B$38/((N12*$B$43+1)) -> 0.70112315 | P12: =(6*F12*G12*SQRT(9*(G12^6)*(0.0002^2)+16*(F12^6)*(0.0002)^2))/((4*F12^2 - 3*G12^2)^2) -> 0.00014015569 | Q12: =(((E12-E11)/2)^2)*(P12^2+P13^2) -> 3.0482081e-09 | R12: =SUM(Q$2:$Q12) -> 8.254213e-08 | S12: =SQRT(((O39*0.001)^2)+((P39*0.02)^2)+((Q39*R12)^2)) -> 0.0010153792 | T12: =O12^3 -> 0.34465368 | U12: =3*S12/O12*T12 -> 0.0014974011 | V12: =T12/$T$2 -> 0.95486712 | W12: =V12*3*SQRT((S12/O12)^2)+(0.001/$O$2)^2 -> 0.0041505401 | X12: =$B$40/((O12/$O$2)^3) -> 6.3778508 | Y12: =(SQRT((0.02/$X$2)^2+(9*(0.001/$O$2)^2)+(9*(S12/O12)^2))*X12) -> 0.043916767 | Z12: =(1-((X12/$B$40)^0.66666667))/2 -> -0.015633801 | AA12: =(SQRT((S12/O12)^2 + (0.0002/F12)^2))*AF12 -> 0.011708554 | AB12: =SQRT((S12/O12)^2 + (0.0002/G12)^2)*AG12 -> 0.0041792826 | AC12: =SQRT((S12/O12)^2 + (0.0002/H12)^2)*AE12 -> 0.010781127 | AD12: =SQRT((S12/O12)^2 + (0.0002/I12)^2)*#REF! -> #REF! | AE12: =2*O12/H12 -> 6.3201108 | AF12: =2*O12/F12 -> 6.7368491 | AG12: =2*O12/G12 -> 2.7831533 | AH12: =X12*#REF!^2 -> #REF! | AI12: =X12*AE12*AE12 -> 254.7556 | AJ12: =X12*AF12^2 -> 289.45962 | AK12: =X12*AG12^2 -> 49.402466 | AL12: =1.5*AI12-AJ12/2-2*AK12 -> 138.59866
A13: 8.5227719 | B13: 330 | C13: 0.18825875 | D13: 0.38477686 | E13: 8.5227719 | F13: 0.20734572 | G13: 0.50403365 | H13: =C13*$O$2/0.607 -> 0.2208241 | I13: =D13*$O$2/0.607 -> 0.45133628 | J13: =1/((1/(H13^2))-(1.33333333333333/(G13^2))) -> 0.065535439 | K13: =1/((-2/(I13^2))+(1/(F13^2))+(0.6666/(G13^2))) -> 0.062244196 | L13: =1/((0.33333333/(H13^2))-(1.33333333333333/(I13^2))+(0.66666666666667/(F13^2))) -> 0.06330322 | M13: =(J13*(E13-E12)+0.5*(E13-E12)*(J12-J13)) -> 0.045430231 | N13: =SUM(M$3:$M13) -> 0.61057219 | O13: =$B$38/((N13*$B$43+1)) -> 0.7002632 | P13: =(6*F13*G13*SQRT(9*(G13^6)*(0.0002^2)+16*(F13^6)*(0.0002)^2))/((4*F13^2 - 3*G13^2)^2) -> 0.00013890838 | Q13: =(((E13-E12)/2)^2)*(P13^2+P14^2) -> 4.5241559e-09 | R13: =SUM(Q$2:$Q13) -> 8.7066286e-08 | S13: =SQRT(((O40*0.001)^2)+((P40*0.02)^2)+((Q40*R13)^2)) -> 0.0010166015 | T13: =O13^3 -> 0.34338705 | U13: =3*S13/O13*T13 -> 0.0014955282 | V13: =T13/$T$2 -> 0.95135791 | W13: =V13*3*SQRT((S13/O13)^2)+(0.001/$O$2)^2 -> 0.0041453513 | X13: =$B$40/((O13/$O$2)^3) -> 6.4013763 | Y13: =(SQRT((0.02/$X$2)^2+(9*(0.001/$O$2)^2)+(9*(S13/O13)^2))*X13) -> 0.04412149 | Z13: =(1-((X13/$B$40)^0.66666667))/2 -> -0.016901011 | AA13: =(SQRT((S13/O13)^2 + (0.0002/F13)^2))*AF13 -> 0.011772994 | AB13: =SQRT((S13/O13)^2 + (0.0002/G13)^2)*AG13 -> 0.0041818291 | AC13: =SQRT((S13/O13)^2 + (0.0002/H13)^2)*AE13 -> 0.010852225 | AD13: =SQRT((S13/O13)^2 + (0.0002/I13)^2)*#REF! -> #REF! | AE13: =2*O13/H13 -> 6.3422714 | AF13: =2*O13/F13 -> 6.754547 | AG13: =2*O13/G13 -> 2.7786367 | AH13: =X13*#REF!^2 -> #REF! | AI13: =X13*AE13*AE13 -> 257.49156 | AJ13: =X13*AF13^2 -> 292.05578 | AK13: =X13*AG13^2 -> 49.423888 | AL13: =1.5*AI13-AJ13/2-2*AK13 -> 141.36168
A14: 9.1253922 | B14: 360 | C14: 0.18750572 | D14: 0.38374368 | E14: 9.1253922 | F14: 0.20634572 | G14: 0.50443365 | H14: =C14*$O$2/0.607 -> 0.21994081 | I14: =D14*$O$2/0.607 -> 0.45012438 | J14: =1/((1/(H14^2))-(1.33333333333333/(G14^2))) -> 0.064799211 | K14: =1/((-2/(I14^2))+(1/(F14^2))+(0.6666/(G14^2))) -> 0.06159665 | L14: =1/((0.33333333/(H14^2))-(1.33333333333333/(I14^2))+(0.66666666666667/(F14^2))) -> 0.062627723 | M14: =(J14*(E14-E13)+0.5*(E14-E13)*(J13-J14)) -> 0.039271149 | N14: =SUM(M$3:$M14) -> 0.64984334 | O14: =$B$38/((N14*$B$43+1)) -> 0.69952154 | P14: =(6*F14*G14*SQRT(9*(G14^6)*(0.0002^2)+16*(F14^6)*(0.0002)^2))/((4*F14^2 - 3*G14^2)^2) -> 0.00013732168 | Q14: =(((E14-E13)/2)^2)*(P14^2+P15^2) -> 3.4000951e-09 | R14: =SUM(Q$2:$Q14) -> 9.0466381e-08 | S14: =SQRT(((O41*0.001)^2)+((P41*0.02)^2)+((Q41*R14)^2)) -> 0.0010176561 | T14: =O14^3 -> 0.34229714 | U14: =3*S14/O14*T14 -> 0.0014939102 | V14: =T14/$T$2 -> 0.9483383 | W14: =V14*3*SQRT((S14/O14)^2)+(0.001/$O$2)^2 -> 0.0041408685 | X14: =$B$40/((O14/$O$2)^3) -> 6.421759 | Y14: =(SQRT((0.02/$X$2)^2+(9*(0.001/$O$2)^2)+(9*(S14/O14)^2))*X14) -> 0.044299091 | Z14: =(1-((X14/$B$40)^0.66666667))/2 -> -0.017997676 | AA14: =(SQRT((S14/O14)^2 + (0.0002/F14)^2))*AF14 -> 0.011852274 | AB14: =SQRT((S14/O14)^2 + (0.0002/G14)^2)*AG14 -> 0.0041820099 | AC14: =SQRT((S14/O14)^2 + (0.0002/H14)^2)*AE14 -> 0.010912962 | AD14: =SQRT((S14/O14)^2 + (0.0002/I14)^2)*#REF! -> #REF! | AE14: =2*O14/H14 -> 6.3609981 | AF14: =2*O14/F14 -> 6.7800925 | AG14: =2*O14/G14 -> 2.7734928 | AH14: =X14*#REF!^2 -> #REF! | AI14: =X14*AE14*AE14 -> 259.83912 | AJ14: =X14*AF14^2 -> 295.20604 | AK14: =X14*AG14^2 -> 49.397854 | AL14: =1.5*AI14-AJ14/2-2*AK14 -> 143.35994
... A23: 12.482848 | B23: 630 | C23: 0.18327563 | D23: 0.377551 | E23: 12.482848 | F23: 0.19974572 | G23: 0.50683365 | H23: =C23*$O$2/0.607 -> 0.21497899 | I23: =D23*$O$2/0.607 -> 0.44286048 | J23: =1/((1/(H23^2))-(1.33333333333333/(G23^2))) -> 0.060801138 | K23: =1/((-2/(I23^2))+(1/(F23^2))+(0.6666/(G23^2))) -> 0.057270106 | L23: =1/((0.33333333/(H23^2))-(1.33333333333333/(I23^2))+(0.66666666666667/(F23^2))) -> 0.058400057 | M23: =(J23*(E23-E22)+0.5*(E23-E22)*(J22-J23)) -> 0.010487428 | N23: =SUM(M$3:$M23) -> 0.86109385 | O23: =$B$38/((N23*$B$43+1)) -> 0.69555872 | P23: =(6*F23*G23*SQRT(9*(G23^6)*(0.0002^2)+16*(F23^6)*(0.0002)^2))/((4*F23^2 - 3*G23^2)^2) -> 0.00012750678 | Q23: =(((E23-E22)/2)^2)*(P23^2+P24^2) -> 1.2049191e-10 | R23: =SUM(Q$2:$Q23) -> 1.0272515e-07 | S23: =SQRT(((O50*0.001)^2)+((P50*0.02)^2)+((Q50*R23)^2)) -> 0.0010232964 | T23: =O23^3 -> 0.33651265 | U23: =3*S23/O23*T23 -> 0.0014852183 | V23: =T23/$T$2 -> 0.93231231 | W23: =V23*3*SQRT((S23/O23)^2)+(0.001/$O$2)^2 -> 0.0041167876 | X23: =$B$40/((O23/$O$2)^3) -> 6.5321459 | Y23: =(SQRT((0.02/$X$2)^2+(9*(0.001/$O$2)^2)+(9*(S23/O23)^2))*X23) -> 0.045264552 | Z23: =(1-((X23/$B$40)^0.66666667))/2 -> -0.023916881 | AA23: =(SQRT((S23/O23)^2 + (0.0002/F23)^2))*AF23 -> 0.012393843 | AB23: =SQRT((S23/O23)^2 + (0.0002/G23)^2)*AG23 -> 0.0041807291 | AC23: =SQRT((S23/O23)^2 + (0.0002/H23)^2)*AE23 -> 0.011263705 | AD23: =SQRT((S23/O23)^2 + (0.0002/I23)^2)*#REF! -> #REF! | AE23: =2*O23/H23 -> 6.4709461 | AF23: =2*O23/F23 -> 6.9644418 | AG23: =2*O23/G23 -> 2.744722 | AH23: =X23*#REF!^2 -> #REF! | AI23: =X23*AE23*AE23 -> 273.52148 | AJ23: =X23*AF23^2 -> 316.83161 | AK23: =X23*AG23^2 -> 49.209912 | AL23: =1.5*AI23-AJ23/2-2*AK23 -> 153.44659
AI26: %uncert min
B27: v111 | AI27: %uncert max
A28: Width then radius | B28: 2.34 | J28: D | M28: K | N28: I | O28: L term | P28: rho term | Q28: Int term | Z28: =1.42/0.2298 -> 6.1792863
A29: Length initial | B29: 0.623 | C29: 0.607 | J29: =12*$B$31*$B$38^2+$M$29*N2 -> 37.047468 | M29: =C34 -> 1.016974 | N29: sum cook | O29: =36*$B$40*($B$38^2)*(4*$B$40*$B$38^2 + $M$29*N2)/J29^2 -> 1 | P29: =36*$B$40*($B$38^2)*(4*$B$40*$B$38^2 + $M$29*O2)/M29^2 -> 1404.8934 | Q29: =-(12*$B$40*$M$29*$D$38^3)/(J29^2) -> -0.018893365
A30: alpha thermal expansion | B30: =0.000046 -> 4.6e-05 | F30: Value | G30: VP100 or 110 or VS110 | H30: bench | J30: =12*$B$31*$B$38^2+$M$29*N3 -> 37.058017 | O30: =36*$B$40*($B$38^2)*(4*$B$40*$B$38^2 + $M$29*N3)/J30^2 -> 1.0002845 | P30: =(12*$M$29*N3*$D$38^3)/(J30^2) -> 3.2163423e-05 | Q30: =-(12*$B$40*$M$29*$D$38^3)/(J30^2) -> -0.01888261
A31: density OG | B31: 6.09 | E31: C11 | F31: 231 | G31: 6.1588176 | H31: 0.23121321 | J31: =12*$B$31*$B$38^2+$M$29*N4 -> 37.176532 | O31: =36*$B$40*($B$38^2)*(4*$B$40*$B$38^2 + $M$29*N4)/J31^2 -> 1.0034476 | P31: =(12*$M$29*N4*$D$38^3)/(J31^2) -> 0.0003909935 | Q31: =-(12*$B$40*$M$29*$D$38^3)/(J31^2) -> -0.018762409
A32: Gamma gruneisen | B32: 1.23 | E32: C12 VP | F32: 120 | G32: 5.9398555 | H32: 0.23973647 | J32: =12*$B$31*$B$38^2+$M$29*N5 -> 37.242145 | O32: =36*$B$40*($B$38^2)*(4*$B$40*$B$38^2 + $M$29*N5)/J32^2 -> 1.0051727 | P32: =(12*$M$29*N5*$D$38^3)/(J32^2) -> 0.00058768702 | Q32: =-(12*$B$40*$M$29*$D$38^3)/(J32^2) -> -0.018696357
A33: T temp K | B33: 300 | E33: C12 VS | F33: 120 | G33: 2.9070625 | H33: 0.48984154 | J33: =12*$B$31*$B$38^2+$M$29*N6 -> 37.312753 | O33: =36*$B$40*($B$38^2)*(4*$B$40*$B$38^2 + $M$29*N6)/J33^2 -> 1.0070087 | P33: =(12*$M$29*N6*$D$38^3)/(J33^2) -> 0.00079780817 | Q33: =-(12*$B$40*$M$29*$D$38^3)/(J33^2) -> -0.018625664
A34: >scalar> | B34: =C34/C35 -> 0.035853802 | C34: =1+B30*B32*B33 -> 1.016974 | E34: C44 | F34: 43.4 | G34: 2.6695387 | H34: 0.5334255 | J34: =12*$B$31*$B$38^2+$M$29*N7 -> 37.384979 | O34: =36*$B$40*($B$38^2)*(4*$B$40*$B$38^2 + $M$29*N7)/J34^2 -> 1.008865 | P34: =(12*$M$29*N7*$D$38^3)/(J34^2) -> 0.0010110985 | Q34: =-(12*$B$40*$M$29*$D$38^3)/(J34^2) -> -0.018553766
C35: =12*B31*(B29^2) -> 28.364467 | J35: =12*$B$31*$B$38^2+$M$29*N8 -> 37.434312 | O35: =36*$B$40*($B$38^2)*(4*$B$40*$B$38^2 + $M$29*N8)/J35^2 -> 1.0101204 | P35: =(12*$M$29*N8*$D$38^3)/(J35^2) -> 0.0011558361 | Q35: =-(12*$B$40*$M$29*$D$38^3)/(J35^2) -> -0.018504896
B36: V100 | J36: =12*$B$31*$B$38^2+$M$29*N9 -> 37.479955 | O36: =36*$B$40*($B$38^2)*(4*$B$40*$B$38^2 + $M$29*N9)/J36^2 -> 1.0112729 | P36: =(12*$M$29*N9*$D$38^3)/(J36^2) -> 0.001289065 | Q36: =-(12*$B$40*$M$29*$D$38^3)/(J36^2) -> -0.018459853
A37: Width then radius | B37: 2.34 | C37: =B37/2 -> 1.17 | J37: =12*$B$31*$B$38^2+$M$29*N10 -> 37.53696 | O37: =36*$B$40*($B$38^2)*(4*$B$40*$B$38^2 + $M$29*N10)/J37^2 -> 1.0127002 | P37: =(12*$M$29*N10*$D$38^3)/(J37^2) -> 0.0014545433 | Q37: =-(12*$B$40*$M$29*$D$38^3)/(J37^2) -> -0.018403829
A38: Length initial | B38: 0.712 | C38: mm | D38: 0.704 | J38: =12*$B$31*$B$38^2+$M$29*N11 -> 37.584238 | O38: =36*$B$40*($B$38^2)*(4*$B$40*$B$38^2 + $M$29*N11)/J38^2 -> 1.0138739 | P38: =(12*$M$29*N11*$D$38^3)/(J38^2) -> 0.0015910236 | Q38: =-(12*$B$40*$M$29*$D$38^3)/(J38^2) -> -0.018357556
A39: alpha thermal expansion | B39: =0.000046 -> 4.6e-05 | C39: m/m C | J39: =12*$B$31*$B$38^2+$M$29*N12 -> 37.622202 | O39: =36*$B$40*($B$38^2)*(4*$B$40*$B$38^2 + $M$29*N12)/J39^2 -> 1.0148097 | P39: =(12*$M$29*N12*$D$38^3)/(J39^2) -> 0.0017001146 | Q39: =-(12*$B$40*$M$29*$D$38^3)/(J39^2) -> -0.018320526
A40: density OG | B40: 6.09 | C40: g/cm^3 | J40: =12*$B$31*$B$38^2+$M$29*N13 -> 37.668404 | O40: =36*$B$40*($B$38^2)*(4*$B$40*$B$38^2 + $M$29*N13)/J40^2 -> 1.0159408 | P40: =(12*$M$29*N13*$D$38^3)/(J40^2) -> 0.0018322792 | Q40: =-(12*$B$40*$M$29*$D$38^3)/(J40^2) -> -0.018275612
A41: Gamma gruneisen | B41: 1.23 | J41: =12*$B$31*$B$38^2+$M$29*N14 -> 37.708341 | O41: =36*$B$40*($B$38^2)*(4*$B$40*$B$38^2 + $M$29*N14)/J41^2 -> 1.0169116 | P41: =(12*$M$29*N14*$D$38^3)/(J41^2) -> 0.0019460002 | Q41: =-(12*$B$40*$M$29*$D$38^3)/(J41^2) -> -0.018236921
A42: T temp K | B42: 300 | J42: =12*$B$31*$B$38^2+$M$29*N15 -> 37.736613 | O42: =36*$B$40*($B$38^2)*(4*$B$40*$B$38^2 + $M$29*N15)/J42^2 -> 1.017595 | P42: =(12*$M$29*N15*$D$38^3)/(J42^2) -> 0.0020262088 | Q42: =-(12*$B$40*$M$29*$D$38^3)/(J42^2) -> -0.018209605
A43: >scalar> | B43: =C43/C44 -> 0.027450567 | C43: =1+B39*B41*B42 -> 1.016974 | J43: =12*$B$31*$B$38^2+$M$29*N16 -> 37.773084 | O43: =36*$B$40*($B$38^2)*(4*$B$40*$B$38^2 + $M$29*N16)/J43^2 -> 1.0184718 | P43: =(12*$M$29*N16*$D$38^3)/(J43^2) -> 0.0021293231 | Q43: =-(12*$B$40*$M$29*$D$38^3)/(J43^2) -> -0.018174458
C44: =12*B40*(B38^2) -> 37.047468 | J44: =12*$B$31*$B$38^2+$M$29*N17 -> 37.806431 | O44: =36*$B$40*($B$38^2)*(4*$B$40*$B$38^2 + $M$29*N17)/J44^2 -> 1.019269 | P44: =(12*$M$29*N17*$D$38^3)/(J44^2) -> 0.0022232534 | Q44: =-(12*$B$40*$M$29*$D$38^3)/(J44^2) -> -0.018142411
A45: delta C11 | B45: 3 | J45: =12*$B$31*$B$38^2+$M$29*N18 -> 37.825724 | O45: =36*$B$40*($B$38^2)*(4*$B$40*$B$38^2 + $M$29*N18)/J45^2 -> 1.0197282 | P45: =(12*$M$29*N18*$D$38^3)/(J45^2) -> 0.0022774435 | Q45: =-(12*$B$40*$M$29*$D$38^3)/(J45^2) -> -0.018123908
A46: delta C12/C44 | B46: 1 | J46: =12*$B$31*$B$38^2+$M$29*N19 -> 37.839433 | O46: =36*$B$40*($B$38^2)*(4*$B$40*$B$38^2 + $M$29*N19)/J46^2 -> 1.0200535 | P46: =(12*$M$29*N19*$D$38^3)/(J46^2) -> 0.0023158822 | Q46: =-(12*$B$40*$M$29*$D$38^3)/(J46^2) -> -0.018110778
J47: =12*$B$31*$B$38^2+$M$29*N20 -> 37.863979 | O47: =36*$B$40*($B$38^2)*(4*$B$40*$B$38^2 + $M$29*N20)/J47^2 -> 1.0206343 | P47: =(12*$M$29*N20*$D$38^3)/(J47^2) -> 0.0023845652 | Q47: =-(12*$B$40*$M$29*$D$38^3)/(J47^2) -> -0.018087305
A48: K | B48: 151.14 | J48: =12*$B$31*$B$38^2+$M$29*N21 -> 37.896429 | O48: =36*$B$40*($B$38^2)*(4*$B$40*$B$38^2 + $M$29*N21)/J48^2 -> 1.0213984 | P48: =(12*$M$29*N21*$D$38^3)/(J48^2) -> 0.0024750892 | Q48: =-(12*$B$40*$M$29*$D$38^3)/(J48^2) -> -0.018056342
A49: K' | B49: 3.47 | J49: =12*$B$31*$B$38^2+$M$29*N22 -> 37.912512 | O49: =36*$B$40*($B$38^2)*(4*$B$40*$B$38^2 + $M$29*N22)/J49^2 -> 1.0217756 | P49: =(12*$M$29*N22*$D$38^3)/(J49^2) -> 0.0025198379 | Q49: =-(12*$B$40*$M$29*$D$38^3)/(J49^2) -> -0.018041026
J50: =12*$B$31*$B$38^2+$M$29*N23 -> 37.923178 | O50: =36*$B$40*($B$38^2)*(4*$B$40*$B$38^2 + $M$29*N23)/J50^2 -> 1.0220252 | P50: =(12*$M$29*N23*$D$38^3)/(J50^2) -> 0.0025494713 | Q50: =-(12*$B$40*$M$29*$D$38^3)/(J50^2) -> -0.01803088
...

Sheet FS No Vs 111
A1: V100 Pressure | B1: Oil P | C1: 2TP Au pressure corrected 111 | D1: 2TS Au pressure corrected 111 | E1: V100 Pressure | F1: 2TP Au 100 | G1: 2TS Au 100 high C44 | H1: L corrected v111 TP | I1: L correct v111 TS | J1: f(x) for cook | K1: rect+triang | L1: Sum Cook (I) | M1: Cook's Length | N1: integ unc | O1: trap uncert | P1: Trap add | Q1: L uncert | R1: Volume | S1: V ncrt | T1: V/v0 | U1: v/v0 ncrt | V1: New density | W1: rho ncrt | X1: Strain | Y1: VP100 ncrt | Z1: VS100 ncrt | AA1: VP111 ncrt | AB1: VS111 ncrt | AC1: Vp 111 | AD1: Vp100 | AE1: Vs100 | AF1: pvp111^2 | AG1: C11 exp | AH1: C44 exp | AI1: C12 vp | AK1: L | AL1: V | AM1: V0/V calc | AN1: density | AO1: FS Pressure | AP1: finite strain f | AQ1: C11 fit | AR1: C44 fit | AS1: C12 fit | AT1: C11 diff | AU1: C44 diff | AV1: C12 diff | AW1: FSP diff | BA1: 2TP Au 100 | BB1: 2TS Au 100 high C44 | BC1: L corrected v111 TP | BD1: L correct v111 TS | BE1: L | BF1: V | BG1: V0/V calc | BH1: density | BI1: FS Pressure | BJ1: finite strain f | BK1: delta P | BL1: Vp 111 calc | BM1: Vp100 calc | BN1: Vs100 calc | BO1: pvp111^2 | BP1: C11 FS calc | BQ1: C44 FS calc | BR1: C12 FS calc | BS1: C11 fit | BT1: C44 fit | BU1: C12 fit | BV1: C11 diff | BW1: C12 vp diff | BX1: C44 diff | BY1: K | BZ1: Vp100 | CA1: Vs100 | CB1: Vp111 | CC1: Vs111 | CD1: GV | CE1: GR | CF1: GH | CG1: VP100 diff | CH1: VS100 diff | CI1: VP111 diff
A2: 0 | B2: 0 | C2: 0.21010882 | D2: 0.41441731 | E2: 0 | F2: =0.229199934662983 -> 0.22919993 | G2: =0.510926917293233 -> 0.51092692 | H2: =C2*0.712/0.623 -> 0.24012437 | I2: =D2*0.712/0.623 -> 0.47361979 | J2: =1/((1/(H2^2))-(1.33333333333333/(G2^2))) -> 0.08172952 | L2: =SUM(K2:$K$2) -> 0 | M2: 0.704 | N2: =(6*F2*G2*SQRT(9*(G2^6)*(0.0002^2)+16*(F2^6)*(0.0002)^2))/((4*F2^2 - 3*G2^2)^2) -> 0.00017248585 | O2: =(((E2-E2)/2)^2)*(N2^2+N3^2) -> 0 | P2: =SUM(O2:$O$2) -> 0 | Q2: 0.001 | R2: =M2^3 -> 0.34891366 | S2: =3*Q2/M2*R2 -> 0.001486848 | T2: =R2/$R$2 -> 1 | U2: =T2*3*SQRT((Q2/M2)^2)+(0.001/$M$2)^2 -> 0.0042633813 | V2: =$B$40/((M2/$M$2)^3) -> 6.09 | W2: 0.01 | X2: =(1-((V2/$B$40)^0.66666667))/2 -> 0 | Y2: =(SQRT((Q2/M2)^2 + (0.0002/F2)^2))*AD2 -> 0.010357367 | Z2: =SQRT((Q2/M2)^2 + (0.0002/G2)^2)*AE2 -> 0.0041065128 | AA2: =SQRT((Q2/M2)^2 + (0.0002/H2)^2)*AC2 -> 0.0097649912 | AB2: =SQRT((Q2/M2)^2 + (0.0002/I2)^2)*#REF! -> #REF! | AC2: =2*0.712/H2 -> 5.9302602 | AD2: =2*0.712/F2 -> 6.2129163 | AE2: =2*0.712/G2 -> 2.7870914 | AF2: =V2*AC2*AC2 -> 214.17304 | AG2: =V2*AD2^2 -> 235.076 | AH2: =V2*AE2^2 -> 47.306379 | AI2: =1.5*AF2-AG2/2-2*AH2 -> 109.1088 | AK2: =M2 -> 0.704 | AL2: =AK2^3 -> 0.34891366 | AM2: =$AL$2/AL2 -> 1 | AN2: 6.09 | AO2: =-3*$AP$31*((1-2*AP2)^2.5)*(1+3*(4-$AR$31)*AP2/2)*AP2 -> 0 | AP2: =0.5*(1-AM2^0.666666667) -> 0 | AQ2: =(1-2*AP2)^(3.5)*($AP$26-$AT$26*AP2)+AO2*3 -> 239.8936 | AR2: =(1-2*AP2)^(3.5)*($AP$28-$AT$28*AP2)+AO2*1 -> 46.22189 | AS2: =(1-2*AP2)^(3.5)*($AP$27-$AT$27*AP2)+AO2*1 -> 122.04281 | AT2: =AQ2-AG2 -> 4.8176043 | AU2: =AR2-AH2 -> -1.0844889 | AV2: =AS2-AI2 -> 12.934019 | AW2: =AO2-A2 -> 0 | BA2: 0.22919993 | BB2: 0.51092692 | BC2: =C2*0.712/0.623 -> 0.24012437 | BD2: =D2*0.712/0.623 -> 0.47361979 | BE2: 0.704 | BF2: =BE2^3 -> 0.34891366 | BG2: =$BF$2/BF2 -> 1 | BH2: 6.09 | BI2: =-3*$BG$36*((1-2*BJ2)^2.5)*(1+3*(4-$BG$37)*BJ2/2)*BJ2 -> 0 | BJ2: =0.5*(1-BG2^0.666666667) -> 0 | BK2: =BI2-E2 -> 0 | BL2: =2*0.712/BC2 -> 5.9302602 | BM2: =2*0.712/BA2 -> 6.2129163 | BN2: =2*0.712/BB2 -> 2.7870914 | BO2: =BH2*BL2*BL2 -> 214.17304 | BP2: =BH2*BM2^2 -> 235.076 | BQ2: =BH2*BN2^2 -> 47.306379 | BR2: =1.5*BO2-BP2/2-2*BQ2 -> 109.1088 | BS2: =(1-2*BJ2)^(3.5)*($BG$25-$BK$25*BJ2)+BI2*3 -> 239.51038 | BT2: =(1-2*BJ2)^(3.5)*($BG$27-$BK$27*BJ2)+BI2*1 -> 46.243127 | BU2: =(1-2*BJ2)^(3.5)*($BG$26-$BK$26*BJ2)+BI2*1 -> 121.79138 | BV2: =BS2-BP2 -> 4.4343822 | BW2: =BU2-BR2 -> 12.682583 | BX2: =BT2-BQ2 -> -1.0632517 | BY2: =(BS2+2*BU2)/3 -> 161.03105 | BZ2: =SQRT(BS2/BH2) -> 6.2712415 | CA2: =SQRT(BT2/BH2) -> 2.7555922 | CB2: =SQRT((0.33333334*(BS2+2*BU2+4*BT2))/BH2) -> 6.0470046 | CC2: =SQRT((0.3333334*(BS2-BU2+BT2))/BH2) -> 2.9957292 | CD2: =(BS2-BU2+3*BT2)/5 -> 51.289677 | CE2: =((5*(BS2-BU2)*BT2)/(3*(BS2-BU2)+4*BT2)) -> 50.579783 | CF2: =(CD2+CE2)/2 -> 50.93473 | CG2: =BZ2-AD2 -> 0.058325246 | CH2: =CA2-AE2 -> -0.031499141 | CI2: =CB2-AC2 -> 0.11674443 | CP2: tttttttttttttttttttt | DP2: o | EI2: 0
A3: 0.12913291 | B3: 30 | C3: 0.2017768 | D3: 0.41395642 | E3: 0.12913291 | F3: 0.22474572 | G3: 0.50723365 | H3: =C3*$M$2/0.607 -> 0.2340212 | I3: =D3*$M$2/0.607 -> 0.48010762 | J3: =1/((1/(H3^2))-(1.33333333333333/(G3^2))) -> 0.076468796 | K3: =(J3*(E3-E2)+0.5*(E3-E2)*(J2-J3)) -> 0.010214304 | L3: =SUM(K$3:$K3) -> 0.010214304 | M3: =0.704/((L3*$B$43+1)) -> 0.70379815 | N3: =(6*F3*G3*SQRT(9*(G3^6)*(0.0002^2)+16*(F3^6)*(0.0002)^2))/((4*F3^2 - 3*G3^2)^2) -> 0.00016605784 | O3: =(((E3-E2)/2)^2)*(N3^2+N4^2) -> 2.216109e-10 | P3: =SUM(O$2:$O3) -> 2.216109e-10 | Q3: =SQRT(((M30*0.001)^2)+((N30*0.02)^2)+((O30*P3)^2)) -> 0.0010002868 | R3: =M3^3 -> 0.34861363 | S3: =3*Q3/M3*R3 -> 0.0014864217 | T3: =R3/$R$2 -> 0.9991401 | U3: =T3*3*SQRT((Q3/M3)^2)+(0.001/$M$2)^2 -> 0.0042621594 | V3: =$B$40/((M3/$M$2)^3) -> 6.0952413 | W3: =(SQRT((0.02/$V$2)^2+(9*(0.001/$M$2)^2)+(9*(Q3/M3)^2))*V3) -> 0.041842138 | X3: =(1-((V3/$B$40)^0.66666667))/2 -> -0.00028683825 | Y3: =(SQRT((Q3/M3)^2 + (0.0002/F3)^2))*AD3 -> 0.010502389 | Z3: =SQRT((Q3/M3)^2 + (0.0002/G3)^2)*AE3 -> 0.0040930513 | AA3: =SQRT((Q3/M3)^2 + (0.0002/H3)^2)*AC3 -> 0.0099751606 | AB3: =SQRT((Q3/M3)^2 + (0.0002/I3)^2)*#REF! -> #REF! | AC3: =2*M3/H3 -> 6.014824 | AD3: =2*M3/F3 -> 6.2630617 | AE3: =2*M3/G3 -> 2.7750452 | AF3: =V3*AC3*AC3 -> 220.51429 | AG3: =V3*AD3^2 -> 239.09158 | AH3: =V3*AE3^2 -> 46.938697 | AI3: =1.5*AF3-AG3/2-2*AH3 -> 117.34826 | AK3: =M3 -> 0.70379815 | AL3: =AK3^3 -> 0.34861363 | AM3: =$AL$2/AL3 -> 1.0008606 | AN3: =$AN$2/((AK3/$AK$2)^3) -> 6.0952413 | AO3: =-3*$AP$31*((1-2*AP3)^2.5)*(1+3*(4-$AR$31)*AP3/2)*AP3 -> 0.13901184 | AP3: =0.5*(1-AM3^0.666666667) -> -0.00028683825 | AQ3: =(1-2*AP3)^(3.5)*($AP$26-$AT$26*AP3)+AO3*3 -> 240.64165 | AR3: =(1-2*AP3)^(3.5)*($AP$28-$AT$28*AP3)+AO3*1 -> 46.262168 | AS3: =(1-2*AP3)^(3.5)*($AP$27-$AT$27*AP3)+AO3*1 -> 122.46384 | AT3: =AQ3-AG3 -> 1.5500767 | AU3: =AR3-AH3 -> -0.67652879 | AV3: =AS3-AI3 -> 5.1155791 | AW3: =AO3-A3 -> 0.0098789332 | BA3: 0.22474572 | BB3: 0.50723365 | BC3: =C3*$BE$2/0.607 -> 0.2340212 | BD3: =D3*$BE$2/0.607 -> 0.48010762 | BE3: 0.70410933 | BF3: =BE3^3 -> 0.34907624 | BG3: =$BF$2/BF3 -> 0.99953426 | BH3: =$BH$2/((BE3/$BE$2)^3) -> 6.0871636 | BI3: =-3*$BG$36*((1-2*BJ3)^2.5)*(1+3*(4-$BG$37)*BJ3/2)*BJ3 -> -0.074948487 | BJ3: =0.5*(1-BG3^0.666666667) -> 0.00015526032 | BK3: =BI3-E3 -> -0.2040814 | BL3: =2*BE3/BC3 -> 6.0174834 | BM3: =2*BE3/BA3 -> 6.2658308 | BN3: =2*BE3/BB3 -> 2.7762722 | BO3: =BH3*BL3*BL3 -> 220.41684 | BP3: =BH3*BM3^2 -> 238.98591 | BQ3: =BH3*BN3^2 -> 46.917953 | BR3: =1.5*BO3-BP3/2-2*BQ3 -> 117.2964 | BS3: =(1-2*BJ3)^(3.5)*($BG$25-$BK$25*BJ3)+BI3*3 -> 239.09688 | BT3: =(1-2*BJ3)^(3.5)*($BG$27-$BK$27*BJ3)+BI3*1 -> 46.221492 | BU3: =(1-2*BJ3)^(3.5)*($BG$26-$BK$26*BJ3)+BI3*1 -> 121.55804 | BV3: =BS3-BP3 -> 0.11096396 | BW3: =BU3-BR3 -> 4.2616411 | BX3: =BT3-BQ3 -> -0.69646135 | BY3: =(BS3+2*BU3)/3 -> 160.73765 | BZ3: =SQRT(BS3/BH3) -> 6.2672853 | CA3: =SQRT(BT3/BH3) -> 2.7555893 | CB3: =SQRT((0.33333334*(BS3+2*BU3+4*BT3))/BH3) -> 6.0440355 | CC3: =SQRT((0.3333334*(BS3-BU3+BT3))/BH3) -> 2.9945825 | CD3: =(BS3-BU3+3*BT3)/5 -> 51.240663 | CE3: =((5*(BS3-BU3)*BT3)/(3*(BS3-BU3)+4*BT3)) -> 50.537631 | CF3: =(CD3+CE3)/2 -> 50.889147 | CG3: =BZ3-AD3 -> 0.0042236189 | CH3: =CA3-AE3 -> -0.019455914 | CI3: =CB3-AC3 -> 0.029211545
A4: 1.6356835 | B4: 60 | C4: 0.19870445 | D4: 0.40424966 | E4: 1.6356835 | F4: 0.22094572 | G4: 0.50583365 | H4: =C4*$M$2/0.607 -> 0.23045788 | I4: =D4*$M$2/0.607 -> 0.46884969 | J4: =1/((1/(H4^2))-(1.33333333333333/(G4^2))) -> 0.073434797 | K4: =(J4*(E4-E3)+0.5*(E4-E3)*(J3-J4)) -> 0.11291867 | L4: =SUM(K$3:$K4) -> 0.12313298 | M4: =$B$38/((L4*$B$43+1)) -> 0.70157443 | N4: =(6*F4*G4*SQRT(9*(G4^6)*(0.0002^2)+16*(F4^6)*(0.0002)^2))/((4*F4^2 - 3*G4^2)^2) -> 0.00015994952 | O4: =(((E4-E3)/2)^2)*(N4^2+N5^2) -> 2.8357893e-08 | P4: =SUM(O$2:$O4) -> 2.8579504e-08 | Q4: =SQRT(((M31*0.001)^2)+((N31*0.02)^2)+((O31*P4)^2)) -> 0.0010034531 | R4: =M4^3 -> 0.34531962 | S4: =3*Q4/M4*R4 -> 0.0014817189 | T4: =R4/$R$2 -> 0.98969933 | U4: =T4*3*SQRT((Q4/M4)^2)+(0.001/$M$2)^2 -> 0.0042486812 | V4: =$B$40/((M4/$M$2)^3) -> 6.153384 | W4: =(SQRT((0.02/$V$2)^2+(9*(0.001/$M$2)^2)+(9*(Q4/M4)^2))*V4) -> 0.042344873 | X4: =(1-((V4/$B$40)^0.66666667))/2 -> -0.0034633029 | Y4: =(SQRT((Q4/M4)^2 + (0.0002/F4)^2))*AD4 -> 0.010749511 | Z4: =SQRT((Q4/M4)^2 + (0.0002/G4)^2)*AE4 -> 0.0041163274 | AA4: =SQRT((Q4/M4)^2 + (0.0002/H4)^2)*AC4 -> 0.010185986 | AB4: =SQRT((Q4/M4)^2 + (0.0002/I4)^2)*#REF! -> #REF! | AC4: =2*M4/H4 -> 6.0885262 | AD4: =2*M4/F4 -> 6.3506496 | AE4: =2*M4/G4 -> 2.7739334 | AF4: =V4*AC4*AC4 -> 228.10687 | AG4: =V4*AD4^2 -> 248.1706 | AH4: =V4*AE4^2 -> 47.348484 | AI4: =1.5*AF4-AG4/2-2*AH4 -> 123.37804 | AK4: =M4 -> 0.70157443 | AL4: =AK4^3 -> 0.34531962 | AM4: =$AL$2/AL4 -> 1.0104079 | AN4: =$AN$2/((AK4/$AK$2)^3) -> 6.153384 | AO4: =-3*$AP$31*((1-2*AP4)^2.5)*(1+3*(4-$AR$31)*AP4/2)*AP4 -> 1.7036993 | AP4: =0.5*(1-AM4^0.666666667) -> -0.0034633029 | AQ4: =(1-2*AP4)^(3.5)*($AP$26-$AT$26*AP4)+AO4*3 -> 249.00692 | AR4: =(1-2*AP4)^(3.5)*($AP$28-$AT$28*AP4)+AO4*1 -> 46.690587 | AS4: =(1-2*AP4)^(3.5)*($AP$27-$AT$27*AP4)+AO4*1 -> 127.18506 | AT4: =AQ4-AG4 -> 0.83632089 | AU4: =AR4-AH4 -> -0.65789744 | AV4: =AS4-AI4 -> 3.8070168 | AW4: =AO4-A4 -> 0.06801577 | BA4: 0.22094572 | BB4: 0.50583365 | BC4: =C4*$BE$2/0.607 -> 0.23045788 | BD4: =D4*$BE$2/0.607 -> 0.46884969 | BE4: 0.70169087 | BF4: =BE4^3 -> 0.34549159 | BG4: =$BF$2/BF4 -> 1.0099049 | BH4: =$BH$2/((BE4/$BE$2)^3) -> 6.1503211 | BI4: =-3*$BG$36*((1-2*BJ4)^2.5)*(1+3*(4-$BG$37)*BJ4/2)*BJ4 -> 1.6180643 | BJ4: =0.5*(1-BG4^0.666666667) -> -0.0032962187 | BK4: =BI4-E4 -> -0.017619155 | BL4: =2*BE4/BC4 -> 6.0895367 | BM4: =2*BE4/BA4 -> 6.3517037 | BN4: =2*BE4/BB4 -> 2.7743938 | BO4: =BH4*BL4*BL4 -> 228.06902 | BP4: =BH4*BM4^2 -> 248.12941 | BQ4: =BH4*BN4^2 -> 47.340627 | BR4: =1.5*BO4-BP4/2-2*BQ4 -> 123.35757 | BS4: =(1-2*BJ4)^(3.5)*($BG$25-$BK$25*BJ4)+BI4*3 -> 248.38067 | BT4: =(1-2*BJ4)^(3.5)*($BG$27-$BK$27*BJ4)+BI4*1 -> 46.684986 | BU4: =(1-2*BJ4)^(3.5)*($BG$26-$BK$26*BJ4)+BI4*1 -> 126.80998 | BV4: =BS4-BP4 -> 0.25125863 | BW4: =BU4-BR4 -> 3.4524138 | BX4: =BT4-BQ4 -> -0.65564099 | BY4: =(BS4+2*BU4)/3 -> 167.33354 | BZ4: =SQRT(BS4/BH4) -> 6.3549188 | CA4: =SQRT(BT4/BH4) -> 2.7551149 | CB4: =SQRT((0.33333334*(BS4+2*BU4+4*BT4))/BH4) -> 6.109678 | CC4: =SQRT((0.3333334*(BS4-BU4+BT4))/BH4) -> 3.0197806 | CD4: =(BS4-BU4+3*BT4)/5 -> 52.32513 | CE4: =((5*(BS4-BU4)*BT4)/(3*(BS4-BU4)+4*BT4)) -> 51.459835 | CF4: =(CD4+CE4)/2 -> 51.892482 | CG4: =BZ4-AD4 -> 0.0042691458 | CH4: =CA4-AE4 -> -0.018818471 | CI4: =CB4-AC4 -> 0.021151788
A5: 2.4965696 | B5: 90 | C5: 0.19712307 | D5: 0.40093724 | E5: 2.4965696 | F5: 0.21874572 | G5: 0.50583365 | H5: =C5*$M$2/0.607 -> 0.22862379 | I5: =D5*$M$2/0.607 -> 0.46500794 | J5: =1/((1/(H5^2))-(1.33333333333333/(G5^2))) -> 0.071834787 | K5: =(J5*(E5-E4)+0.5*(E5-E4)*(J4-J5)) -> 0.06253028 | L5: =SUM(K$3:$K5) -> 0.18566326 | M5: =$B$38/((L5*$B$43+1)) -> 0.70034904 | N5: =(6*F5*G5*SQRT(9*(G5^6)*(0.0002^2)+16*(F5^6)*(0.0002)^2))/((4*F5^2 - 3*G5^2)^2) -> 0.00015618171 | O5: =(((E5-E4)/2)^2)*(N5^2+N6^2) -> 8.8434243e-09 | P5: =SUM(O$2:$O5) -> 3.7422929e-08 | Q5: =SQRT(((M32*0.001)^2)+((N32*0.02)^2)+((O32*P5)^2)) -> 0.001005203 | R5: =M5^3 -> 0.34351335 | S5: =3*Q5/M5*R5 -> 0.0014791224 | T5: =R5/$R$2 -> 0.9845225 | U5: =T5*3*SQRT((Q5/M5)^2)+(0.001/$M$2)^2 -> 0.0042412394 | V5: =$B$40/((M5/$M$2)^3) -> 6.1857398 | W5: =(SQRT((0.02/$V$2)^2+(9*(0.001/$M$2)^2)+(9*(Q5/M5)^2))*V5) -> 0.042625462 | X5: =(1-((V5/$B$40)^0.66666667))/2 -> -0.0052266388 | Y5: =(SQRT((Q5/M5)^2 + (0.0002/F5)^2))*AD5 -> 0.010896941 | Z5: =SQRT((Q5/M5)^2 + (0.0002/G5)^2)*AE5 -> 0.0041224874 | AA5: =SQRT((Q5/M5)^2 + (0.0002/H5)^2)*AC5 -> 0.01029811 | AB5: =SQRT((Q5/M5)^2 + (0.0002/I5)^2)*#REF! -> #REF! | AC5: =2*M5/H5 -> 6.1266507 | AD5: =2*M5/F5 -> 6.4033166 | AE5: =2*M5/G5 -> 2.7690884 | AF5: =V5*AC5*AC5 -> 232.18699 | AG5: =V5*AD5^2 -> 253.63057 | AH5: =V5*AE5^2 -> 47.431329 | AI5: =1.5*AF5-AG5/2-2*AH5 -> 126.60255 | AK5: =M5 -> 0.70034904 | AL5: =AK5^3 -> 0.34351335 | AM5: =$AL$2/AL5 -> 1.0157208 | AN5: =$AN$2/((AK5/$AK$2)^3) -> 6.1857398 | AO5: =-3*$AP$31*((1-2*AP5)^2.5)*(1+3*(4-$AR$31)*AP5/2)*AP5 -> 2.5924334 | AP5: =0.5*(1-AM5^0.666666667) -> -0.0052266388 | AQ5: =(1-2*AP5)^(3.5)*($AP$26-$AT$26*AP5)+AO5*3 -> 253.71523 | AR5: =(1-2*AP5)^(3.5)*($AP$28-$AT$28*AP5)+AO5*1 -> 46.914092 | AS5: =(1-2*AP5)^(3.5)*($AP$27-$AT$27*AP5)+AO5*1 -> 129.85282 | AT5: =AQ5-AG5 -> 0.084666732 | AU5: =AR5-AH5 -> -0.51723713 | AV5: =AS5-AI5 -> 3.2502691 | AW5: =AO5-A5 -> 0.095863852 | BA5: 0.21874572 | BB5: 0.50583365 | BC5: =C5*$BE$2/0.607 -> 0.22862379 | BD5: =D5*$BE$2/0.607 -> 0.46500794 | BE5: 0.70031976 | BF5: =BE5^3 -> 0.34347026 | BG5: =$BF$2/BF5 -> 1.0158483 | BH5: =$BH$2/((BE5/$BE$2)^3) -> 6.1865159 | BI5: =-3*$BG$36*((1-2*BJ5)^2.5)*(1+3*(4-$BG$37)*BJ5/2)*BJ5 -> 2.6111737 | BJ5: =0.5*(1-BG5^0.666666667) -> -0.0052688963 | BK5: =BI5-E5 -> 0.1146041 | BL5: =2*BE5/BC5 -> 6.1263945 | BM5: =2*BE5/BA5 -> 6.4030488 | BN5: =2*BE5/BB5 -> 2.7689726 | BO5: =BH5*BL5*BL5 -> 232.1967 | BP5: =BH5*BM5^2 -> 253.64117 | BQ5: =BH5*BN5^2 -> 47.433312 | BR5: =1.5*BO5-BP5/2-2*BQ5 -> 126.60784 | BS5: =(1-2*BJ5)^(3.5)*($BG$25-$BK$25*BJ5)+BI5*3 -> 253.77315 | BT5: =(1-2*BJ5)^(3.5)*($BG$27-$BK$27*BJ5)+BI5*1 -> 46.933034 | BU5: =(1-2*BJ5)^(3.5)*($BG$26-$BK$26*BJ5)+BI5*1 -> 129.87304 | BV5: =BS5-BP5 -> 0.13197829 | BW5: =BU5-BR5 -> 3.2651986 | BX5: =BT5-BQ5 -> -0.50027888 | BY5: =(BS5+2*BU5)/3 -> 171.17308 | BZ5: =SQRT(BS5/BH5) -> 6.4047144 | CA5: =SQRT(BT5/BH5) -> 2.7543317 | CB5: =SQRT((0.33333334*(BS5+2*BU5+4*BT5))/BH5) -> 6.1468579 | CC5: =SQRT((0.3333334*(BS5-BU5+BT5))/BH5) -> 3.0339081 | CD5: =(BS5-BU5+3*BT5)/5 -> 52.939842 | CE5: =((5*(BS5-BU5)*BT5)/(3*(BS5-BU5)+4*BT5)) -> 51.972386 | CF5: =(CD5+CE5)/2 -> 52.456114 | CG5: =BZ5-AD5 -> 0.0013978749 | CH5: =CA5-AE5 -> -0.014756673 | CI5: =CB5-AC5 -> 0.020207187
A6: 3.4435442 | B6: 120 | C6: 0.19552144 | D6: 0.39786989 | E6: 3.4435442 | F6: 0.21654572 | G6: 0.50523365 | H6: =C6*$M$2/0.607 -> 0.22676622 | I6: =D6*$M$2/0.607 -> 0.46145042 | J6: =1/((1/(H6^2))-(1.33333333333333/(G6^2))) -> 0.07030781 | K6: =(J6*(E6-E5)+0.5*(E6-E5)*(J5-J6)) -> 0.067302719 | L6: =SUM(K$3:$K6) -> 0.25296598 | M6: =$B$38/((L6*$B$43+1)) -> 0.69903491 | N6: =(6*F6*G6*SQRT(9*(G6^6)*(0.0002^2)+16*(F6^6)*(0.0002)^2))/((4*F6^2 - 3*G6^2)^2) -> 0.00015276458 | O6: =(((E6-E5)/2)^2)*(N6^2+N7^2) -> 1.0265501e-08 | P6: =SUM(O$2:$O6) -> 4.768843e-08 | Q6: =SQRT(((M33*0.001)^2)+((N33*0.02)^2)+((O33*P6)^2)) -> 0.0010070834 | R6: =M6^3 -> 0.34158328 | S6: =3*Q6/M6*R6 -> 0.0014763333 | T6: =R6/$R$2 -> 0.97899082 | U6: =T6*3*SQRT((Q6/M6)^2)+(0.001/$M$2)^2 -> 0.0042332457 | V6: =$B$40/((M6/$M$2)^3) -> 6.2206916 | W6: =(SQRT((0.02/$V$2)^2+(9*(0.001/$M$2)^2)+(9*(Q6/M6)^2))*V6) -> 0.042929216 | X6: =(1-((V6/$B$40)^0.66666667))/2 -> -0.0071280005 | Y6: =(SQRT((Q6/M6)^2 + (0.0002/F6)^2))*AD6 -> 0.0110486 | Z6: =SQRT((Q6/M6)^2 + (0.0002/G6)^2)*AE6 -> 0.0041343591 | AA6: =SQRT((Q6/M6)^2 + (0.0002/H6)^2)*AC6 -> 0.010414365 | AB6: =SQRT((Q6/M6)^2 + (0.0002/I6)^2)*#REF! -> #REF! | AC6: =2*M6/H6 -> 6.1652473 | AD6: =2*M6/F6 -> 6.4562339 | AE6: =2*M6/G6 -> 2.7671748 | AF6: =V6*AC6*AC6 -> 236.45019 | AG6: =V6*AD6^2 -> 259.29682 | AH6: =V6*AE6^2 -> 47.633431 | AI6: =1.5*AF6-AG6/2-2*AH6 -> 129.76002 | AK6: =M6 -> 0.69903491 | AL6: =AK6^3 -> 0.34158328 | AM6: =$AL$2/AL6 -> 1.02146 | AN6: =$AN$2/((AK6/$AK$2)^3) -> 6.2206916 | AO6: =-3*$AP$31*((1-2*AP6)^2.5)*(1+3*(4-$AR$31)*AP6/2)*AP6 -> 3.5669827 | AP6: =0.5*(1-AM6^0.666666667) -> -0.0071280005 | AQ6: =(1-2*AP6)^(3.5)*($AP$26-$AT$26*AP6)+AO6*3 -> 258.84391 | AR6: =(1-2*AP6)^(3.5)*($AP$28-$AT$28*AP6)+AO6*1 -> 47.14325 | AS6: =(1-2*AP6)^(3.5)*($AP$27-$AT$27*AP6)+AO6*1 -> 132.76725 | AT6: =AQ6-AG6 -> -0.45290914 | AU6: =AR6-AH6 -> -0.49018104 | AV6: =AS6-AI6 -> 3.0072331 | AW6: =AO6-A6 -> 0.12343852 | BA6: 0.21654572 | BB6: 0.50523365 | BC6: =C6*$BE$2/0.607 -> 0.22676622 | BD6: =D6*$BE$2/0.607 -> 0.46145042 | BE6: 0.69916921 | BF6: =BE6^3 -> 0.34178019 | BG6: =$BF$2/BF6 -> 1.0208715 | BH6: =$BH$2/((BE6/$BE$2)^3) -> 6.2171076 | BI6: =-3*$BG$36*((1-2*BJ6)^2.5)*(1+3*(4-$BG$37)*BJ6/2)*BJ6 -> 3.4635885 | BJ6: =0.5*(1-BG6^0.666666667) -> -0.0069331943 | BK6: =BI6-E6 -> 0.020044316 | BL6: =2*BE6/BC6 -> 6.1664318 | BM6: =2*BE6/BA6 -> 6.4574743 | BN6: =2*BE6/BB6 -> 2.7677065 | BO6: =BH6*BL6*BL6 -> 236.40478 | BP6: =BH6*BM6^2 -> 259.24701 | BQ6: =BH6*BN6^2 -> 47.624281 | BR6: =1.5*BO6-BP6/2-2*BQ6 -> 129.7351 | BS6: =(1-2*BJ6)^(3.5)*($BG$25-$BK$25*BJ6)+BI6*3 -> 258.37177 | BT6: =(1-2*BJ6)^(3.5)*($BG$27-$BK$27*BJ6)+BI6*1 -> 47.132435 | BU6: =(1-2*BJ6)^(3.5)*($BG$26-$BK$26*BJ6)+BI6*1 -> 132.49233 | BV6: =BS6-BP6 -> -0.8752448 | BW6: =BU6-BR6 -> 2.7572288 | BX6: =BT6-BQ6 -> -0.49184598 | BY6: =(BS6+2*BU6)/3 -> 174.45214 | BZ6: =SQRT(BS6/BH6) -> 6.4465645 | CA6: =SQRT(BT6/BH6) -> 2.7533774 | CB6: =SQRT((0.33333334*(BS6+2*BU6+4*BT6))/BH6) -> 6.1780364 | CC6: =SQRT((0.3333334*(BS6-BU6+BT6))/BH6) -> 3.0456724 | CD6: =(BS6-BU6+3*BT6)/5 -> 53.455349 | CE6: =((5*(BS6-BU6)*BT6)/(3*(BS6-BU6)+4*BT6)) -> 52.396143 | CF6: =(CD6+CE6)/2 -> 52.925746 | CG6: =BZ6-AD6 -> -0.0096693736 | CH6: =CA6-AE6 -> -0.013797378 | CI6: =CB6-AC6 -> 0.012789056
A7: 4.4335632 | B7: 150 | C7: 0.19396667 | D7: 0.39485534 | E7: 4.4335632 | F7: 0.21474572 | G7: 0.50523365 | H7: =C7*$M$2/0.607 -> 0.224963 | I7: =D7*$M$2/0.607 -> 0.45795413 | J7: =1/((1/(H7^2))-(1.33333333333333/(G7^2))) -> 0.068793893 | K7: =(J7*(E7-E6)+0.5*(E7-E6)*(J6-J7)) -> 0.068856661 | L7: =SUM(K$3:$K7) -> 0.32182264 | M7: =$B$38/((L7*$B$43+1)) -> 0.69769553 | N7: =(6*F7*G7*SQRT(9*(G7^6)*(0.0002^2)+16*(F7^6)*(0.0002)^2))/((4*F7^2 - 3*G7^2)^2) -> 0.00014984065 | O7: =(((E7-E6)/2)^2)*(N7^2+N8^2) -> 1.0840844e-08 | P7: =SUM(O$2:$O7) -> 5.8529274e-08 | Q7: =SQRT(((M34*0.001)^2)+((N34*0.02)^2)+((O34*P7)^2)) -> 0.0010090035 | R7: =M7^3 -> 0.33962357 | S7: =3*Q7/M7*R7 -> 0.0014734853 | T7: =R7/$R$2 -> 0.97337423 | U7: =T7*3*SQRT((Q7/M7)^2)+(0.001/$M$2)^2 -> 0.0042250832 | V7: =$B$40/((M7/$M$2)^3) -> 6.2565864 | W7: =(SQRT((0.02/$V$2)^2+(9*(0.001/$M$2)^2)+(9*(Q7/M7)^2))*V7) -> 0.043241866 | X7: =(1-((V7/$B$40)^0.66666667))/2 -> -0.0090769582 | Y7: =(SQRT((Q7/M7)^2 + (0.0002/F7)^2))*AD7 -> 0.011177219 | Z7: =SQRT((Q7/M7)^2 + (0.0002/G7)^2)*AE7 -> 0.0041411342 | AA7: =SQRT((Q7/M7)^2 + (0.0002/H7)^2)*AC7 -> 0.010529832 | AB7: =SQRT((Q7/M7)^2 + (0.0002/I7)^2)*#REF! -> #REF! | AC7: =2*M7/H7 -> 6.2027582 | AD7: =2*M7/F7 -> 6.497876 | AE7: =2*M7/G7 -> 2.7618728 | AF7: =V7*AC7*AC7 -> 240.71721 | AG7: =V7*AD7^2 -> 264.16805 | AH7: =V7*AE7^2 -> 47.724874 | AI7: =1.5*AF7-AG7/2-2*AH7 -> 133.54205 | AK7: =M7 -> 0.69769553 | AL7: =AK7^3 -> 0.33962357 | AM7: =$AL$2/AL7 -> 1.0273541 | AN7: =$AN$2/((AK7/$AK$2)^3) -> 6.2565864 | AO7: =-3*$AP$31*((1-2*AP7)^2.5)*(1+3*(4-$AR$31)*AP7/2)*AP7 -> 4.5835518 | AP7: =0.5*(1-AM7^0.666666667) -> -0.0090769582 | AQ7: =(1-2*AP7)^(3.5)*($AP$26-$AT$26*AP7)+AO7*3 -> 264.15692 | AR7: =(1-2*AP7)^(3.5)*($AP$28-$AT$28*AP7)+AO7*1 -> 47.365047 | AS7: =(1-2*AP7)^(3.5)*($AP$27-$AT$27*AP7)+AO7*1 -> 135.79573 | AT7: =AQ7-AG7 -> -0.011124977 | AU7: =AR7-AH7 -> -0.35982676 | AV7: =AS7-AI7 -> 2.2536873 | AW7: =AO7-A7 -> 0.14998865 | BA7: 0.21474572 | BB7: 0.50523365 | BC7: =C7*$BE$2/0.607 -> 0.224963 | BD7: =D7*$BE$2/0.607 -> 0.45795413 | BE7: 0.69785874 | BF7: =BE7^3 -> 0.33986196 | BG7: =$BF$2/BF7 -> 1.0266335 | BH7: =$BH$2/((BE7/$BE$2)^3) -> 6.2521978 | BI7: =-3*$BG$36*((1-2*BJ7)^2.5)*(1+3*(4-$BG$37)*BJ7/2)*BJ7 -> 4.4561175 | BJ7: =0.5*(1-BG7^0.666666667) -> -0.0088388755 | BK7: =BI7-E7 -> 0.022554303 | BL7: =2*BE7/BC7 -> 6.2042091 | BM7: =2*BE7/BA7 -> 6.499396 | BN7: =2*BE7/BB7 -> 2.7625188 | BO7: =BH7*BL7*BL7 -> 240.66092 | BP7: =BH7*BM7^2 -> 264.10627 | BQ7: =BH7*BN7^2 -> 47.713713 | BR7: =1.5*BO7-BP7/2-2*BQ7 -> 133.51081 | BS7: =(1-2*BJ7)^(3.5)*($BG$25-$BK$25*BJ7)+BI7*3 -> 263.69277 | BT7: =(1-2*BJ7)^(3.5)*($BG$27-$BK$27*BJ7)+BI7*1 -> 47.349369 | BU7: =(1-2*BJ7)^(3.5)*($BG$26-$BK$26*BJ7)+BI7*1 -> 135.53122 | BV7: =BS7-BP7 -> -0.41349806 | BW7: =BU7-BR7 -> 2.0204096 | BX7: =BT7-BQ7 -> -0.36434339 | BY7: =(BS7+2*BU7)/3 -> 178.25174 | BZ7: =SQRT(BS7/BH7) -> 6.4943061 | CA7: =SQRT(BT7/BH7) -> 2.7519513 | CB7: =SQRT((0.33333334*(BS7+2*BU7+4*BT7))/BH7) -> 6.2135257 | CC7: =SQRT((0.3333334*(BS7-BU7+BT7))/BH7) -> 3.0589693 | CD7: =(BS7-BU7+3*BT7)/5 -> 54.041931 | CE7: =((5*(BS7-BU7)*BT7)/(3*(BS7-BU7)+4*BT7)) -> 52.87121 | CF7: =(CD7+CE7)/2 -> 53.45657 | CG7: =BZ7-AD7 -> -0.0035699027 | CH7: =CA7-AE7 -> -0.0099214955 | CI7: =CB7-AC7 -> 0.010767511
A8: 5.122272 | B8: 180 | C8: 0.19293671 | D8: 0.3928225 | E8: 5.122272 | F8: 0.21334572 | G8: 0.50523365 | H8: =C8*$M$2/0.607 -> 0.22376844 | I8: =D8*$M$2/0.607 -> 0.45559644 | J8: =1/((1/(H8^2))-(1.33333333333333/(G8^2))) -> 0.067807165 | K8: =(J8*(E8-E7)+0.5*(E8-E7)*(J7-J8)) -> 0.047039178 | L8: =SUM(K$3:$K8) -> 0.36886182 | M8: =$B$38/((L8*$B$43+1)) -> 0.69678348 | N8: =(6*F8*G8*SQRT(9*(G8^6)*(0.0002^2)+16*(F8^6)*(0.0002)^2))/((4*F8^2 - 3*G8^2)^2) -> 0.00014761407 | O8: =(((E8-E7)/2)^2)*(N8^2+N9^2) -> 5.0935318e-09 | P8: =SUM(O$2:$O8) -> 6.3622806e-08 | Q8: =SQRT(((M35*0.001)^2)+((N35*0.02)^2)+((O35*P8)^2)) -> 0.0010103129 | R8: =M8^3 -> 0.33829342 | S8: =3*Q8/M8*R8 -> 0.0014715427 | T8: =R8/$R$2 -> 0.96956196 | U8: =T8*3*SQRT((Q8/M8)^2)+(0.001/$M$2)^2 -> 0.0042195156 | V8: =$B$40/((M8/$M$2)^3) -> 6.281187 | W8: =(SQRT((0.02/$V$2)^2+(9*(0.001/$M$2)^2)+(9*(Q8/M8)^2))*V8) -> 0.043456547 | X8: =(1-((V8/$B$40)^0.66666667))/2 -> -0.010410531 | Y8: =(SQRT((Q8/M8)^2 + (0.0002/F8)^2))*AD8 -> 0.011278206 | Z8: =SQRT((Q8/M8)^2 + (0.0002/G8)^2)*AE8 -> 0.0041457574 | AA8: =SQRT((Q8/M8)^2 + (0.0002/H8)^2)*AC8 -> 0.010607705 | AB8: =SQRT((Q8/M8)^2 + (0.0002/I8)^2)*#REF! -> #REF! | AC8: =2*M8/H8 -> 6.2277189 | AD8: =2*M8/F8 -> 6.5319659 | AE8: =2*M8/G8 -> 2.7582624 | AF8: =V8*AC8*AC8 -> 243.61259 | AG8: =V8*AD8^2 -> 267.99676 | AH8: =V8*AE8^2 -> 47.787343 | AI8: =1.5*AF8-AG8/2-2*AH8 -> 135.84582 | AK8: =M8 -> 0.69678348 | AL8: =AK8^3 -> 0.33829342 | AM8: =$AL$2/AL8 -> 1.0313936 | AN8: =$AN$2/((AK8/$AK$2)^3) -> 6.281187 | AO8: =-3*$AP$31*((1-2*AP8)^2.5)*(1+3*(4-$AR$31)*AP8/2)*AP8 -> 5.2894865 | AP8: =0.5*(1-AM8^0.666666667) -> -0.010410531 | AQ8: =(1-2*AP8)^(3.5)*($AP$26-$AT$26*AP8)+AO8*3 -> 267.82507 | AR8: =(1-2*AP8)^(3.5)*($AP$28-$AT$28*AP8)+AO8*1 -> 47.508984 | AS8: =(1-2*AP8)^(3.5)*($AP$27-$AT$27*AP8)+AO8*1 -> 137.8921 | AT8: =AQ8-AG8 -> -0.17168878 | AU8: =AR8-AH8 -> -0.27835897 | AV8: =AS8-AI8 -> 2.0462836 | AW8: =AO8-A8 -> 0.16721446 | BA8: 0.21334572 | BB8: 0.50523365 | BC8: =C8*$BE$2/0.607 -> 0.22376844 | BD8: =D8*$BE$2/0.607 -> 0.45559644 | BE8: 0.69691659 | BF8: =BE8^3 -> 0.33848733 | BG8: =$BF$2/BF8 -> 1.0308027 | BH8: =$BH$2/((BE8/$BE$2)^3) -> 6.2775887 | BI8: =-3*$BG$36*((1-2*BJ8)^2.5)*(1+3*(4-$BG$37)*BJ8/2)*BJ8 -> 5.1841635 | BJ8: =0.5*(1-BG8^0.666666667) -> -0.010215578 | BK8: =BI8-E8 -> 0.061891455 | BL8: =2*BE8/BC8 -> 6.2289086 | BM8: =2*BE8/BA8 -> 6.5332137 | BN8: =2*BE8/BB8 -> 2.7587893 | BO8: =BH8*BL8*BL8 -> 243.56606 | BP8: =BH8*BM8^2 -> 267.94557 | BQ8: =BH8*BN8^2 -> 47.778216 | BR8: =1.5*BO8-BP8/2-2*BQ8 -> 135.81987 | BS8: =(1-2*BJ8)^(3.5)*($BG$25-$BK$25*BJ8)+BI8*3 -> 267.57372 | BT8: =(1-2*BJ8)^(3.5)*($BG$27-$BK$27*BJ8)+BI8*1 -> 47.498346 | BU8: =(1-2*BJ8)^(3.5)*($BG$26-$BK$26*BJ8)+BI8*1 -> 137.75316 | BV8: =BS8-BP8 -> -0.37185556 | BW8: =BU8-BR8 -> 1.9332907 | BX8: =BT8-BQ8 -> -0.27986968 | BY8: =(BS8+2*BU8)/3 -> 181.02668 | BZ8: =SQRT(BS8/BH8) -> 6.5286787 | CA8: =SQRT(BT8/BH8) -> 2.7506974 | CB8: =SQRT((0.33333334*(BS8+2*BU8+4*BT8))/BH8) -> 6.2390244 | CC8: =SQRT((0.3333334*(BS8-BU8+BT8))/BH8) -> 3.0684603 | CD8: =(BS8-BU8+3*BT8)/5 -> 54.463119 | CE8: =((5*(BS8-BU8)*BT8)/(3*(BS8-BU8)+4*BT8)) -> 53.20742 | CF8: =(CD8+CE8)/2 -> 53.835269 | CG8: =BZ8-AD8 -> -0.003287173 | CH8: =CA8-AE8 -> -0.0075650121 | CI8: =CB8-AC8 -> 0.011305548
A9: 5.7679366 | B9: 210 | C9: 0.1919993 | D9: 0.39099582 | E9: 5.7679366 | F9: 0.21174572 | G9: 0.50423365 | H9: =C9*$M$2/0.607 -> 0.22268123 | I9: =D9*$M$2/0.607 -> 0.45347786 | J9: =1/((1/(H9^2))-(1.33333333333333/(G9^2))) -> 0.067013107 | K9: =(J9*(E9-E8)+0.5*(E9-E8)*(J8-J9)) -> 0.043524335 | L9: =SUM(K$3:$K9) -> 0.41238615 | M9: =$B$38/((L9*$B$43+1)) -> 0.69594171 | N9: =(6*F9*G9*SQRT(9*(G9^6)*(0.0002^2)+16*(F9^6)*(0.0002)^2))/((4*F9^2 - 3*G9^2)^2) -> 0.00014548021 | O9: =(((E9-E8)/2)^2)*(N9^2+N10^2) -> 4.3650511e-09 | P9: =SUM(O$2:$O9) -> 6.7987857e-08 | Q9: =SQRT(((M36*0.001)^2)+((N36*0.02)^2)+((O36*P9)^2)) -> 0.0010115228 | R9: =M9^3 -> 0.33706883 | S9: =3*Q9/M9*R9 -> 0.0014697472 | T9: =R9/$R$2 -> 0.96605226 | U9: =T9*3*SQRT((Q9/M9)^2)+(0.001/$M$2)^2 -> 0.0042143698 | V9: =$B$40/((M9/$M$2)^3) -> 6.3040068 | W9: =(SQRT((0.02/$V$2)^2+(9*(0.001/$M$2)^2)+(9*(Q9/M9)^2))*V9) -> 0.043655982 | X9: =(1-((V9/$B$40)^0.66666667))/2 -> -0.01164601 | Y9: =(SQRT((Q9/M9)^2 + (0.0002/F9)^2))*AD9 -> 0.011394289 | Z9: =SQRT((Q9/M9)^2 + (0.0002/G9)^2)*AE9 -> 0.0041588313 | AA9: =SQRT((Q9/M9)^2 + (0.0002/H9)^2)*AC9 -> 0.010679519 | AB9: =SQRT((Q9/M9)^2 + (0.0002/I9)^2)*#REF! -> #REF! | AC9: =2*M9/H9 -> 6.2505645 | AD9: =2*M9/F9 -> 6.5733721 | AE9: =2*M9/G9 -> 2.7603938 | AF9: =V9*AC9*AC9 -> 246.29475 | AG9: =V9*AD9^2 -> 272.39123 | AH9: =V9*AE9^2 -> 48.035106 | AI9: =1.5*AF9-AG9/2-2*AH9 -> 137.1763 | AK9: =M9 -> 0.69594171 | AL9: =AK9^3 -> 0.33706883 | AM9: =$AL$2/AL9 -> 1.0351407 | AN9: =$AN$2/((AK9/$AK$2)^3) -> 6.3040068 | AO9: =-3*$AP$31*((1-2*AP9)^2.5)*(1+3*(4-$AR$31)*AP9/2)*AP9 -> 5.9510408 | AP9: =0.5*(1-AM9^0.666666667) -> -0.01164601 | AQ9: =(1-2*AP9)^(3.5)*($AP$26-$AT$26*AP9)+AO9*3 -> 271.24718 | AR9: =(1-2*AP9)^(3.5)*($AP$28-$AT$28*AP9)+AO9*1 -> 47.636538 | AS9: =(1-2*AP9)^(3.5)*($AP$27-$AT$27*AP9)+AO9*1 -> 139.85188 | AT9: =AQ9-AG9 -> -1.144044 | AU9: =AR9-AH9 -> -0.39856808 | AV9: =AS9-AI9 -> 2.6755711 | AW9: =AO9-A9 -> 0.18310427 | BA9: 0.21174572 | BB9: 0.50423365 | BC9: =C9*$BE$2/0.607 -> 0.22268123 | BD9: =D9*$BE$2/0.607 -> 0.45347786 | BE9: 0.69599234 | BF9: =BE9^3 -> 0.3371424 | BG9: =$BF$2/BF9 -> 1.0349148 | BH9: =$BH$2/((BE9/$BE$2)^3) -> 6.3026313 | BI9: =-3*$BG$36*((1-2*BJ9)^2.5)*(1+3*(4-$BG$37)*BJ9/2)*BJ9 -> 5.9103578 | BJ9: =0.5*(1-BG9^0.666666667) -> -0.011571579 | BK9: =BI9-E9 -> 0.14242126 | BL9: =2*BE9/BC9 -> 6.2510192 | BM9: =2*BE9/BA9 -> 6.5738503 | BN9: =2*BE9/BB9 -> 2.7605946 | BO9: =BH9*BL9*BL9 -> 246.27684 | BP9: =BH9*BM9^2 -> 272.37141 | BQ9: =BH9*BN9^2 -> 48.031612 | BR9: =1.5*BO9-BP9/2-2*BQ9 -> 137.16633 | BS9: =(1-2*BJ9)^(3.5)*($BG$25-$BK$25*BJ9)+BI9*3 -> 271.4267 | BT9: =(1-2*BJ9)^(3.5)*($BG$27-$BK$27*BJ9)+BI9*1 -> 47.638598 | BU9: =(1-2*BJ9)^(3.5)*($BG$26-$BK$26*BJ9)+BI9*1 -> 139.96363 | BV9: =BS9-BP9 -> -0.9447072 | BW9: =BU9-BR9 -> 2.7973024 | BX9: =BT9-BQ9 -> -0.39301396 | BY9: =(BS9+2*BU9)/3 -> 183.78465 | BZ9: =SQRT(BS9/BH9) -> 6.5624399 | CA9: =SQRT(BT9/BH9) -> 2.7492772 | CB9: =SQRT((0.33333334*(BS9+2*BU9+4*BT9))/BH9) -> 6.2640261 | CC9: =SQRT((0.3333334*(BS9-BU9+BT9))/BH9) -> 3.0777142 | CD9: =(BS9-BU9+3*BT9)/5 -> 54.875774 | CE9: =((5*(BS9-BU9)*BT9)/(3*(BS9-BU9)+4*BT9)) -> 53.532652 | CF9: =(CD9+CE9)/2 -> 54.204213 | CG9: =BZ9-AD9 -> -0.010932264 | CH9: =CA9-AE9 -> -0.011116541 | CI9: =CB9-AC9 -> 0.013461568
