Workbook
Name alpha_100: Inputs!$M$6
Name alpha_111: Inputs!$M$15
Name CutoffLowBar: Inputs!$M$23
Name CutoffOilBar: Inputs!$M$22
Name gamma_100: Inputs!$M$8
Name gamma_111: Inputs!$M$17
Name gC11_0: Global_Cook!$CW$4
Name gC11a: Global_Cook!$CW$14
Name gC11p: Global_Cook!$CW$7
Name gC12_0: Global_Cook!$CW$5
Name gC12a: Global_Cook!$CW$15
Name gC12p: Global_Cook!$CW$8
Name gC44_0: Global_Cook!$CW$6
Name gC44a: Global_Cook!$CW$16
Name gC44p: Global_Cook!$CW$9
Name gK0: Global_Cook!$CW$11
Name gK0p: Global_Cook!$CW$12
Name Lfin_100: Inputs!$M$5
Name Lfin_111: Inputs!$M$14
Name Linit_100: Inputs!$M$4
Name Linit_111: Inputs!$M$13
Name nData: 22
Name NormalizeFlag: Inputs!$M$24
Name rho_100: Inputs!$M$7
Name rho_111: Inputs!$M$16
Name SBR0_100: Inputs!$M$10
Name SBR0_111: Inputs!$M$19
Name scal_100: Inputs!$M$11
Name scal_111: Inputs!$M$20
Name T_100: Inputs!$M$9
Name T_111: Inputs!$M$18

Sheet Summary
A1: SIMPLIFIED VANADIUM Cij Cij' SUMMARY (all fits live-linked; edit Inputs, re-run each sheet's Solver)
B3: No Vs111 FS | C3: No Vs111 CK | D3: No Vp111 FS | E3: No Vp111 CK | F3: No Vs100 FS | G3: No Vs100 CK | H3: No Vp100 FS | I3: No Vp100 CK | J3: GLOBAL FS | K3: GLOBAL CK | M3: Katahara 1979 | N3: Lenkkeri 1978 | O3: Greiner 1979
A4: C11_0 (GPa) | B4: =FS_NoVs111!AM4 -> 240.96035 | C4: =Cook_NoVs111!AT4 -> 240.71785 | D4: =FS_NoVp111!AM4 -> 240.83323 | E4: =Cook_NoVp111!AT4 -> 241.08939 | F4: =FS_NoVs100!AM4 -> 240.84873 | G4: =Cook_NoVs100!AT4 -> 240.97216 | H4: =FS_NoVp100!AM4 -> 229.36895 | I4: =Cook_NoVp100!AT4 -> 229.5456 | J4: =Global_FS!AT4 -> 239.4993 | K4: =Global_Cook!DA4 -> 238.85608 | M4: 230.9 | N4: 235.7 | O4: 235.89
A5: C12_0 (GPa) | B5: =FS_NoVs111!AM5 -> 112.06575 | C5: =Cook_NoVs111!AT5 -> 111.92081 | D5: =FS_NoVp111!AM5 -> 128.74145 | E5: =Cook_NoVp111!AT5 -> 128.90556 | F5: =FS_NoVs100!AM5 -> 123.20384 | G5: =Cook_NoVs100!AT5 -> 123.26424 | H5: =FS_NoVp100!AM5 -> 117.43415 | I5: =Cook_NoVp100!AT5 -> 117.5164 | J5: =Global_FS!AT5 -> 121.24044 | K5: =Global_Cook!DA5 -> 121.75227 | M5: 120.02 | N5: 126.5 | O5: 120.76
A6: C44_0 (GPa) | B6: =FS_NoVs111!AM6 -> 46.819079 | C6: =Cook_NoVs111!AT6 -> 46.789339 | D6: =FS_NoVp111!AM6 -> 46.761629 | E6: =Cook_NoVp111!AT6 -> 46.760043 | F6: =FS_NoVs100!AM6 -> 41.226119 | G6: =Cook_NoVs100!AT6 -> 41.196739 | H6: =FS_NoVp100!AM6 -> 46.816589 | I6: =Cook_NoVp100!AT6 -> 46.789541 | J6: =Global_FS!AT6 -> 45.46439 | K6: =Global_Cook!DA6 -> 45.196513 | M6: 43.36 | N6: 43.6 | O6: 46.55
A7: C11' | B7: =FS_NoVs111!AM7 -> 5.4419713 | C7: =Cook_NoVs111!AT7 -> 5.3943352 | D7: =FS_NoVp111!AM7 -> 5.3801597 | E7: =Cook_NoVp111!AT7 -> 5.2862824 | F7: =FS_NoVs100!AM7 -> 5.3991815 | G7: =Cook_NoVs100!AT7 -> 5.3201903 | H7: =FS_NoVp100!AM7 -> 5.9623945 | I7: =Cook_NoVp100!AT7 -> 5.8541865 | J7: =Global_FS!AT7 -> 5.5161185 | K7: =Global_Cook!DA7 -> 5.329709 | M7: 5.65
A8: C12' | B8: =FS_NoVs111!AM8 -> 3.4771143 | C8: =Cook_NoVs111!AT8 -> 3.4396087 | D8: =FS_NoVp111!AM8 -> 2.7363926 | E8: =Cook_NoVp111!AT8 -> 2.6829994 | F8: =FS_NoVs100!AM8 -> 2.9762004 | G8: =Cook_NoVs100!AT8 -> 2.9314957 | H8: =FS_NoVp100!AM8 -> 3.268427 | I8: =Cook_NoVp100!AT8 -> 3.2082419 | J8: =Global_FS!AT8 -> 3.0938019 | K8: =Global_Cook!DA8 -> 2.8658596 | M8: 3.566
A9: C44' | B9: =FS_NoVs111!AM9 -> 0.25171875 | C9: =Cook_NoVs111!AT9 -> 0.255884 | D9: =FS_NoVp111!AM9 -> 0.25693971 | E9: =Cook_NoVp111!AT9 -> 0.25806269 | F9: =FS_NoVs100!AM9 -> 0.48443352 | G9: =Cook_NoVs100!AT9 -> 0.48531966 | H9: =FS_NoVp100!AM9 -> 0.25140052 | I9: =Cook_NoVp100!AT9 -> 0.25585661 | J9: =Global_FS!AT9 -> 0.30700295 | K9: =Global_Cook!DA9 -> 0.3404298 | M9: 0.185
A10: K0 (GPa) | B10: =FS_NoVs111!AM10 -> 155.03062 | C10: =Cook_NoVs111!AT10 -> 154.85316 | D10: =FS_NoVp111!AM10 -> 166.10538 | E10: =Cook_NoVp111!AT10 -> 166.30017 | F10: =FS_NoVs100!AM10 -> 162.41881 | G10: =Cook_NoVs100!AT10 -> 162.50021 | H10: =FS_NoVp100!AM10 -> 154.74575 | I10: =Cook_NoVp100!AT10 -> 154.85947 | J10: =Global_FS!AT10 -> 160.66006 | K10: =Global_Cook!DA10 -> 160.78687 | M10: =(M4+2*M5)/3 -> 156.98 | N10: =(N4+2*N5)/3 -> 162.9 | O10: =(O4+2*O5)/3 -> 159.13667
A11: K0' | B11: =FS_NoVs111!AM11 -> 4.1320666 | C11: =Cook_NoVs111!AT11 -> 4.0911842 | D11: =FS_NoVp111!AM11 -> 3.6176483 | E11: =Cook_NoVp111!AT11 -> 3.5507604 | F11: =FS_NoVs100!AM11 -> 3.7838608 | G11: =Cook_NoVs100!AT11 -> 3.7277273 | H11: =FS_NoVp100!AM11 -> 4.1664162 | I11: =Cook_NoVp100!AT11 -> 4.0902234 | J11: =Global_FS!AT11 -> 3.9012408 | K11: =Global_Cook!DA11 -> 3.6871428
A12: G Hill 0 (GPa) | B12: =FS_NoVs111!AM14 -> 53.220663 | C12: =Cook_NoVs111!AT14 -> 53.184245 | D12: =FS_NoVp111!AM14 -> 50.277678 | E12: =Cook_NoVp111!AT14 -> 50.293207 | F12: =FS_NoVs100!AM14 -> 47.547135 | G12: =Cook_NoVs100!AT14 -> 47.537238 | H12: =FS_NoVp100!AM14 -> 50.284807 | I12: =Cook_NoVp100!AT14 -> 50.284395 | J12: =Global_FS!AT14 -> 50.51284 | K12: =Global_Cook!DA14 -> 50.136414
A13: total misfit | B13: =FS_NoVs111!AM15 -> 2.328486 | C13: =Cook_NoVs111!AT15 -> 3.5582994 | D13: =FS_NoVp111!AM15 -> 1.7693238 | E13: =Cook_NoVp111!AT15 -> 5.2648649 | F13: =FS_NoVs100!AM15 -> 1.2627223 | G13: =Cook_NoVs100!AT15 -> 3.6179983 | H13: =FS_NoVp100!AM15 -> 0.63238467 | I13: =Cook_NoVp100!AT15 -> 2.7608174 | J13: =Global_FS!AT15 -> 1452.0622 | K13: =Global_Cook!DA15 -> 1835.6762

Sheet Inputs
A1: INPUTS - paste raw measured data here (100 block cols A-D, 111 block cols F-I). Constants at cols L-M.
A3: Oil bar | B3: SBR 100 (S buffer) | C3: 2TP 100 (raw) | D3: 2TS 100 (raw) | F3: Oil bar | G3: SBR 111 (S buffer) | H3: 2TP 111 (raw) | I3: 2TS 111 (raw)
A4: 0 | B4: 1.1602 | C4: 0.22919993 | D4: 0.51092692 | F4: 0 | G4: 1.1382 | H4: 0.2029 | I4: 0.4194 | L4: Linit 100 (initial length, mm) | M4: 0.712
A5: 30 | B5: 1.1596 | C5: 0.22474572 | D5: 0.50723365 | F5: 30 | G5: 1.1162 | H5: 0.2011 | I5: 0.4126 | L5: Lfin 100 (final/used length, mm) | M5: 0.704
A6: 60 | B6: 1.1526 | C6: 0.22094572 | D6: 0.50583365 | F6: 60 | G6: 1.112 | H6: 0.1995 | I6: 0.4052 | L6: alpha 100 (thermal expansion) | M6: 4.6e-05
A7: 90 | B7: 1.1486 | C7: 0.21874572 | D7: 0.50583365 | F7: 90 | G7: 1.1056 | H7: 0.1969 | I7: 0.4028 | L7: rho 100 (density g/cc) | M7: 6.09
A8: 120 | B8: 1.1442 | C8: 0.21654572 | D8: 0.50523365 | F8: 120 | G8: 1.1034 | H8: 0.1953 | I8: 0.3972 | L8: gamma 100 (Gruneisen) | M8: 1.23
A9: 150 | B9: 1.1396 | C9: 0.21474572 | D9: 0.50523365 | F9: 150 | G9: 1.0978 | H9: 0.1941 | I9: 0.396 | L9: T 100 (K) | M9: 300
A10: 180 | B10: 1.1364 | C10: 0.21334572 | D10: 0.50523365 | F10: 180 | G10: 1.0942 | H10: 0.1929 | I10: 0.3926 | L10: SBR0 100 (0-P buffer S-time = first measured pt; source O24) | M10: 1.1602
A11: 210 | B11: 1.1334 | C11: 0.21174572 | D11: 0.50423365 | F11: 210 | G11: 1.0914 | H11: 0.1917 | I11: 0.3894 | L11: scalar 100 =(1+a*g*T)/(12*rho*Lfin^2) | M11: =(1+M6*M8*M9)/(12*M7*M5^2) -> 0.028077989
A12: 240 | B12: 1.1296 | C12: 0.21074572 | D12: 0.50423365 | F12: 240 | G12: 1.0862 | H12: 0.1905 | I12: 0.3894
A13: 270 | B13: 1.1264 | C13: 0.20914572 | D13: 0.50463365 | F13: 270 | G13: 1.0832 | H13: 0.1889 | I13: 0.3866 | L13: Linit 111 (initial length, mm) | M13: 0.623
A14: 300 | B14: 1.1238 | C14: 0.20814572 | D14: 0.50383365 | F14: 300 | G14: 1.0804 | H14: 0.1881 | I14: 0.3846 | L14: Lfin 111 (final/used length, mm) | M14: 0.607
A15: 330 | B15: 1.1206 | C15: 0.20734572 | D15: 0.50403365 | F15: 330 | G15: 1.0758 | H15: 0.1875 | I15: 0.3844 | L15: alpha 111 (thermal expansion) | M15: 4.6e-05
A16: 360 | B16: 1.1178 | C16: 0.20634572 | D16: 0.50443365 | F16: 360 | G16: 1.0726 | H16: 0.1863 | I16: 0.383 | L16: rho 111 (density g/cc) | M16: 6.09
A17: 390 | B17: 1.1158 | C17: 0.20554572 | D17: 0.50383365 | F17: 390 | G17: 1.0708 | H17: 0.1859 | I17: 0.3812 | L17: gamma 111 (Gruneisen) | M17: 1.23
A18: 420 | B18: 1.1132 | C18: 0.20474572 | D18: 0.50323365 | F18: 420 | G18: 1.068 | H18: 0.1851 | I18: 0.38 | L18: T 111 (K) | M18: 300
A19: 450 | B19: 1.1108 | C19: 0.20394572 | D19: 0.50443365 | F19: 450 | G19: 1.0644 | H19: 0.1845 | I19: 0.3798 | L19: SBR0 111 (pressure_fit, 0-P buffer S-time) | M19: 1.1225
A20: 480 | B20: 1.1094 | C20: 0.20334572 | D20: 0.50523365 | F20: 480 | G20: 1.0626 | H20: 0.1839 | I20: 0.3788 | L20: scalar 111 =(1+a*g*T)/(12*rho*Lfin^2) | M20: =(1+M15*M17*M18)/(12*M16*M14^2) -> 0.037768865
A21: 510 | B21: 1.1084 | C21: 0.20234572 | D21: 0.50563365 | F21: 510 | G21: 1.0614 | H21: 0.1829 | I21: 0.3774
A22: 540 | B22: 1.1066 | C22: 0.20174572 | D22: 0.50523365 | F22: 540 | G22: 1.0594 | H22: 0.1825 | I22: 0.3763 | L22: Cutoff HIGH oil bar (fit uses oil <= this) | M22: 420
A23: 570 | B23: 1.1042 | C23: 0.20094572 | D23: 0.50583365 | F23: 570 | G23: 1.0568 | H23: 0.1813 | I23: 0.3766 | L23: Cutoff LOW oil bar (fit uses oil >= this) | M23: 120
A24: 600 | B24: 1.103 | C24: 0.20034572 | D24: 0.50703365 | F24: 600 | G24: 1.0552 | H24: 0.1805 | I24: 0.3762 | L24: Normalize flag (0/1, global fits) | M24: 0
A25: 630 | B25: 1.1022 | C25: 0.19974572 | D25: 0.50683365 | F25: 630 | G25: 1.0546 | H25: 0.1801 | I25: 0.3746

Sheet Align
A1: ALIGN - master pressure = 100 calibration; 111 travel times resampled onto master P via 6th-order polynomial (LINEST). | K1: poly coeffs c6..c0 ->
J2: 2TP111: | K2: =INDEX(LINEST(Inputs!$H$4:$H$25,$E$4:$E$25^{1,2,3,4,5,6}),1,1) -> -1.4769646e-08 | L2: =INDEX(LINEST(Inputs!$H$4:$H$25,$E$4:$E$25^{1,2,3,4,5,6}),1,2) -> 6.0182297e-07 | M2: =INDEX(LINEST(Inputs!$H$4:$H$25,$E$4:$E$25^{1,2,3,4,5,6}),1,3) -> -9.4365267e-06 | N2: =INDEX(LINEST(Inputs!$H$4:$H$25,$E$4:$E$25^{1,2,3,4,5,6}),1,4) -> 6.9849465e-05 | O2: =INDEX(LINEST(Inputs!$H$4:$H$25,$E$4:$E$25^{1,2,3,4,5,6}),1,5) -> -0.00019504809 | P2: =INDEX(LINEST(Inputs!$H$4:$H$25,$E$4:$E$25^{1,2,3,4,5,6}),1,6) -> -0.0017595092 | Q2: =INDEX(LINEST(Inputs!$H$4:$H$25,$E$4:$E$25^{1,2,3,4,5,6}),1,7) -> 0.20385318
A3: Oil bar | B3: P master (GPa) | C3: tP100 | D3: tS100 | E3: P111 (GPa) | F3: tP111 aligned | G3: tS111 aligned | J3: 2TS111: | K3: =INDEX(LINEST(Inputs!$I$4:$I$25,$E$4:$E$25^{1,2,3,4,5,6}),1,1) -> -1.9658081e-08 | L3: =INDEX(LINEST(Inputs!$I$4:$I$25,$E$4:$E$25^{1,2,3,4,5,6}),1,2) -> 1.013512e-06 | M3: =INDEX(LINEST(Inputs!$I$4:$I$25,$E$4:$E$25^{1,2,3,4,5,6}),1,3) -> -1.9930178e-05 | N3: =INDEX(LINEST(Inputs!$I$4:$I$25,$E$4:$E$25^{1,2,3,4,5,6}),1,4) -> 0.00017486101 | O3: =INDEX(LINEST(Inputs!$I$4:$I$25,$E$4:$E$25^{1,2,3,4,5,6}),1,5) -> -0.0004369497 | P3: =INDEX(LINEST(Inputs!$I$4:$I$25,$E$4:$E$25^{1,2,3,4,5,6}),1,6) -> -0.0048072238 | Q3: =INDEX(LINEST(Inputs!$I$4:$I$25,$E$4:$E$25^{1,2,3,4,5,6}),1,7) -> 0.41892602
A4: =Inputs!A4 -> 0 | B4: =249.7*(1-Inputs!B4/SBR0_100) -> 0 | C4: =Inputs!C4 -> 0.22919993 | D4: =Inputs!D4 -> 0.51092692 | E4: =249.7*(1-Inputs!G4/SBR0_111) -> -3.4924633 | F4: =SUMPRODUCT($K$2:$P$2,B4^{6,5,4,3,2,1})+$Q$2 -> 0.20385318 | G4: =SUMPRODUCT($K$3:$P$3,B4^{6,5,4,3,2,1})+$Q$3 -> 0.41892602
A5: =Inputs!A5 -> 30 | B5: =249.7*(1-Inputs!B5/SBR0_100) -> 0.12913291 | C5: =Inputs!C5 -> 0.22474572 | D5: =Inputs!D5 -> 0.50723365 | E5: =249.7*(1-Inputs!G5/SBR0_111) -> 1.4014343 | F5: =SUMPRODUCT($K$2:$P$2,B5^{6,5,4,3,2,1})+$Q$2 -> 0.20362287 | G5: =SUMPRODUCT($K$3:$P$3,B5^{6,5,4,3,2,1})+$Q$3 -> 0.41829834
A6: =Inputs!A6 -> 60 | B6: =249.7*(1-Inputs!B6/SBR0_100) -> 1.6356835 | C6: =Inputs!C6 -> 0.22094572 | D6: =Inputs!D6 -> 0.50583365 | E6: =249.7*(1-Inputs!G6/SBR0_111) -> 2.3357238 | F6: =SUMPRODUCT($K$2:$P$2,B6^{6,5,4,3,2,1})+$Q$2 -> 0.20069823 | G6: =SUMPRODUCT($K$3:$P$3,B6^{6,5,4,3,2,1})+$Q$3 -> 0.41052794
A7: =Inputs!A7 -> 90 | B7: =249.7*(1-Inputs!B7/SBR0_100) -> 2.4965696 | C7: =Inputs!C7 -> 0.21874572 | D7: =Inputs!D7 -> 0.50583365 | E7: =249.7*(1-Inputs!G7/SBR0_111) -> 3.7594031 | F7: =SUMPRODUCT($K$2:$P$2,B7^{6,5,4,3,2,1})+$Q$2 -> 0.19901985 | G7: =SUMPRODUCT($K$3:$P$3,B7^{6,5,4,3,2,1})+$Q$3 -> 0.40624126
A8: =Inputs!A8 -> 120 | B8: =249.7*(1-Inputs!B8/SBR0_100) -> 3.4435442 | C8: =Inputs!C8 -> 0.21654572 | D8: =Inputs!D8 -> 0.50523365 | E8: =249.7*(1-Inputs!G8/SBR0_111) -> 4.2487929 | F8: =SUMPRODUCT($K$2:$P$2,B8^{6,5,4,3,2,1})+$Q$2 -> 0.19727344 | G8: =SUMPRODUCT($K$3:$P$3,B8^{6,5,4,3,2,1})+$Q$3 -> 0.40198653
A9: =Inputs!A9 -> 150 | B9: =249.7*(1-Inputs!B9/SBR0_100) -> 4.4335632 | C9: =Inputs!C9 -> 0.21474572 | D9: =Inputs!D9 -> 0.50523365 | E9: =249.7*(1-Inputs!G9/SBR0_111) -> 5.4945122 | F9: =SUMPRODUCT($K$2:$P$2,B9^{6,5,4,3,2,1})+$Q$2 -> 0.19557829 | G9: =SUMPRODUCT($K$3:$P$3,B9^{6,5,4,3,2,1})+$Q$3 -> 0.39814914
A10: =Inputs!A10 -> 180 | B10: =249.7*(1-Inputs!B10/SBR0_100) -> 5.122272 | C10: =Inputs!C10 -> 0.21334572 | D10: =Inputs!D10 -> 0.50523365 | E10: =249.7*(1-Inputs!G10/SBR0_111) -> 6.2953318 | F10: =SUMPRODUCT($K$2:$P$2,B10^{6,5,4,3,2,1})+$Q$2 -> 0.19446957 | G10: =SUMPRODUCT($K$3:$P$3,B10^{6,5,4,3,2,1})+$Q$3 -> 0.39583686
A11: =Inputs!A11 -> 210 | B11: =249.7*(1-Inputs!B11/SBR0_100) -> 5.7679366 | C11: =Inputs!C11 -> 0.21174572 | D11: =Inputs!D11 -> 0.50423365 | E11: =249.7*(1-Inputs!G11/SBR0_111) -> 6.9181915 | F11: =SUMPRODUCT($K$2:$P$2,B11^{6,5,4,3,2,1})+$Q$2 -> 0.19347267 | G11: =SUMPRODUCT($K$3:$P$3,B11^{6,5,4,3,2,1})+$Q$3 -> 0.39390328
A12: =Inputs!A12 -> 240 | B12: =249.7*(1-Inputs!B12/SBR0_100) -> 6.5857783 | C12: =Inputs!C12 -> 0.21074572 | D12: =Inputs!D12 -> 0.50423365 | E12: =249.7*(1-Inputs!G12/SBR0_111) -> 8.074931 | F12: =SUMPRODUCT($K$2:$P$2,B12^{6,5,4,3,2,1})+$Q$2 -> 0.19225681 | G12: =SUMPRODUCT($K$3:$P$3,B12^{6,5,4,3,2,1})+$Q$3 -> 0.39172305
A13: =Inputs!A13 -> 270 | B13: =249.7*(1-Inputs!B13/SBR0_100) -> 7.2744872 | C13: =Inputs!C13 -> 0.20914572 | D13: =Inputs!D13 -> 0.50463365 | E13: =249.7*(1-Inputs!G13/SBR0_111) -> 8.7422806 | F13: =SUMPRODUCT($K$2:$P$2,B13^{6,5,4,3,2,1})+$Q$2 -> 0.19126642 | G13: =SUMPRODUCT($K$3:$P$3,B13^{6,5,4,3,2,1})+$Q$3 -> 0.39006856
A14: =Inputs!A14 -> 300 | B14: =249.7*(1-Inputs!B14/SBR0_100) -> 7.8340631 | C14: =Inputs!C14 -> 0.20814572 | D14: =Inputs!D14 -> 0.50383365 | E14: =249.7*(1-Inputs!G14/SBR0_111) -> 9.3651403 | F14: =SUMPRODUCT($K$2:$P$2,B14^{6,5,4,3,2,1})+$Q$2 -> 0.19048251 | G14: =SUMPRODUCT($K$3:$P$3,B14^{6,5,4,3,2,1})+$Q$3 -> 0.3888151
A15: =Inputs!A15 -> 330 | B15: =249.7*(1-Inputs!B15/SBR0_100) -> 8.5227719 | C15: =Inputs!C15 -> 0.20734572 | D15: =Inputs!D15 -> 0.50403365 | E15: =249.7*(1-Inputs!G15/SBR0_111) -> 10.38841 | F15: =SUMPRODUCT($K$2:$P$2,B15^{6,5,4,3,2,1})+$Q$2 -> 0.1895445 | G15: =SUMPRODUCT($K$3:$P$3,B15^{6,5,4,3,2,1})+$Q$3 -> 0.3873536
... A25: =Inputs!A25 -> 630 | B25: =249.7*(1-Inputs!B25/SBR0_100) -> 12.482848 | C25: =Inputs!C25 -> 0.19974572 | D25: =Inputs!D25 -> 0.50683365 | E25: =249.7*(1-Inputs!G25/SBR0_111) -> 15.104347 | F25: =SUMPRODUCT($K$2:$P$2,B25^{6,5,4,3,2,1})+$Q$2 -> 0.1847644 | G25: =SUMPRODUCT($K$3:$P$3,B25^{6,5,4,3,2,1})+$Q$3 -> 0.37985075

Sheet FS_NoVs111
A3: Oil bar | B3: P (GPa) | C3: tP100 | D3: tS100 | E3: tP111 | F3: tS111 | G3: L fit | H3: L111 | I3: V0/V | J3: rho | K3: f | L3: Vp100 | M3: Vs100 | N3: Vp111 | O3: Vs111 | P3: rVp111^2 | Q3: rVs111^2 | R3: C11 meas | S3: C12 meas | T3: C44 meas | U3: P_FS | V3: C11 mod | W3: C12 mod | X3: C44 mod | Y3: dP | Z3: dC11 | AA3: dC12 | AB3: dC44 | AC3: gated sq | AD3: K bulk | AE3: GV | AF3: GR | AG3: GH | AI3: FIT PARAMS | AL3: OUTPUTS
A4: =Align!A4 -> 0 | B4: =Align!B4 -> 0 | C4: =Align!C4 -> 0.22919993 | D4: =Align!D4 -> 0.51092692 | E4: =Align!F4 -> 0.20385318 | F4: =Align!G4 -> 0.41892602 | G4: =Lfin_100 -> 0.704 | H4: =G4*Lfin_111/Lfin_100 -> 0.607 | I4: =($G$4/G4)^3 -> 1 | J4: =rho_100*I4 -> 6.09 | K4: =0.5*(1-I4^(2/3)) -> 0 | L4: =2*G4/C4 -> 6.1431082 | M4: =2*G4/D4 -> 2.7557757 | N4: =2*H4/E4 -> 5.9552664 | O4: =2*H4/F4 -> 2.8978863 | P4: =J4*N4^2 -> 215.98305 | Q4: =J4*O4^2 -> 51.142269 | R4: =J4*L4^2 -> 229.82307 | S4: =1.5*P4-0.5*R4-2*T4 -> 116.56447 | T4: =J4*M4^2 -> 46.249286 | U4: =-3*$AI$11*((1-2*K4)^2.5)*(1+1.5*(4-$AI$12)*K4)*K4 -> 0 | V4: =((1-2*K4)^3.5)*($AI$4-$AI$14*K4)+3*U4 -> 240.96035 | W4: =((1-2*K4)^3.5)*($AI$5-$AI$15*K4)+1*U4 -> 112.06575 | X4: =((1-2*K4)^3.5)*($AI$6-$AI$16*K4)+1*U4 -> 46.819079 | Y4: =U4-B4 -> 0 | Z4: =V4-R4 -> 11.137281 | AA4: =W4-S4 -> -4.4987251 | AB4: =X4-T4 -> 0.56979298 | AC4: =IF(AND(A4>=CutoffLowBar,A4<=CutoffOilBar),Y4^2+Z4^2+AA4^2+AB4^2,0) -> 0 | AD4: =(V4+2*W4)/3 -> 155.03062 | AE4: =(V4-W4+3*X4)/5 -> 53.870368 | AF4: =5*(V4-W4)*X4/(3*(V4-W4)+4*X4) -> 52.570957 | AG4: =(AE4+AF4)/2 -> 53.220663 | AH4: C11_0 | AI4: 240.96035 | AL4: C11_0 | AM4: =$AI$4 -> 240.96035
A5: =Align!A5 -> 30 | B5: =Align!B5 -> 0.12913291 | C5: =Align!C5 -> 0.22474572 | D5: =Align!D5 -> 0.50723365 | E5: =Align!F5 -> 0.20362287 | F5: =Align!G5 -> 0.41829834 | G5: 0.70328571 | H5: =G5*Lfin_111/Lfin_100 -> 0.60638413 | I5: =($G$4/G5)^3 -> 1.00305 | J5: =rho_100*I5 -> 6.1085746 | K5: =0.5*(1-I5^(2/3)) -> -0.0010161566 | L5: =2*G5/C5 -> 6.2585015 | M5: =2*G5/D5 -> 2.7730247 | N5: =2*H5/E5 -> 5.9559532 | O5: =2*H5/F5 -> 2.8992902 | P5: =J5*N5^2 -> 216.69178 | Q5: =J5*O5^2 -> 51.347967 | R5: =J5*L5^2 -> 239.26579 | S5: =1.5*P5-0.5*R5-2*T5 -> 111.45898 | T5: =J5*M5^2 -> 46.972898 | U5: =-3*$AI$11*((1-2*K5)^2.5)*(1+1.5*(4-$AI$12)*K5)*K5 -> 0.47510666 | V5: =((1-2*K5)^3.5)*($AI$4-$AI$14*K5)+3*U5 -> 243.54013 | W5: =((1-2*K5)^3.5)*($AI$5-$AI$15*K5)+1*U5 -> 113.71625 | X5: =((1-2*K5)^3.5)*($AI$6-$AI$16*K5)+1*U5 -> 46.936494 | Y5: =U5-B5 -> 0.34597375 | Z5: =V5-R5 -> 4.2743393 | AA5: =W5-S5 -> 2.2572668 | AB5: =X5-T5 -> -0.036404529 | AC5: =IF(AND(A5>=CutoffLowBar,A5<=CutoffOilBar),Y5^2+Z5^2+AA5^2+AB5^2,0) -> 0 | AD5: =(V5+2*W5)/3 -> 156.99087 | AE5: =(V5-W5+3*X5)/5 -> 54.126673 | AF5: =5*(V5-W5)*X5/(3*(V5-W5)+4*X5) -> 52.783193 | AG5: =(AE5+AF5)/2 -> 53.454933 | AH5: C12_0 | AI5: 112.06575 | AL5: C12_0 | AM5: =$AI$5 -> 112.06575
A6: =Align!A6 -> 60 | B6: =Align!B6 -> 1.6356835 | C6: =Align!C6 -> 0.22094572 | D6: =Align!D6 -> 0.50583365 | E6: =Align!F6 -> 0.20069823 | F6: =Align!G6 -> 0.41052794 | G6: 0.70257143 | H6: =G6*Lfin_111/Lfin_100 -> 0.60576826 | I6: =($G$4/G6)^3 -> 1.0061125 | J6: =rho_100*I6 -> 6.1272248 | K6: =0.5*(1-I6^(2/3)) -> -0.0020354141 | L6: =2*G6/C6 -> 6.3596745 | M6: =2*G6/D6 -> 2.7778754 | N6: =2*H6/E6 -> 6.0366079 | O6: =2*H6/F6 -> 2.951167 | P6: =J6*N6^2 -> 223.27997 | Q6: =J6*O6^2 -> 53.364372 | R6: =J6*L6^2 -> 247.81842 | S6: =1.5*P6-0.5*R6-2*T6 -> 116.44815 | T6: =J6*M6^2 -> 47.281293 | U6: =-3*$AI$11*((1-2*K6)^2.5)*(1+1.5*(4-$AI$12)*K6)*K6 -> 0.95670373 | V6: =((1-2*K6)^3.5)*($AI$4-$AI$14*K6)+3*U6 -> 246.14361 | W6: =((1-2*K6)^3.5)*($AI$5-$AI$15*K6)+1*U6 -> 115.38628 | X6: =((1-2*K6)^3.5)*($AI$6-$AI$16*K6)+1*U6 -> 47.051124 | Y6: =U6-B6 -> -0.67897977 | Z6: =V6-R6 -> -1.6748128 | AA6: =W6-S6 -> -1.0618701 | AB6: =X6-T6 -> -0.23016994 | AC6: =IF(AND(A6>=CutoffLowBar,A6<=CutoffOilBar),Y6^2+Z6^2+AA6^2+AB6^2,0) -> 0 | AD6: =(V6+2*W6)/3 -> 158.97206 | AE6: =(V6-W6+3*X6)/5 -> 54.38214 | AF6: =5*(V6-W6)*X6/(3*(V6-W6)+4*X6) -> 52.993355 | AG6: =(AE6+AF6)/2 -> 53.687748 | AH6: C44_0 | AI6: 46.819079 | AL6: C44_0 | AM6: =$AI$6 -> 46.819079
A7: =Align!A7 -> 90 | B7: =Align!B7 -> 2.4965696 | C7: =Align!C7 -> 0.21874572 | D7: =Align!D7 -> 0.50583365 | E7: =Align!F7 -> 0.19901985 | F7: =Align!G7 -> 0.40624126 | G7: 0.70185714 | H7: =G7*Lfin_111/Lfin_100 -> 0.60515239 | I7: =($G$4/G7)^3 -> 1.0091874 | J7: =rho_100*I7 -> 6.1459511 | K7: =0.5*(1-I7^(2/3)) -> -0.0030577851 | L7: =2*G7/C7 -> 6.4171051 | M7: =2*G7/D7 -> 2.7750512 | N7: =2*H7/E7 -> 6.0813271 | O7: =2*H7/F7 -> 2.9792759 | P7: =J7*N7^2 -> 227.29288 | Q7: =J7*O7^2 -> 54.551983 | R7: =J7*L7^2 -> 253.08558 | S7: =1.5*P7-0.5*R7-2*T7 -> 119.7377 | T7: =J7*M7^2 -> 47.329412 | U7: =-3*$AI$11*((1-2*K7)^2.5)*(1+1.5*(4-$AI$12)*K7)*K7 -> 1.4448686 | V7: =((1-2*K7)^3.5)*($AI$4-$AI$14*K7)+3*U7 -> 248.77102 | W7: =((1-2*K7)^3.5)*($AI$5-$AI$15*K7)+1*U7 -> 117.07609 | X7: =((1-2*K7)^3.5)*($AI$6-$AI$16*K7)+1*U7 -> 47.162896 | Y7: =U7-B7 -> -1.0517009 | Z7: =V7-R7 -> -4.3145656 | AA7: =W7-S7 -> -2.6616146 | AB7: =X7-T7 -> -0.16651613 | AC7: =IF(AND(A7>=CutoffLowBar,A7<=CutoffOilBar),Y7^2+Z7^2+AA7^2+AB7^2,0) -> 0 | AD7: =(V7+2*W7)/3 -> 160.9744 | AE7: =(V7-W7+3*X7)/5 -> 54.636724 | AF7: =5*(V7-W7)*X7/(3*(V7-W7)+4*X7) -> 53.201364 | AG7: =(AE7+AF7)/2 -> 53.919044 | AH7: C11' | AI7: 5.4419713 | AL7: C11' | AM7: =$AI$7 -> 5.4419713
A8: =Align!A8 -> 120 | B8: =Align!B8 -> 3.4435442 | C8: =Align!C8 -> 0.21654572 | D8: =Align!D8 -> 0.50523365 | E8: =Align!F8 -> 0.19727344 | F8: =Align!G8 -> 0.40198653 | G8: 0.69911064 | H8: =G8*Lfin_111/Lfin_100 -> 0.60278431 | I8: =($G$4/G8)^3 -> 1.0211282 | J8: =rho_100*I8 -> 6.2186705 | K8: =0.5*(1-I8^(2/3)) -> -0.0070181477 | L8: =2*G8/C8 -> 6.4569333 | M8: =2*G8/D8 -> 2.7674746 | N8: =2*H8/E8 -> 6.1111552 | O8: =2*H8/F8 -> 2.9990275 | P8: =J8*N8^2 -> 232.24382 | Q8: =J8*O8^2 -> 55.931752 | R8: =J8*L8^2 -> 259.26873 | S8: =1.5*P8-0.5*R8-2*T8 -> 123.47482 | T8: =J8*M8^2 -> 47.628272 | U8: =-3*$AI$11*((1-2*K8)^2.5)*(1+1.5*(4-$AI$12)*K8)*K8 -> 3.3845299 | V8: =((1-2*K8)^3.5)*($AI$4-$AI$14*K8)+3*U8 -> 259.10057 | W8: =((1-2*K8)^3.5)*($AI$5-$AI$15*K8)+1*U8 -> 123.76205 | X8: =((1-2*K8)^3.5)*($AI$6-$AI$16*K8)+1*U8 -> 47.564693 | Y8: =U8-B8 -> -0.059014274 | Z8: =V8-R8 -> -0.16816062 | AA8: =W8-S8 -> 0.28722999 | AB8: =X8-T8 -> -0.063578451 | AC8: =IF(AND(A8>=CutoffLowBar,A8<=CutoffOilBar),Y8^2+Z8^2+AA8^2+AB8^2,0) -> 0.11830396 | AD8: =(V8+2*W8)/3 -> 168.87489 | AE8: =(V8-W8+3*X8)/5 -> 55.60652 | AF8: =5*(V8-W8)*X8/(3*(V8-W8)+4*X8) -> 53.979644 | AG8: =(AE8+AF8)/2 -> 54.793082 | AH8: C12' | AI8: 3.4771143 | AL8: C12' | AM8: =$AI$8 -> 3.4771143
A9: =Align!A9 -> 150 | B9: =Align!B9 -> 4.4335632 | C9: =Align!C9 -> 0.21474572 | D9: =Align!D9 -> 0.50523365 | E9: =Align!F9 -> 0.19557829 | F9: =Align!G9 -> 0.39814914 | G9: 0.6977311 | H9: =G9*Lfin_111/Lfin_100 -> 0.60159485 | I9: =($G$4/G9)^3 -> 1.027197 | J9: =rho_100*I9 -> 6.2556297 | K9: =0.5*(1-I9^(2/3)) -> -0.009025062 | L9: =2*G9/C9 -> 6.4982072 | M9: =2*G9/D9 -> 2.7620136 | N9: =2*H9/E9 -> 6.1519593 | O9: =2*H9/F9 -> 3.0219573 | P9: =J9*N9^2 -> 236.75434 | Q9: =J9*O9^2 -> 57.127825 | R9: =J9*L9^2 -> 264.15458 | S9: =1.5*P9-0.5*R9-2*T9 -> 127.60933 | T9: =J9*M9^2 -> 47.722441 | U9: =-3*$AI$11*((1-2*K9)^2.5)*(1+1.5*(4-$AI$12)*K9)*K9 -> 4.3973151 | V9: =((1-2*K9)^3.5)*($AI$4-$AI$14*K9)+3*U9 -> 264.4277 | W9: =((1-2*K9)^3.5)*($AI$5-$AI$15*K9)+1*U9 -> 127.23627 | X9: =((1-2*K9)^3.5)*($AI$6-$AI$16*K9)+1*U9 -> 47.748776 | Y9: =U9-B9 -> -0.036248044 | Z9: =V9-R9 -> 0.27311902 | AA9: =W9-S9 -> -0.37306107 | AB9: =X9-T9 -> 0.02633468 | AC9: =IF(AND(A9>=CutoffLowBar,A9<=CutoffOilBar),Y9^2+Z9^2+AA9^2+AB9^2,0) -> 0.215776 | AD9: =(V9+2*W9)/3 -> 172.96675 | AE9: =(V9-W9+3*X9)/5 -> 56.087552 | AF9: =5*(V9-W9)*X9/(3*(V9-W9)+4*X9) -> 54.356585 | AG9: =(AE9+AF9)/2 -> 55.222068 | AH9: C44' | AI9: 0.25171875 | AL9: C44' | AM9: =$AI$9 -> 0.25171875
A10: =Align!A10 -> 180 | B10: =Align!B10 -> 5.122272 | C10: =Align!C10 -> 0.21334572 | D10: =Align!D10 -> 0.50523365 | E10: =Align!F10 -> 0.19446957 | F10: =Align!G10 -> 0.39583686 | G10: 0.69675193 | H10: =G10*Lfin_111/Lfin_100 -> 0.6007506 | I10: =($G$4/G10)^3 -> 1.0315338 | J10: =rho_100*I10 -> 6.2820406 | K10: =0.5*(1-I10^(2/3)) -> -0.010456769 | L10: =2*G10/C10 -> 6.5316701 | M10: =2*G10/D10 -> 2.7581375 | N10: =2*H10/E10 -> 6.1783508 | O10: =2*H10/F10 -> 3.0353444 | P10: =J10*N10^2 -> 239.79817 | Q10: =J10*O10^2 -> 57.878421 | R10: =J10*L10^2 -> 268.0089 | S10: =1.5*P10-0.5*R10-2*T10 -> 130.11379 | T10: =J10*M10^2 -> 47.789507 | U10: =-3*$AI$11*((1-2*K10)^2.5)*(1+1.5*(4-$AI$12)*K10)*K10 -> 5.1322446 | V10: =((1-2*K10)^3.5)*($AI$4-$AI$14*K10)+3*U10 -> 268.26632 | W10: =((1-2*K10)^3.5)*($AI$5-$AI$15*K10)+1*U10 -> 129.75059 | X10: =((1-2*K10)^3.5)*($AI$6-$AI$16*K10)+1*U10 -> 47.871803 | Y10: =U10-B10 -> 0.0099725668 | Z10: =V10-R10 -> 0.25741776 | AA10: =W10-S10 -> -0.36319713 | AB10: =X10-T10 -> 0.082295589 | AC10: =IF(AND(A10>=CutoffLowBar,A10<=CutoffOilBar),Y10^2+Z10^2+AA10^2+AB10^2,0) -> 0.20504808 | AD10: =(V10+2*W10)/3 -> 175.9225 | AE10: =(V10-W10+3*X10)/5 -> 56.426227 | AF10: =5*(V10-W10)*X10/(3*(V10-W10)+4*X10) -> 54.617972 | AG10: =(AE10+AF10)/2 -> 55.5221 | AL10: K0 | AM10: =$AI$11 -> 155.03062
A11: =Align!A11 -> 210 | B11: =Align!B11 -> 5.7679366 | C11: =Align!C11 -> 0.21174572 | D11: =Align!D11 -> 0.50423365 | E11: =Align!F11 -> 0.19347267 | F11: =Align!G11 -> 0.39390328 | G11: 0.69580581 | H11: =G11*Lfin_111/Lfin_100 -> 0.59993484 | I11: =($G$4/G11)^3 -> 1.0357474 | J11: =rho_100*I11 -> 6.3077014 | K11: =0.5*(1-I11^(2/3)) -> -0.011845897 | L11: =2*G11/C11 -> 6.5720885 | M11: =2*G11/D11 -> 2.7598547 | N11: =2*H11/E11 -> 6.2017529 | O11: =2*H11/F11 -> 3.0461023 | P11: =J11*N11^2 -> 242.60517 | Q11: =J11*O11^2 -> 58.527515 | R11: =J11*L11^2 -> 272.44443 | S11: =1.5*P11-0.5*R11-2*T11 -> 131.59656 | T11: =J11*M11^2 -> 48.044488 | U11: =-3*$AI$11*((1-2*K11)^2.5)*(1+1.5*(4-$AI$12)*K11)*K11 -> 5.8552803 | V11: =((1-2*K11)^3.5)*($AI$4-$AI$14*K11)+3*U11 -> 272.02138 | W11: =((1-2*K11)^3.5)*($AI$5-$AI$15*K11)+1*U11 -> 132.21892 | X11: =((1-2*K11)^3.5)*($AI$6-$AI$16*K11)+1*U11 -> 47.984428 | Y11: =U11-B11 -> 0.087343694 | Z11: =V11-R11 -> -0.42304642 | AA11: =W11-S11 -> 0.62235605 | AB11: =X11-T11 -> -0.060060203 | AC11: =IF(AND(A11>=CutoffLowBar,A11<=CutoffOilBar),Y11^2+Z11^2+AA11^2+AB11^2,0) -> 0.57753148 | AD11: =(V11+2*W11)/3 -> 178.81974 | AE11: =(V11-W11+3*X11)/5 -> 56.75115 | AF11: =5*(V11-W11)*X11/(3*(V11-W11)+4*X11) -> 54.865421 | AG11: =(AE11+AF11)/2 -> 55.808285 | AH11: K0 | AI11: =($AI$4+2*$AI$5)/3 -> 155.03062 | AL11: K0' | AM11: =$AI$12 -> 4.1320666
A12: =Align!A12 -> 240 | B12: =Align!B12 -> 6.5857783 | C12: =Align!C12 -> 0.21074572 | D12: =Align!D12 -> 0.50423365 | E12: =Align!F12 -> 0.19225681 | F12: =Align!G12 -> 0.39172305 | G12: 0.69488649 | H12: =G12*Lfin_111/Lfin_100 -> 0.59914219 | I12: =($G$4/G12)^3 -> 1.0398636 | J12: =rho_100*I12 -> 6.3327692 | K12: =0.5*(1-I12^(2/3)) -> -0.013201104 | L12: =2*G12/C12 -> 6.594549 | M12: =2*G12/D12 -> 2.7562083 | N12: =2*H12/E12 -> 6.232728 | O12: =2*H12/F12 -> 3.0590091 | P12: =J12*N12^2 -> 246.00844 | Q12: =J12*O12^2 -> 59.259119 | R12: =J12*L12^2 -> 275.39995 | S12: =1.5*P12-0.5*R12-2*T12 -> 135.09658 | T12: =J12*M12^2 -> 48.108049 | U12: =-3*$AI$11*((1-2*K12)^2.5)*(1+1.5*(4-$AI$12)*K12)*K12 -> 6.5701787 | V12: =((1-2*K12)^3.5)*($AI$4-$AI$14*K12)+3*U12 -> 275.7139 | W12: =((1-2*K12)^3.5)*($AI$5-$AI$15*K12)+1*U12 -> 134.65448 | X12: =((1-2*K12)^3.5)*($AI$6-$AI$16*K12)+1*U12 -> 48.087786 | Y12: =U12-B12 -> -0.015599588 | Z12: =V12-R12 -> 0.31395017 | AA12: =W12-S12 -> -0.44210152 | AB12: =X12-T12 -> -0.020263483 | AC12: =IF(AND(A12>=CutoffLowBar,A12<=CutoffOilBar),Y12^2+Z12^2+AA12^2+AB12^2,0) -> 0.29467242 | AD12: =(V12+2*W12)/3 -> 181.67429 | AE12: =(V12-W12+3*X12)/5 -> 57.064556 | AF12: =5*(V12-W12)*X12/(3*(V12-W12)+4*X12) -> 55.100822 | AG12: =(AE12+AF12)/2 -> 56.082689 | AH12: K0' | AI12: =($AI$7+2*$AI$8)/3 -> 4.1320666 | AL12: GV0 | AM12: =AE4 -> 53.870368
A13: =Align!A13 -> 270 | B13: =Align!B13 -> 7.2744872 | C13: =Align!C13 -> 0.20914572 | D13: =Align!D13 -> 0.50463365 | E13: =Align!F13 -> 0.19126642 | F13: =Align!G13 -> 0.39006856 | G13: 0.69386574 | H13: =G13*Lfin_111/Lfin_100 -> 0.59826208 | I13: =($G$4/G13)^3 -> 1.0444596 | J13: =rho_100*I13 -> 6.3607589 | K13: =0.5*(1-I13^(2/3)) -> -0.014712167 | L13: =2*G13/C13 -> 6.6352373 | M13: =2*G13/D13 -> 2.7499781 | N13: =2*H13/E13 -> 6.2557984 | O13: =2*H13/F13 -> 3.0674714 | P13: =J13*N13^2 -> 248.92839 | Q13: =J13*O13^2 -> 59.850804 | R13: =J13*L13^2 -> 280.04115 | S13: =1.5*P13-0.5*R13-2*T13 -> 137.16706 | T13: =J13*M13^2 -> 48.102474 | U13: =-3*$AI$11*((1-2*K13)^2.5)*(1+1.5*(4-$AI$12)*K13)*K13 -> 7.3784534 | V13: =((1-2*K13)^3.5)*($AI$4-$AI$14*K13)+3*U13 -> 279.86515 | W13: =((1-2*K13)^3.5)*($AI$5-$AI$15*K13)+1*U13 -> 137.40242 | X13: =((1-2*K13)^3.5)*($AI$6-$AI$16*K13)+1*U13 -> 48.195302 | Y13: =U13-B13 -> 0.10396627 | Z13: =V13-R13 -> -0.17600248 | AA13: =W13-S13 -> 0.23536399 | AB13: =X13-T13 -> 0.092828833 | AC13: =IF(AND(A13>=CutoffLowBar,A13<=CutoffOilBar),Y13^2+Z13^2+AA13^2+AB13^2,0) -> 0.10579926 | AD13: =(V13+2*W13)/3 -> 184.89 | AE13: =(V13-W13+3*X13)/5 -> 57.409726 | AF13: =5*(V13-W13)*X13/(3*(V13-W13)+4*X13) -> 55.356119 | AG13: =(AE13+AF13)/2 -> 56.382923 | AL13: GR0 | AM13: =AF4 -> 52.570957
A14: =Align!A14 -> 300 | B14: =Align!B14 -> 7.8340631 | C14: =Align!C14 -> 0.20814572 | D14: =Align!D14 -> 0.50383365 | E14: =Align!F14 -> 0.19048251 | F14: =Align!G14 -> 0.3888151 | G14: 0.69318896 | H14: =G14*Lfin_111/Lfin_100 -> 0.59767855 | I14: =($G$4/G14)^3 -> 1.0475218 | J14: =rho_100*I14 -> 6.3794078 | K14: =0.5*(1-I14^(2/3)) -> -0.015717717 | L14: =2*G14/C14 -> 6.6606122 | M14: =2*G14/D14 -> 2.7516581 | N14: =2*H14/E14 -> 6.2754165 | O14: =2*H14/F14 -> 3.0743587 | P14: =J14*N14^2 -> 251.22652 | Q14: =J14*O14^2 -> 60.29613 | R14: =J14*L14^2 -> 283.01448 | S14: =1.5*P14-0.5*R14-2*T14 -> 138.7276 | T14: =J14*M14^2 -> 48.302465 | U14: =-3*$AI$11*((1-2*K14)^2.5)*(1+1.5*(4-$AI$12)*K14)*K14 -> 7.9228872 | V14: =((1-2*K14)^3.5)*($AI$4-$AI$14*K14)+3*U14 -> 282.6476 | W14: =((1-2*K14)^3.5)*($AI$5-$AI$15*K14)+1*U14 -> 139.25005 | X14: =((1-2*K14)^3.5)*($AI$6-$AI$16*K14)+1*U14 -> 48.26226 | Y14: =U14-B14 -> 0.088824156 | Z14: =V14-R14 -> -0.36688355 | AA14: =W14-S14 -> 0.52244962 | AB14: =X14-T14 -> -0.040204365 | AC14: =IF(AND(A14>=CutoffLowBar,A14<=CutoffOilBar),Y14^2+Z14^2+AA14^2+AB14^2,0) -> 0.41706327 | AD14: =(V14+2*W14)/3 -> 187.04923 | AE14: =(V14-W14+3*X14)/5 -> 57.636865 | AF14: =5*(V14-W14)*X14/(3*(V14-W14)+4*X14) -> 55.521717 | AG14: =(AE14+AF14)/2 -> 56.579291 | AH14: C11a | AI14: =3*$AI$11*($AI$7-3)-7*$AI$4 -> -550.9815 | AL14: GH0 (Hill) | AM14: =AG4 -> 53.220663
A15: =Align!A15 -> 330 | B15: =Align!B15 -> 8.5227719 | C15: =Align!C15 -> 0.20734572 | D15: =Align!D15 -> 0.50403365 | E15: =Align!F15 -> 0.1895445 | F15: =Align!G15 -> 0.3873536 | G15: 0.69244723 | H15: =G15*Lfin_111/Lfin_100 -> 0.59703902 | I15: =($G$4/G15)^3 -> 1.0508916 | J15: =rho_100*I15 -> 6.3999301 | K15: =0.5*(1-I15^(2/3)) -> -0.016823153 | L15: =2*G15/C15 -> 6.6791562 | M15: =2*G15/D15 -> 2.747623 | N15: =2*H15/E15 -> 6.2997238 | O15: =2*H15/F15 -> 3.0826563 | P15: =J15*N15^2 -> 253.99096 | Q15: =J15*O15^2 -> 60.817064 | R15: =J15*L15^2 -> 285.5081 | S15: =1.5*P15-0.5*R15-2*T15 -> 141.60071 | T15: =J15*M15^2 -> 48.315839 | U15: =-3*$AI$11*((1-2*K15)^2.5)*(1+1.5*(4-$AI$12)*K15)*K15 -> 8.5274848 | V15: =((1-2*K15)^3.5)*($AI$4-$AI$14*K15)+3*U15 -> 285.72489 | W15: =((1-2*K15)^3.5)*($AI$5-$AI$15*K15)+1*U15 -> 141.29883 | X15: =((1-2*K15)^3.5)*($AI$6-$AI$16*K15)+1*U15 -> 48.331572 | Y15: =U15-B15 -> 0.0047128953 | Z15: =V15-R15 -> 0.21679731 | AA15: =W15-S15 -> -0.30187926 | AB15: =X15-T15 -> 0.01573354 | AC15: =IF(AND(A15>=CutoffLowBar,A15<=CutoffOilBar),Y15^2+Z15^2+AA15^2+AB15^2,0) -> 0.13840191 | AD15: =(V15+2*W15)/3 -> 189.44085 | AE15: =(V15-W15+3*X15)/5 -> 57.884157 | AF15: =5*(V15-W15)*X15/(3*(V15-W15)+4*X15) -> 55.69972 | AG15: =(AE15+AF15)/2 -> 56.791938 | AH15: C12a | AI15: =3*$AI$11*($AI$8-1)-7*$AI$5 -> 367.62541 | AL15: misfit | AM15: =$AI$18 -> 2.328486
A16: =Align!A16 -> 360 | B16: =Align!B16 -> 9.1253922 | C16: =Align!C16 -> 0.20634572 | D16: =Align!D16 -> 0.50443365 | E16: =Align!F16 -> 0.18875088 | F16: =Align!G16 -> 0.38612789 | G16: 0.69170257 | H16: =G16*Lfin_111/Lfin_100 -> 0.59639696 | I16: =($G$4/G16)^3 -> 1.0542893 | J16: =rho_100*I16 -> 6.420622 | K16: =0.5*(1-I16^(2/3)) -> -0.017936531 | L16: =2*G16/C16 -> 6.7043074 | M16: =2*G16/D16 -> 2.7424918 | N16: =2*H16/E16 -> 6.3194086 | O16: =2*H16/F16 -> 3.0891162 | P16: =J16*N16^2 -> 256.40706 | Q16: =J16*O16^2 -> 61.269678 | R16: =J16*L16^2 -> 288.59243 | S16: =1.5*P16-0.5*R16-2*T16 -> 143.73202 | T16: =J16*M16^2 -> 48.291176 | U16: =-3*$AI$11*((1-2*K16)^2.5)*(1+1.5*(4-$AI$12)*K16)*K16 -> 9.1428993 | V16: =((1-2*K16)^3.5)*($AI$4-$AI$14*K16)+3*U16 -> 288.8439 | W16: =((1-2*K16)^3.5)*($AI$5-$AI$15*K16)+1*U16 -> 143.38107 | X16: =((1-2*K16)^3.5)*($AI$6-$AI$16*K16)+1*U16 -> 48.396772 | Y16: =U16-B16 -> 0.017507131 | Z16: =V16-R16 -> 0.2514652 | AA16: =W16-S16 -> -0.3509507 | AB16: =X16-T16 -> 0.10559613 | AC16: =IF(AND(A16>=CutoffLowBar,A16<=CutoffOilBar),Y16^2+Z16^2+AA16^2+AB16^2,0) -> 0.19785818 | AD16: =(V16+2*W16)/3 -> 191.86868 | AE16: =(V16-W16+3*X16)/5 -> 58.130628 | AF16: =5*(V16-W16)*X16/(3*(V16-W16)+4*X16) -> 55.874637 | AG16: =(AE16+AF16)/2 -> 57.002633 | AH16: C44a | AI16: =3*$AI$11*($AI$9-1)-7*$AI$6 -> -675.75307
A17: =Align!A17 -> 390 | B17: =Align!B17 -> 9.5558352 | C17: =Align!C17 -> 0.20554572 | D17: =Align!D17 -> 0.50383365 | E17: =Align!F17 -> 0.18820127 | F17: =Align!G17 -> 0.38527502 | G17: 0.69119065 | H17: =G17*Lfin_111/Lfin_100 -> 0.59595557 | I17: =($G$4/G17)^3 -> 1.0566336 | J17: =rho_100*I17 -> 6.4348986 | K17: =0.5*(1-I17^(2/3)) -> -0.01870402 | L17: =2*G17/C17 -> 6.72542 | M17: =2*G17/D17 -> 2.7437257 | N17: =2*H17/E17 -> 6.3331729 | O17: =2*H17/F17 -> 3.0936632 | P17: =J17*N17^2 -> 258.09785 | Q17: =J17*O17^2 -> 61.586819 | R17: =J17*L17^2 -> 291.05866 | S17: =1.5*P17-0.5*R17-2*T17 -> 144.73322 | T17: =J17*M17^2 -> 48.442112 | U17: =-3*$AI$11*((1-2*K17)^2.5)*(1+1.5*(4-$AI$12)*K17)*K17 -> 9.5709248 | V17: =((1-2*K17)^3.5)*($AI$4-$AI$14*K17)+3*U17 -> 291.00541 | W17: =((1-2*K17)^3.5)*($AI$5-$AI$15*K17)+1*U17 -> 144.82745 | X17: =((1-2*K17)^3.5)*($AI$6-$AI$16*K17)+1*U17 -> 48.438988 | Y17: =U17-B17 -> 0.015089641 | Z17: =V17-R17 -> -0.053253596 | AA17: =W17-S17 -> 0.094223703 | AB17: =X17-T17 -> -0.0031241052 | AC17: =IF(AND(A17>=CutoffLowBar,A17<=CutoffOilBar),Y17^2+Z17^2+AA17^2+AB17^2,0) -> 0.011951509 | AD17: =(V17+2*W17)/3 -> 193.55344 | AE17: =(V17-W17+3*X17)/5 -> 58.298985 | AF17: =5*(V17-W17)*X17/(3*(V17-W17)+4*X17) -> 55.992617 | AG17: =(AE17+AF17)/2 -> 57.145801
A18: =Align!A18 -> 420 | B18: =Align!B18 -> 10.115411 | C18: =Align!C18 -> 0.20474572 | D18: =Align!D18 -> 0.50323365 | E18: =Align!F18 -> 0.1875096 | F18: =Align!G18 -> 0.38418916 | G18: 0.69060359 | H18: =G18*Lfin_111/Lfin_100 -> 0.5954494 | I18: =($G$4/G18)^3 -> 1.0593305 | J18: =rho_100*I18 -> 6.4513228 | K18: =0.5*(1-I18^(2/3)) -> -0.019586262 | L18: =2*G18/C18 -> 6.7459636 | M18: =2*G18/D18 -> 2.7446638 | N18: =2*H18/E18 -> 6.351135 | O18: =2*H18/F18 -> 3.099772 | P18: =J18*N18^2 -> 260.22647 | Q18: =J18*O18^2 -> 61.988095 | R18: =J18*L18^2 -> 293.58696 | S18: =1.5*P18-0.5*R18-2*T18 -> 146.34828 | T18: =J18*M18^2 -> 48.598973 | U18: =-3*$AI$11*((1-2*K18)^2.5)*(1+1.5*(4-$AI$12)*K18)*K18 -> 10.066795 | V18: =((1-2*K18)^3.5)*($AI$4-$AI$14*K18)+3*U18 -> 293.5017 | W18: =((1-2*K18)^3.5)*($AI$5-$AI$15*K18)+1*U18 -> 146.50124 | X18: =((1-2*K18)^3.5)*($AI$6-$AI$16*K18)+1*U18 -> 48.484736 | Y18: =U18-B18 -> -0.048615901 | Z18: =V18-R18 -> -0.085262644 | AA18: =W18-S18 -> 0.15295953 | AB18: =X18-T18 -> -0.11423689 | AC18: =IF(AND(A18>=CutoffLowBar,A18<=CutoffOilBar),Y18^2+Z18^2+AA18^2+AB18^2,0) -> 0.046079909 | AD18: =(V18+2*W18)/3 -> 195.50139 | AE18: =(V18-W18+3*X18)/5 -> 58.490934 | AF18: =5*(V18-W18)*X18/(3*(V18-W18)+4*X18) -> 56.125578 | AG18: =(AE18+AF18)/2 -> 57.308256 | AH18: OBJECTIVE (misfit) | AI18: =SUM(AC4:AC25) -> 2.328486
A19: =Align!A19 -> 450 | B19: =Align!B19 -> 10.631943 | C19: =Align!C19 -> 0.20394572 | D19: =Align!D19 -> 0.50443365 | E19: =Align!F19 -> 0.18689359 | F19: =Align!G19 -> 0.38320738 | G19: 0.69328571 | H19: =G19*Lfin_111/Lfin_100 -> 0.59776197 | I19: =($G$4/G19)^3 -> 1.0470833 | J19: =rho_100*I19 -> 6.3767372 | K19: =0.5*(1-I19^(2/3)) -> -0.015573777 | L19: =2*G19/C19 -> 6.7987278 | M19: =2*G19/D19 -> 2.7487687 | N19: =2*H19/E19 -> 6.3968164 | O19: =2*H19/F19 -> 3.1197832 | P19: =J19*N19^2 -> 260.93136 | Q19: =J19*O19^2 -> 62.065083 | R19: =J19*L19^2 -> 294.75 | S19: =1.5*P19-0.5*R19-2*T19 -> 147.66024 | T19: =J19*M19^2 -> 48.180901 | U19: =-3*$AI$11*((1-2*K19)^2.5)*(1+1.5*(4-$AI$12)*K19)*K19 -> 7.844631 | V19: =((1-2*K19)^3.5)*($AI$4-$AI$14*K19)+3*U19 -> 282.24832 | W19: =((1-2*K19)^3.5)*($AI$5-$AI$15*K19)+1*U19 -> 138.98464 | X19: =((1-2*K19)^3.5)*($AI$6-$AI$16*K19)+1*U19 -> 48.252903 | Y19: =U19-B19 -> -2.7873118 | Z19: =V19-R19 -> -12.501684 | AA19: =W19-S19 -> -8.675604 | AB19: =X19-T19 -> 0.072001946 | AC19: =IF(AND(A19>=CutoffLowBar,A19<=CutoffOilBar),Y19^2+Z19^2+AA19^2+AB19^2,0) -> 0 | AD19: =(V19+2*W19)/3 -> 186.7392 | AE19: =(V19-W19+3*X19)/5 -> 57.604478 | AF19: =5*(V19-W19)*X19/(3*(V19-W19)+4*X19) -> 55.498226 | AG19: =(AE19+AF19)/2 -> 56.551352
A20: =Align!A20 -> 480 | B20: =Align!B20 -> 10.933253 | C20: =Align!C20 -> 0.20334572 | D20: =Align!D20 -> 0.50523365 | E20: =Align!F20 -> 0.18654301 | F20: =Align!G20 -> 0.38264355 | G20: 0.69257143 | H20: =G20*Lfin_111/Lfin_100 -> 0.5971461 | I20: =($G$4/G20)^3 -> 1.0503264 | J20: =rho_100*I20 -> 6.3964875 | K20: =0.5*(1-I20^(2/3)) -> -0.016637802 | L20: =2*G20/C20 -> 6.811763 | M20: =2*G20/D20 -> 2.7415887 | N20: =2*H20/E20 -> 6.4022352 | O20: =2*H20/F20 -> 3.1211612 | P20: =J20*N20^2 -> 262.18317 | Q20: =J20*O20^2 -> 62.312325 | R20: =J20*L20^2 -> 296.79776 | S20: =1.5*P20-0.5*R20-2*T20 -> 148.71992 | T20: =J20*M20^2 -> 48.077974 | U20: =-3*$AI$11*((1-2*K20)^2.5)*(1+1.5*(4-$AI$12)*K20)*K20 -> 8.425665 | V20: =((1-2*K20)^3.5)*($AI$4-$AI$14*K20)+3*U20 -> 285.20757 | W20: =((1-2*K20)^3.5)*($AI$5-$AI$15*K20)+1*U20 -> 140.95401 | X20: =((1-2*K20)^3.5)*($AI$6-$AI$16*K20)+1*U20 -> 48.320267 | Y20: =U20-B20 -> -2.5075879 | Z20: =V20-R20 -> -11.590192 | AA20: =W20-S20 -> -7.7659105 | AB20: =X20-T20 -> 0.24229305 | AC20: =IF(AND(A20>=CutoffLowBar,A20<=CutoffOilBar),Y20^2+Z20^2+AA20^2+AB20^2,0) -> 0 | AD20: =(V20+2*W20)/3 -> 189.03853 | AE20: =(V20-W20+3*X20)/5 -> 57.842871 | AF20: =5*(V20-W20)*X20/(3*(V20-W20)+4*X20) -> 55.670173 | AG20: =(AE20+AF20)/2 -> 56.756522
A21: =Align!A21 -> 510 | B21: =Align!B21 -> 11.148474 | C21: =Align!C21 -> 0.20234572 | D21: =Align!D21 -> 0.50563365 | E21: =Align!F21 -> 0.18629574 | F21: =Align!G21 -> 0.38224488 | G21: 0.69185714 | H21: =G21*Lfin_111/Lfin_100 -> 0.59653024 | I21: =($G$4/G21)^3 -> 1.0535828 | J21: =rho_100*I21 -> 6.4163195 | K21: =0.5*(1-I21^(2/3)) -> -0.017705125 | L21: =2*G21/C21 -> 6.838367 | M21: =2*G21/D21 -> 2.7365946 | N21: =2*H21/E21 -> 6.4041211 | O21: =2*H21/F21 -> 3.1211941 | P21: =J21*N21^2 -> 263.15102 | Q21: =J21*O21^2 -> 62.506841 | R21: =J21*L21^2 -> 300.04803 | S21: =1.5*P21-0.5*R21-2*T21 -> 148.59952 | T21: =J21*M21^2 -> 48.051495 | U21: =-3*$AI$11*((1-2*K21)^2.5)*(1+1.5*(4-$AI$12)*K21)*K21 -> 9.0144546 | V21: =((1-2*K21)^3.5)*($AI$4-$AI$14*K21)+3*U21 -> 288.19402 | W21: =((1-2*K21)^3.5)*($AI$5-$AI$15*K21)+1*U21 -> 142.94674 | X21: =((1-2*K21)^3.5)*($AI$6-$AI$16*K21)+1*U21 -> 48.383605 | Y21: =U21-B21 -> -2.1340198 | Z21: =V21-R21 -> -11.854014 | AA21: =W21-S21 -> -5.6527796 | AB21: =X21-T21 -> 0.33211 | AC21: =IF(AND(A21>=CutoffLowBar,A21<=CutoffOilBar),Y21^2+Z21^2+AA21^2+AB21^2,0) -> 0 | AD21: =(V21+2*W21)/3 -> 191.3625 | AE21: =(V21-W21+3*X21)/5 -> 58.079618 | AF21: =5*(V21-W21)*X21/(3*(V21-W21)+4*X21) -> 55.838647 | AG21: =(AE21+AF21)/2 -> 56.959133
A22: =Align!A22 -> 540 | B22: =Align!B22 -> 11.535873 | C22: =Align!C22 -> 0.20174572 | D22: =Align!D22 -> 0.50523365 | E22: =Align!F22 -> 0.18585489 | F22: =Align!G22 -> 0.38153599 | G22: 0.69114286 | H22: =G22*Lfin_111/Lfin_100 -> 0.59591437 | I22: =($G$4/G22)^3 -> 1.0568528 | J22: =rho_100*I22 -> 6.4362336 | K22: =0.5*(1-I22^(2/3)) -> -0.018775759 | L22: =2*G22/C22 -> 6.8516235 | M22: =2*G22/D22 -> 2.7359336 | N22: =2*H22/E22 -> 6.4126842 | O22: =2*H22/F22 -> 3.1237649 | P22: =J22*N22^2 -> 264.67414 | Q22: =J22*O22^2 -> 62.80417 | R22: =J22*L22^2 -> 302.14734 | S22: =1.5*P22-0.5*R22-2*T22 -> 149.58283 | T22: =J22*M22^2 -> 48.17735 | U22: =-3*$AI$11*((1-2*K22)^2.5)*(1+1.5*(4-$AI$12)*K22)*K22 -> 9.6110926 | V22: =((1-2*K22)^3.5)*($AI$4-$AI$14*K22)+3*U22 -> 291.20793 | W22: =((1-2*K22)^3.5)*($AI$5-$AI$15*K22)+1*U22 -> 144.96311 | X22: =((1-2*K22)^3.5)*($AI$6-$AI$16*K22)+1*U22 -> 48.44282 | Y22: =U22-B22 -> -1.9247805 | Z22: =V22-R22 -> -10.93941 | AA22: =W22-S22 -> -4.6197286 | AB22: =X22-T22 -> 0.26546985 | AC22: =IF(AND(A22>=CutoffLowBar,A22<=CutoffOilBar),Y22^2+Z22^2+AA22^2+AB22^2,0) -> 0 | AD22: =(V22+2*W22)/3 -> 193.71138 | AE22: =(V22-W22+3*X22)/5 -> 58.314657 | AF22: =5*(V22-W22)*X22/(3*(V22-W22)+4*X22) -> 56.003536 | AG22: =(AE22+AF22)/2 -> 57.159096
A23: =Align!A23 -> 570 | B23: =Align!B23 -> 12.052405 | C23: =Align!C23 -> 0.20094572 | D23: =Align!D23 -> 0.50583365 | E23: =Align!F23 -> 0.18526701 | F23: =Align!G23 -> 0.38060856 | G23: 0.69042857 | H23: =G23*Lfin_111/Lfin_100 -> 0.5952985 | I23: =($G$4/G23)^3 -> 1.0601363 | J23: =rho_100*I23 -> 6.4562302 | K23: =0.5*(1-I23^(2/3)) -> -0.019849718 | L23: =2*G23/C23 -> 6.8717918 | M23: =2*G23/D23 -> 2.7298642 | N23: =2*H23/E23 -> 6.4263842 | O23: =2*H23/F23 -> 3.1281403 | P23: =J23*N23^2 -> 266.63207 | Q23: =J23*O23^2 -> 63.175904 | R23: =J23*L23^2 -> 304.87301 | S23: =1.5*P23-0.5*R23-2*T23 -> 151.28589 | T23: =J23*M23^2 -> 48.112849 | U23: =-3*$AI$11*((1-2*K23)^2.5)*(1+1.5*(4-$AI$12)*K23)*K23 -> 10.215673 | V23: =((1-2*K23)^3.5)*($AI$4-$AI$14*K23)+3*U23 -> 294.24955 | W23: =((1-2*K23)^3.5)*($AI$5-$AI$15*K23)+1*U23 -> 147.00339 | X23: =((1-2*K23)^3.5)*($AI$6-$AI$16*K23)+1*U23 -> 48.497816 | Y23: =U23-B23 -> -1.8367319 | Z23: =V23-R23 -> -10.623462 | AA23: =W23-S23 -> -4.2825066 | AB23: =X23-T23 -> 0.38496612 | AC23: =IF(AND(A23>=CutoffLowBar,A23<=CutoffOilBar),Y23^2+Z23^2+AA23^2+AB23^2,0) -> 0 | AD23: =(V23+2*W23)/3 -> 196.08544 | AE23: =(V23-W23+3*X23)/5 -> 58.547923 | AF23: =5*(V23-W23)*X23/(3*(V23-W23)+4*X23) -> 56.164725 | AG23: =(AE23+AF23)/2 -> 57.356324
A24: =Align!A24 -> 600 | B24: =Align!B24 -> 12.310671 | C24: =Align!C24 -> 0.20034572 | D24: =Align!D24 -> 0.50703365 | E24: =Align!F24 -> 0.18496783 | F24: =Align!G24 -> 0.38015232 | G24: 0.68971429 | H24: =G24*Lfin_111/Lfin_100 -> 0.59468263 | I24: =($G$4/G24)^3 -> 1.0634334 | J24: =rho_100*I24 -> 6.4763097 | K24: =0.5*(1-I24^(2/3)) -> -0.020927014 | L24: =2*G24/C24 -> 6.885241 | M24: =2*G24/D24 -> 2.7205859 | N24: =2*H24/E24 -> 6.4301195 | O24: =2*H24/F24 -> 3.1286545 | P24: =J24*N24^2 -> 267.77233 | Q24: =J24*O24^2 -> 63.393221 | R24: =J24*L24^2 -> 307.01946 | S24: =1.5*P24-0.5*R24-2*T24 -> 152.27882 | T24: =J24*M24^2 -> 47.934972 | U24: =-3*$AI$11*((1-2*K24)^2.5)*(1+1.5*(4-$AI$12)*K24)*K24 -> 10.82829 | V24: =((1-2*K24)^3.5)*($AI$4-$AI$14*K24)+3*U24 -> 297.31914 | W24: =((1-2*K24)^3.5)*($AI$5-$AI$15*K24)+1*U24 -> 149.06787 | X24: =((1-2*K24)^3.5)*($AI$6-$AI$16*K24)+1*U24 -> 48.548493 | Y24: =U24-B24 -> -1.4823801 | Z24: =V24-R24 -> -9.7003182 | AA24: =W24-S24 -> -3.2109481 | AB24: =X24-T24 -> 0.61352105 | AC24: =IF(AND(A24>=CutoffLowBar,A24<=CutoffOilBar),Y24^2+Z24^2+AA24^2+AB24^2,0) -> 0 | AD24: =(V24+2*W24)/3 -> 198.48496 | AE24: =(V24-W24+3*X24)/5 -> 58.77935 | AF24: =5*(V24-W24)*X24/(3*(V24-W24)+4*X24) -> 56.322097 | AG24: =(AE24+AF24)/2 -> 57.550723
A25: =Align!A25 -> 630 | B25: =Align!B25 -> 12.482848 | C25: =Align!C25 -> 0.19974572 | D25: =Align!D25 -> 0.50683365 | E25: =Align!F25 -> 0.1847644 | F25: =Align!G25 -> 0.37985075 | G25: 0.689 | H25: =G25*Lfin_111/Lfin_100 -> 0.59406676 | I25: =($G$4/G25)^3 -> 1.0667443 | J25: =rho_100*I25 -> 6.4964725 | K25: =0.5*(1-I25^(2/3)) -> -0.022007663 | L25: =2*G25/C25 -> 6.8987711 | M25: =2*G25/D25 -> 2.7188408 | N25: =2*H25/E25 -> 6.4305329 | O25: =2*H25/F25 -> 3.1278957 | P25: =J25*N25^2 -> 268.64053 | Q25: =J25*O25^2 -> 63.559742 | R25: =J25*L25^2 -> 309.18689 | S25: =1.5*P25-0.5*R25-2*T25 -> 152.32226 | T25: =J25*M25^2 -> 48.022544 | U25: =-3*$AI$11*((1-2*K25)^2.5)*(1+1.5*(4-$AI$12)*K25)*K25 -> 11.449042 | V25: =((1-2*K25)^3.5)*($AI$4-$AI$14*K25)+3*U25 -> 300.41695 | W25: =((1-2*K25)^3.5)*($AI$5-$AI$15*K25)+1*U25 -> 151.15686 | X25: =((1-2*K25)^3.5)*($AI$6-$AI$16*K25)+1*U25 -> 48.594752 | Y25: =U25-B25 -> -1.0338061 | Z25: =V25-R25 -> -8.7699389 | AA25: =W25-S25 -> -1.1654014 | AB25: =X25-T25 -> 0.57220842 | AC25: =IF(AND(A25>=CutoffLowBar,A25<=CutoffOilBar),Y25^2+Z25^2+AA25^2+AB25^2,0) -> 0 | AD25: =(V25+2*W25)/3 -> 200.91022 | AE25: =(V25-W25+3*X25)/5 -> 59.008871 | AF25: =5*(V25-W25)*X25/(3*(V25-W25)+4*X25) -> 56.475531 | AG25: =(AE25+AF25)/2 -> 57.742201

Sheet FS_NoVp111
A3: Oil bar | B3: P (GPa) | C3: tP100 | D3: tS100 | E3: tP111 | F3: tS111 | G3: L fit | H3: L111 | I3: V0/V | J3: rho | K3: f | L3: Vp100 | M3: Vs100 | N3: Vp111 | O3: Vs111 | P3: rVp111^2 | Q3: rVs111^2 | R3: C11 meas | S3: C12 meas | T3: C44 meas | U3: P_FS | V3: C11 mod | W3: C12 mod | X3: C44 mod | Y3: dP | Z3: dC11 | AA3: dC12 | AB3: dC44 | AC3: gated sq | AD3: K bulk | AE3: GV | AF3: GR | AG3: GH | AI3: FIT PARAMS | AL3: OUTPUTS
A4: =Align!A4 -> 0 | B4: =Align!B4 -> 0 | C4: =Align!C4 -> 0.22919993 | D4: =Align!D4 -> 0.51092692 | E4: =Align!F4 -> 0.20385318 | F4: =Align!G4 -> 0.41892602 | G4: =Lfin_100 -> 0.704 | H4: =G4*Lfin_111/Lfin_100 -> 0.607 | I4: =($G$4/G4)^3 -> 1 | J4: =rho_100*I4 -> 6.09 | K4: =0.5*(1-I4^(2/3)) -> 0 | L4: =2*G4/C4 -> 6.1431082 | M4: =2*G4/D4 -> 2.7557757 | N4: =2*H4/E4 -> 5.9552664 | O4: =2*H4/F4 -> 2.8978863 | P4: =J4*N4^2 -> 215.98305 | Q4: =J4*O4^2 -> 51.142269 | R4: =J4*L4^2 -> 229.82307 | S4: =R4+T4-3*Q4 -> 122.64555 | T4: =J4*M4^2 -> 46.249286 | U4: =-3*$AI$11*((1-2*K4)^2.5)*(1+1.5*(4-$AI$12)*K4)*K4 -> 0 | V4: =((1-2*K4)^3.5)*($AI$4-$AI$14*K4)+3*U4 -> 240.83323 | W4: =((1-2*K4)^3.5)*($AI$5-$AI$15*K4)+1*U4 -> 128.74145 | X4: =((1-2*K4)^3.5)*($AI$6-$AI$16*K4)+1*U4 -> 46.761629 | Y4: =U4-B4 -> 0 | Z4: =V4-R4 -> 11.010158 | AA4: =W4-S4 -> 6.095903 | AB4: =X4-T4 -> 0.51234265 | AC4: =IF(AND(A4>=CutoffLowBar,A4<=CutoffOilBar),Y4^2+Z4^2+AA4^2+AB4^2,0) -> 0 | AD4: =(V4+2*W4)/3 -> 166.10538 | AE4: =(V4-W4+3*X4)/5 -> 50.475332 | AF4: =5*(V4-W4)*X4/(3*(V4-W4)+4*X4) -> 50.080023 | AG4: =(AE4+AF4)/2 -> 50.277678 | AH4: C11_0 | AI4: 240.83323 | AL4: C11_0 | AM4: =$AI$4 -> 240.83323
A5: =Align!A5 -> 30 | B5: =Align!B5 -> 0.12913291 | C5: =Align!C5 -> 0.22474572 | D5: =Align!D5 -> 0.50723365 | E5: =Align!F5 -> 0.20362287 | F5: =Align!G5 -> 0.41829834 | G5: 0.70328571 | H5: =G5*Lfin_111/Lfin_100 -> 0.60638413 | I5: =($G$4/G5)^3 -> 1.00305 | J5: =rho_100*I5 -> 6.1085746 | K5: =0.5*(1-I5^(2/3)) -> -0.0010161566 | L5: =2*G5/C5 -> 6.2585015 | M5: =2*G5/D5 -> 2.7730247 | N5: =2*H5/E5 -> 5.9559532 | O5: =2*H5/F5 -> 2.8992902 | P5: =J5*N5^2 -> 216.69178 | Q5: =J5*O5^2 -> 51.347967 | R5: =J5*L5^2 -> 239.26579 | S5: =R5+T5-3*Q5 -> 132.19479 | T5: =J5*M5^2 -> 46.972898 | U5: =-3*$AI$11*((1-2*K5)^2.5)*(1+1.5*(4-$AI$12)*K5)*K5 -> 0.5086473 | V5: =((1-2*K5)^3.5)*($AI$4-$AI$14*K5)+3*U5 -> 243.56514 | W5: =((1-2*K5)^3.5)*($AI$5-$AI$15*K5)+1*U5 -> 130.13142 | X5: =((1-2*K5)^3.5)*($AI$6-$AI$16*K5)+1*U5 -> 46.889806 | Y5: =U5-B5 -> 0.3795144 | Z5: =V5-R5 -> 4.2993514 | AA5: =W5-S5 -> -2.0633633 | AB5: =X5-T5 -> -0.083092696 | AC5: =IF(AND(A5>=CutoffLowBar,A5<=CutoffOilBar),Y5^2+Z5^2+AA5^2+AB5^2,0) -> 0 | AD5: =(V5+2*W5)/3 -> 167.94266 | AE5: =(V5-W5+3*X5)/5 -> 50.820627 | AF5: =5*(V5-W5)*X5/(3*(V5-W5)+4*X5) -> 50.381552 | AG5: =(AE5+AF5)/2 -> 50.601089 | AH5: C12_0 | AI5: 128.74145 | AL5: C12_0 | AM5: =$AI$5 -> 128.74145
A6: =Align!A6 -> 60 | B6: =Align!B6 -> 1.6356835 | C6: =Align!C6 -> 0.22094572 | D6: =Align!D6 -> 0.50583365 | E6: =Align!F6 -> 0.20069823 | F6: =Align!G6 -> 0.41052794 | G6: 0.70257143 | H6: =G6*Lfin_111/Lfin_100 -> 0.60576826 | I6: =($G$4/G6)^3 -> 1.0061125 | J6: =rho_100*I6 -> 6.1272248 | K6: =0.5*(1-I6^(2/3)) -> -0.0020354141 | L6: =2*G6/C6 -> 6.3596745 | M6: =2*G6/D6 -> 2.7778754 | N6: =2*H6/E6 -> 6.0366079 | O6: =2*H6/F6 -> 2.951167 | P6: =J6*N6^2 -> 223.27997 | Q6: =J6*O6^2 -> 53.364372 | R6: =J6*L6^2 -> 247.81842 | S6: =R6+T6-3*Q6 -> 135.0066 | T6: =J6*M6^2 -> 47.281293 | U6: =-3*$AI$11*((1-2*K6)^2.5)*(1+1.5*(4-$AI$12)*K6)*K6 -> 1.0234375 | V6: =((1-2*K6)^3.5)*($AI$4-$AI$14*K6)+3*U6 -> 246.32062 | W6: =((1-2*K6)^3.5)*($AI$5-$AI$15*K6)+1*U6 -> 131.53439 | X6: =((1-2*K6)^3.5)*($AI$6-$AI$16*K6)+1*U6 -> 47.014459 | Y6: =U6-B6 -> -0.61224598 | Z6: =V6-R6 -> -1.4978062 | AA6: =W6-S6 -> -3.4722168 | AB6: =X6-T6 -> -0.26683489 | AC6: =IF(AND(A6>=CutoffLowBar,A6<=CutoffOilBar),Y6^2+Z6^2+AA6^2+AB6^2,0) -> 0 | AD6: =(V6+2*W6)/3 -> 169.79646 | AE6: =(V6-W6+3*X6)/5 -> 51.165922 | AF6: =5*(V6-W6)*X6/(3*(V6-W6)+4*X6) -> 50.680363 | AG6: =(AE6+AF6)/2 -> 50.923142 | AH6: C44_0 | AI6: 46.761629 | AL6: C44_0 | AM6: =$AI$6 -> 46.761629
A7: =Align!A7 -> 90 | B7: =Align!B7 -> 2.4965696 | C7: =Align!C7 -> 0.21874572 | D7: =Align!D7 -> 0.50583365 | E7: =Align!F7 -> 0.19901985 | F7: =Align!G7 -> 0.40624126 | G7: 0.70185714 | H7: =G7*Lfin_111/Lfin_100 -> 0.60515239 | I7: =($G$4/G7)^3 -> 1.0091874 | J7: =rho_100*I7 -> 6.1459511 | K7: =0.5*(1-I7^(2/3)) -> -0.0030577851 | L7: =2*G7/C7 -> 6.4171051 | M7: =2*G7/D7 -> 2.7750512 | N7: =2*H7/E7 -> 6.0813271 | O7: =2*H7/F7 -> 2.9792759 | P7: =J7*N7^2 -> 227.29288 | Q7: =J7*O7^2 -> 54.551983 | R7: =J7*L7^2 -> 253.08558 | S7: =R7+T7-3*Q7 -> 136.75905 | T7: =J7*M7^2 -> 47.329412 | U7: =-3*$AI$11*((1-2*K7)^2.5)*(1+1.5*(4-$AI$12)*K7)*K7 -> 1.5444338 | V7: =((1-2*K7)^3.5)*($AI$4-$AI$14*K7)+3*U7 -> 249.09985 | W7: =((1-2*K7)^3.5)*($AI$5-$AI$15*K7)+1*U7 -> 132.95047 | X7: =((1-2*K7)^3.5)*($AI$6-$AI$16*K7)+1*U7 -> 47.135495 | Y7: =U7-B7 -> -0.95213578 | Z7: =V7-R7 -> -3.9857343 | AA7: =W7-S7 -> -3.8085814 | AB7: =X7-T7 -> -0.1939168 | AC7: =IF(AND(A7>=CutoffLowBar,A7<=CutoffOilBar),Y7^2+Z7^2+AA7^2+AB7^2,0) -> 0 | AD7: =(V7+2*W7)/3 -> 171.66693 | AE7: =(V7-W7+3*X7)/5 -> 51.511174 | AF7: =5*(V7-W7)*X7/(3*(V7-W7)+4*X7) -> 50.976344 | AG7: =(AE7+AF7)/2 -> 51.243759 | AH7: C11' | AI7: 5.3801597 | AL7: C11' | AM7: =$AI$7 -> 5.3801597
A8: =Align!A8 -> 120 | B8: =Align!B8 -> 3.4435442 | C8: =Align!C8 -> 0.21654572 | D8: =Align!D8 -> 0.50523365 | E8: =Align!F8 -> 0.19727344 | F8: =Align!G8 -> 0.40198653 | G8: 0.69920982 | H8: =G8*Lfin_111/Lfin_100 -> 0.60286983 | I8: =($G$4/G8)^3 -> 1.0206937 | J8: =rho_100*I8 -> 6.2160245 | K8: =0.5*(1-I8^(2/3)) -> -0.0068743197 | L8: =2*G8/C8 -> 6.4578493 | M8: =2*G8/D8 -> 2.7678672 | N8: =2*H8/E8 -> 6.1120221 | O8: =2*H8/F8 -> 2.9994529 | P8: =J8*N8^2 -> 232.21088 | Q8: =J8*O8^2 -> 55.923818 | R8: =J8*L8^2 -> 259.23196 | S8: =R8+T8-3*Q8 -> 139.08202 | T8: =J8*M8^2 -> 47.621516 | U8: =-3*$AI$11*((1-2*K8)^2.5)*(1+1.5*(4-$AI$12)*K8)*K8 -> 3.5305694 | V8: =((1-2*K8)^3.5)*($AI$4-$AI$14*K8)+3*U8 -> 259.61073 | W8: =((1-2*K8)^3.5)*($AI$5-$AI$15*K8)+1*U8 -> 138.3153 | X8: =((1-2*K8)^3.5)*($AI$6-$AI$16*K8)+1*U8 -> 47.550962 | Y8: =U8-B8 -> 0.087025137 | Z8: =V8-R8 -> 0.3787777 | AA8: =W8-S8 -> -0.76671904 | AB8: =X8-T8 -> -0.070554104 | AC8: =IF(AND(A8>=CutoffLowBar,A8<=CutoffOilBar),Y8^2+Z8^2+AA8^2+AB8^2,0) -> 0.74388188 | AD8: =(V8+2*W8)/3 -> 178.74711 | AE8: =(V8-W8+3*X8)/5 -> 52.789664 | AF8: =5*(V8-W8)*X8/(3*(V8-W8)+4*X8) -> 52.046716 | AG8: =(AE8+AF8)/2 -> 52.41819 | AH8: C12' | AI8: 2.7363926 | AL8: C12' | AM8: =$AI$8 -> 2.7363926
A9: =Align!A9 -> 150 | B9: =Align!B9 -> 4.4335632 | C9: =Align!C9 -> 0.21474572 | D9: =Align!D9 -> 0.50523365 | E9: =Align!F9 -> 0.19557829 | F9: =Align!G9 -> 0.39814914 | G9: 0.69813954 | H9: =G9*Lfin_111/Lfin_100 -> 0.60194702 | I9: =($G$4/G9)^3 -> 1.0253952 | J9: =rho_100*I9 -> 6.2446566 | K9: =0.5*(1-I9^(2/3)) -> -0.0084296299 | L9: =2*G9/C9 -> 6.5020112 | M9: =2*G9/D9 -> 2.7636304 | N9: =2*H9/E9 -> 6.1555606 | O9: =2*H9/F9 -> 3.0237263 | P9: =J9*N9^2 -> 236.61582 | Q9: =J9*O9^2 -> 57.094403 | R9: =J9*L9^2 -> 264.00004 | S9: =R9+T9-3*Q9 -> 140.41135 | T9: =J9*M9^2 -> 47.694521 | U9: =-3*$AI$11*((1-2*K9)^2.5)*(1+1.5*(4-$AI$12)*K9)*K9 -> 4.3587387 | V9: =((1-2*K9)^3.5)*($AI$4-$AI$14*K9)+3*U9 -> 263.95574 | W9: =((1-2*K9)^3.5)*($AI$5-$AI$15*K9)+1*U9 -> 140.53732 | X9: =((1-2*K9)^3.5)*($AI$6-$AI$16*K9)+1*U9 -> 47.703321 | Y9: =U9-B9 -> -0.07482447 | Z9: =V9-R9 -> -0.044304147 | AA9: =W9-S9 -> 0.12596643 | AB9: =X9-T9 -> 0.0087991485 | AC9: =IF(AND(A9>=CutoffLowBar,A9<=CutoffOilBar),Y9^2+Z9^2+AA9^2+AB9^2,0) -> 0.023506525 | AD9: =(V9+2*W9)/3 -> 181.67679 | AE9: =(V9-W9+3*X9)/5 -> 53.305676 | AF9: =5*(V9-W9)*X9/(3*(V9-W9)+4*X9) -> 52.46657 | AG9: =(AE9+AF9)/2 -> 52.886123 | AH9: C44' | AI9: 0.25693971 | AL9: C44' | AM9: =$AI$9 -> 0.25693971
A10: =Align!A10 -> 180 | B10: =Align!B10 -> 5.122272 | C10: =Align!C10 -> 0.21334572 | D10: =Align!D10 -> 0.50523365 | E10: =Align!F10 -> 0.19446957 | F10: =Align!G10 -> 0.39583686 | G10: 0.69724023 | H10: =G10*Lfin_111/Lfin_100 -> 0.60117162 | I10: =($G$4/G10)^3 -> 1.029368 | J10: =rho_100*I10 -> 6.2688511 | K10: =0.5*(1-I10^(2/3)) -> -0.0097420318 | L10: =2*G10/C10 -> 6.5362477 | M10: =2*G10/D10 -> 2.7600705 | N10: =2*H10/E10 -> 6.1826808 | O10: =2*H10/F10 -> 3.0374716 | P10: =J10*N10^2 -> 239.63023 | Q10: =J10*O10^2 -> 57.837887 | R10: =J10*L10^2 -> 267.8212 | S10: =R10+T10-3*Q10 -> 142.06358 | T10: =J10*M10^2 -> 47.756038 | U10: =-3*$AI$11*((1-2*K10)^2.5)*(1+1.5*(4-$AI$12)*K10)*K10 -> 5.0660824 | V10: =((1-2*K10)^3.5)*($AI$4-$AI$14*K10)+3*U10 -> 267.64995 | W10: =((1-2*K10)^3.5)*($AI$5-$AI$15*K10)+1*U10 -> 142.42851 | X10: =((1-2*K10)^3.5)*($AI$6-$AI$16*K10)+1*U10 -> 47.824011 | Y10: =U10-B10 -> -0.056189604 | Z10: =V10-R10 -> -0.17125532 | AA10: =W10-S10 -> 0.3649326 | AB10: =X10-T10 -> 0.067972169 | AC10: =IF(AND(A10>=CutoffLowBar,A10<=CutoffOilBar),Y10^2+Z10^2+AA10^2+AB10^2,0) -> 0.17028168 | AD10: =(V10+2*W10)/3 -> 184.16899 | AE10: =(V10-W10+3*X10)/5 -> 53.738693 | AF10: =5*(V10-W10)*X10/(3*(V10-W10)+4*X10) -> 52.81314 | AG10: =(AE10+AF10)/2 -> 53.275917 | AL10: K0 | AM10: =$AI$11 -> 166.10538
A11: =Align!A11 -> 210 | B11: =Align!B11 -> 5.7679366 | C11: =Align!C11 -> 0.21174572 | D11: =Align!D11 -> 0.50423365 | E11: =Align!F11 -> 0.19347267 | F11: =Align!G11 -> 0.39390328 | G11: 0.69612231 | H11: =G11*Lfin_111/Lfin_100 -> 0.60020773 | I11: =($G$4/G11)^3 -> 1.0343352 | J11: =rho_100*I11 -> 6.2991016 | K11: =0.5*(1-I11^(2/3)) -> -0.011380564 | L11: =2*G11/C11 -> 6.575078 | M11: =2*G11/D11 -> 2.7611101 | N11: =2*H11/E11 -> 6.2045739 | O11: =2*H11/F11 -> 3.0474879 | P11: =J11*N11^2 -> 242.49486 | Q11: =J11*O11^2 -> 58.500904 | R11: =J11*L11^2 -> 272.32056 | S11: =R11+T11-3*Q11 -> 144.84049 | T11: =J11*M11^2 -> 48.022644 | U11: =-3*$AI$11*((1-2*K11)^2.5)*(1+1.5*(4-$AI$12)*K11)*K11 -> 5.960193 | V11: =((1-2*K11)^3.5)*($AI$4-$AI$14*K11)+3*U11 -> 272.29793 | W11: =((1-2*K11)^3.5)*($AI$5-$AI$15*K11)+1*U11 -> 144.81056 | X11: =((1-2*K11)^3.5)*($AI$6-$AI$16*K11)+1*U11 -> 47.964368 | Y11: =U11-B11 -> 0.19225639 | Z11: =V11-R11 -> -0.022622463 | AA11: =W11-S11 -> -0.029923256 | AB11: =X11-T11 -> -0.058275659 | AC11: =IF(AND(A11>=CutoffLowBar,A11<=CutoffOilBar),Y11^2+Z11^2+AA11^2+AB11^2,0) -> 0.04176575 | AD11: =(V11+2*W11)/3 -> 187.30635 | AE11: =(V11-W11+3*X11)/5 -> 54.276095 | AF11: =5*(V11-W11)*X11/(3*(V11-W11)+4*X11) -> 53.235614 | AG11: =(AE11+AF11)/2 -> 53.755855 | AH11: K0 | AI11: =($AI$4+2*$AI$5)/3 -> 166.10538 | AL11: K0' | AM11: =$AI$12 -> 3.6176483
A12: =Align!A12 -> 240 | B12: =Align!B12 -> 6.5857783 | C12: =Align!C12 -> 0.21074572 | D12: =Align!D12 -> 0.50423365 | E12: =Align!F12 -> 0.19225681 | F12: =Align!G12 -> 0.39172305 | G12: 0.69550164 | H12: =G12*Lfin_111/Lfin_100 -> 0.59967258 | I12: =($G$4/G12)^3 -> 1.0371068 | J12: =rho_100*I12 -> 6.3159806 | K12: =0.5*(1-I12^(2/3)) -> -0.012293682 | L12: =2*G12/C12 -> 6.6003869 | M12: =2*G12/D12 -> 2.7586483 | N12: =2*H12/E12 -> 6.2382455 | O12: =2*H12/F12 -> 3.0617171 | P12: =J12*N12^2 -> 245.79085 | Q12: =J12*O12^2 -> 59.206706 | R12: =J12*L12^2 -> 275.15637 | S12: =R12+T12-3*Q12 -> 145.60175 | T12: =J12*M12^2 -> 48.065499 | U12: =-3*$AI$11*((1-2*K12)^2.5)*(1+1.5*(4-$AI$12)*K12)*K12 -> 6.4637784 | V12: =((1-2*K12)^3.5)*($AI$4-$AI$14*K12)+3*U12 -> 274.90541 | W12: =((1-2*K12)^3.5)*($AI$5-$AI$15*K12)+1*U12 -> 146.14814 | X12: =((1-2*K12)^3.5)*($AI$6-$AI$16*K12)+1*U12 -> 48.037525 | Y12: =U12-B12 -> -0.12199993 | Z12: =V12-R12 -> -0.25095983 | AA12: =W12-S12 -> 0.54638562 | AB12: =X12-T12 -> -0.027974259 | AC12: =IF(AND(A12>=CutoffLowBar,A12<=CutoffOilBar),Y12^2+Z12^2+AA12^2+AB12^2,0) -> 0.37718463 | AD12: =(V12+2*W12)/3 -> 189.06723 | AE12: =(V12-W12+3*X12)/5 -> 54.57397 | AF12: =5*(V12-W12)*X12/(3*(V12-W12)+4*X12) -> 53.465995 | AG12: =(AE12+AF12)/2 -> 54.019982 | AH12: K0' | AI12: =($AI$7+2*$AI$8)/3 -> 3.6176483 | AL12: GV0 | AM12: =AE4 -> 50.475332
A13: =Align!A13 -> 270 | B13: =Align!B13 -> 7.2744872 | C13: =Align!C13 -> 0.20914572 | D13: =Align!D13 -> 0.50463365 | E13: =Align!F13 -> 0.19126642 | F13: =Align!G13 -> 0.39006856 | G13: 0.694363 | H13: =G13*Lfin_111/Lfin_100 -> 0.59869082 | I13: =($G$4/G13)^3 -> 1.0422173 | J13: =rho_100*I13 -> 6.3471032 | K13: =0.5*(1-I13^(2/3)) -> -0.013975221 | L13: =2*G13/C13 -> 6.6399924 | M13: =2*G13/D13 -> 2.7519489 | N13: =2*H13/E13 -> 6.2602816 | O13: =2*H13/F13 -> 3.0696697 | P13: =J13*N13^2 -> 248.75012 | Q13: =J13*O13^2 -> 59.807943 | R13: =J13*L13^2 -> 279.8406 | S13: =R13+T13-3*Q13 -> 148.4848 | T13: =J13*M13^2 -> 48.068026 | U13: =-3*$AI$11*((1-2*K13)^2.5)*(1+1.5*(4-$AI$12)*K13)*K13 -> 7.4011481 | V13: =((1-2*K13)^3.5)*($AI$4-$AI$14*K13)+3*U13 -> 279.73952 | W13: =((1-2*K13)^3.5)*($AI$5-$AI$15*K13)+1*U13 -> 148.63032 | X13: =((1-2*K13)^3.5)*($AI$6-$AI$16*K13)+1*U13 -> 48.162589 | Y13: =U13-B13 -> 0.12666099 | Z13: =V13-R13 -> -0.10108479 | AA13: =W13-S13 -> 0.14552431 | AB13: =X13-T13 -> 0.094563041 | AC13: =IF(AND(A13>=CutoffLowBar,A13<=CutoffOilBar),Y13^2+Z13^2+AA13^2+AB13^2,0) -> 0.056380634 | AD13: =(V13+2*W13)/3 -> 192.33339 | AE13: =(V13-W13+3*X13)/5 -> 55.119392 | AF13: =5*(V13-W13)*X13/(3*(V13-W13)+4*X13) -> 53.880511 | AG13: =(AE13+AF13)/2 -> 54.499952 | AL13: GR0 | AM13: =AF4 -> 50.080023
A14: =Align!A14 -> 300 | B14: =Align!B14 -> 7.8340631 | C14: =Align!C14 -> 0.20814572 | D14: =Align!D14 -> 0.50383365 | E14: =Align!F14 -> 0.19048251 | F14: =Align!G14 -> 0.3888151 | G14: 0.69363909 | H14: =G14*Lfin_111/Lfin_100 -> 0.59806666 | I14: =($G$4/G14)^3 -> 1.0454838 | J14: =rho_100*I14 -> 6.3669962 | K14: =0.5*(1-I14^(2/3)) -> -0.015048591 | L14: =2*G14/C14 -> 6.6649373 | M14: =2*G14/D14 -> 2.7534449 | N14: =2*H14/E14 -> 6.2794915 | O14: =2*H14/F14 -> 3.0763551 | P14: =J14*N14^2 -> 251.06348 | Q14: =J14*O14^2 -> 60.257001 | R14: =J14*L14^2 -> 282.83082 | S14: =R14+T14-3*Q14 -> 150.33093 | T14: =J14*M14^2 -> 48.271119 | U14: =-3*$AI$11*((1-2*K14)^2.5)*(1+1.5*(4-$AI$12)*K14)*K14 -> 8.0062976 | V14: =((1-2*K14)^3.5)*($AI$4-$AI$14*K14)+3*U14 -> 282.8472 | W14: =((1-2*K14)^3.5)*($AI$5-$AI$15*K14)+1*U14 -> 150.22769 | X14: =((1-2*K14)^3.5)*($AI$6-$AI$16*K14)+1*U14 -> 48.235769 | Y14: =U14-B14 -> 0.17223451 | Z14: =V14-R14 -> 0.016380018 | AA14: =W14-S14 -> -0.10324723 | AB14: =X14-T14 -> -0.03535008 | AC14: =IF(AND(A14>=CutoffLowBar,A14<=CutoffOilBar),Y14^2+Z14^2+AA14^2+AB14^2,0) -> 0.041842649 | AD14: =(V14+2*W14)/3 -> 194.43419 | AE14: =(V14-W14+3*X14)/5 -> 55.465364 | AF14: =5*(V14-W14)*X14/(3*(V14-W14)+4*X14) -> 54.138344 | AG14: =(AE14+AF14)/2 -> 54.801854 | AH14: C11a | AI14: =3*$AI$11*($AI$7-3)-7*$AI$4 -> -499.76061 | AL14: GH0 (Hill) | AM14: =AG4 -> 50.277678
A15: =Align!A15 -> 330 | B15: =Align!B15 -> 8.5227719 | C15: =Align!C15 -> 0.20734572 | D15: =Align!D15 -> 0.50403365 | E15: =Align!F15 -> 0.1895445 | F15: =Align!G15 -> 0.3873536 | G15: 0.69310536 | H15: =G15*Lfin_111/Lfin_100 -> 0.59760647 | I15: =($G$4/G15)^3 -> 1.0479009 | J15: =rho_100*I15 -> 6.3817164 | K15: =0.5*(1-I15^(2/3)) -> -0.01584213 | L15: =2*G15/C15 -> 6.6855044 | M15: =2*G15/D15 -> 2.7502345 | N15: =2*H15/E15 -> 6.3057114 | O15: =2*H15/F15 -> 3.0855862 | P15: =J15*N15^2 -> 253.74978 | Q15: =J15*O15^2 -> 60.759316 | R15: =J15*L15^2 -> 285.237 | S15: =R15+T15-3*Q15 -> 151.22901 | T15: =J15*M15^2 -> 48.269961 | U15: =-3*$AI$11*((1-2*K15)^2.5)*(1+1.5*(4-$AI$12)*K15)*K15 -> 8.4571014 | V15: =((1-2*K15)^3.5)*($AI$4-$AI$14*K15)+3*U15 -> 285.1557 | W15: =((1-2*K15)^3.5)*($AI$5-$AI$15*K15)+1*U15 -> 151.4151 | X15: =((1-2*K15)^3.5)*($AI$6-$AI$16*K15)+1*U15 -> 48.286487 | Y15: =U15-B15 -> -0.065670514 | Z15: =V15-R15 -> -0.081298493 | AA15: =W15-S15 -> 0.186094 | AB15: =X15-T15 -> 0.016526474 | AC15: =IF(AND(A15>=CutoffLowBar,A15<=CutoffOilBar),Y15^2+Z15^2+AA15^2+AB15^2,0) -> 0.045826161 | AD15: =(V15+2*W15)/3 -> 195.9953 | AE15: =(V15-W15+3*X15)/5 -> 55.720011 | AF15: =5*(V15-W15)*X15/(3*(V15-W15)+4*X15) -> 54.325489 | AG15: =(AE15+AF15)/2 -> 55.02275 | AH15: C12a | AI15: =3*$AI$11*($AI$8-1)-7*$AI$5 -> -35.917736 | AL15: misfit | AM15: =$AI$18 -> 1.7693238
