Workbook

Sheet Baosheng Global
A1: V100 Pressure | B1: Oil P | C1: 2TP Au pressure corrected 111 | D1: 2TS Au pressure corrected 111 | E1: V100 Pressure | F1: 2TP Au 100 | G1: 2TS Au 100 high C44 | H1: L corrected v111 TP | I1: L correct v111 TS | J1: f(x) for cook | K1: rect+triang | L1: Sum Cook (I) | M1: Cook's Length | N1: integ unc | O1: trap uncert | P1: Trap add | Q1: L uncert | R1: Volume | S1: V ncrt | T1: V/v0 | U1: v/v0 ncrt | V1: New density | W1: rho ncrt | X1: Strain | Y1: VP100 ncrt | Z1: VS100 ncrt | AA1: VP111 ncrt | AB1: VS111 ncrt | AC1: Vp 111 | AD1: Vs 111 | AE1: Vs100 | AF1: pvs111^^2 | AG1: pvp111^2 | AH1: pvp111^2 = B | AI1: pvs111^2 = A | AJ1: C44 pVs100^2 | AK1: C12 calc | AL1: C11 calc | AN1: L | AO1: V | AP1: V0/V calc | AQ1: density | AR1: FS Pressure | AS1: finite strain f | AT1: C11 fit | AU1: C44 fit | AV1: C12 fit | AW1: C11 diff | AX1: C44 diff | AY1: C12 diff | AZ1: FSP diff | BC1: 2TP Au 100 | BD1: 2TS Au 100 high C44 | BE1: L corrected v111 TP | BF1: L correct v111 TS | BG1: L 100 | BH1: V | BI1: V0/V calc | BJ1: density | BK1: FS Pressure | BL1: finite strain f | BM1: delta P | BN1: Vp 111 | BO1: Vs 111 | BP1: Vs100 | BQ1: Vp100 | BR1: pvp111^2 = B | BS1: pvs111^2 = A | BT1: C11 from 100 | BU1: C44 pVs100^2 | BW1: C11 fit | BX1: C44 fit | BZ1: C12 fit | CA1: C11 diff | CB1: C44 diff | CC1: C12 diff | CD1: K | CE1: Vp100 FS | CF1: Vs100 FS | CG1: Vp111 FS | CH1: Vs111 FS | CJ1: GV | CK1: GR | CL1: GH | CN1: VP 100 diff | CO1: VS100 diff | CP1: VP111 diff | CQ1: VS 111 diff | CS1: C11 | CT1: C44 | CU1: C12 | CV1: < from no vp100
A2: 0 | B2: 0 | C2: 0.21010882 | D2: 0.41441731 | E2: 0 | F2: 0.22919993 | G2: 0.51092692 | H2: =C2*0.712/0.623 -> 0.24012437 | I2: =D2*0.712/0.623 -> 0.47361979 | J2: =1/((1/(H2^2))-(1.33333333333333/(G2^2))) -> 0.08172952 | L2: =SUM(K2:$K$2) -> 0 | M2: 0.704 | N2: =(6*F2*G2*SQRT(9*(G2^6)*(0.0002^2)+16*(F2^6)*(0.0002)^2))/((4*F2^2 - 3*G2^2)^2) -> 0.00017248585 | O2: =(((E2-E2)/2)^2)*(N2^2+N3^2) -> 0 | P2: =SUM(O2:$O$2) -> 0 | Q2: 0.001 | R2: =M2^3 -> 0.34891366 | S2: =3*Q2/M2*R2 -> 0.001486848 | T2: =R2/$R$2 -> 1 | U2: =T2*3*SQRT((Q2/M2)^2)+(0.001/$M$2)^2 -> 0.0042633813 | V2: =$B$40/((M2/$B$38)^3) -> 6.09 | W2: 0.01 | X2: =(1-((V2/$B$40)^0.66666667))/2 -> 0 | Y2: =(SQRT((Q2/M2)^2 + (0.0002/F2)^2))*#REF! -> #REF! | Z2: =SQRT((Q2/M2)^2 + (0.0002/G2)^2)*AE2 -> 0.0041065128 | AA2: =SQRT((Q2/M2)^2 + (0.0002/H2)^2)*AC2 -> 0.0097649912 | AB2: =SQRT((Q2/M2)^2 + (0.0002/I2)^2)*AD2 -> 0.00445551 | AC2: =2*0.712/H2 -> 5.9302602 | AD2: =2*0.712/I2 -> 3.0066311 | AE2: =2*0.712/G2 -> 2.7870914 | AF2: =V2*AD2^2 -> 55.052569 | AG2: =V2*AC2*AC2 -> 214.17304 | AH2: =V2*AC2^2 -> 214.17304 | AI2: =V2*AD2^2 -> 55.052569 | AJ2: =V2*AE2^2 -> 47.306379 | AK2: =AH2-AI2-AJ2 -> 111.81409 | AL2: =3*AI2+AK2-AJ2 -> 229.66542 | AN2: =M2 -> 0.704 | AO2: =AN2^3 -> 0.34891366 | AP2: =$AO$2/AO2 -> 1 | AQ2: 6.09 | AR2: =-3*$AZ$33*((1-2*AS2)^2.5)*(1+3*(4-$AZ$34)*AS2/2)*AS2 -> 0 | AS2: =0.5*(1-AP2^0.666666667) -> 0 | AT2: =(1-2*AS2)^(3.5)*($AZ$27-$AZ$40*AS2)+AR2*3 -> 236.4933 | AU2: =(1-2*AS2)^(3.5)*($AZ$29-$AZ$42*AS2)+AR2*1 -> 46.785203 | AV2: =(1-2*AS2)^(3.5)*($AZ$28-$AZ$41*AS2)+AR2*1 -> 120.75389 | AW2: =AT2-AL2 -> 6.8278835 | AX2: =AU2-AJ2 -> -0.52117609 | AY2: =AV2-AK2 -> 8.9398075 | AZ2: =AR2-A2 -> 0 | BC2: 0.22919993 | BD2: 0.51092692 | BE2: 0.24012437 | BF2: 0.47361979 | BG2: 0.704 | BH2: =BG2^3 -> 0.34891366 | BI2: =$BH$2/BH2 -> 1 | BJ2: 6.09 | BK2: =-3*$BD$33*((1-2*BL2)^2.5)*(1+3*(4-$BD$34)*BL2/2)*BL2 -> 0 | BL2: =0.5*(1-BI2^0.666666667) -> 0 | BM2: =BK2-E2 -> 0 | BN2: =2*0.712/BE2 -> 5.9302602 | BO2: =2*0.712/BF2 -> 3.0066311 | BP2: =2*0.712/BD2 -> 2.7870914 | BQ2: =2*0.712/BC2 -> 6.2129163 | BR2: =BJ2*BN2^2 -> 214.17304 | BS2: =BJ2*BO2^2 -> 55.052569 | BT2: =BJ2*BQ2^2 -> 235.076 | BU2: =BJ2*BP2^2 -> 47.306379 | BW2: =(1-2*BL2)^(3.5)*($BD$27-$BD$40*BL2)+BK2*3 -> 239.50441 | BX2: =(1-2*BL2)^(3.5)*($BD$29-$BD$42*BL2)+BK2*1 -> 46.445135 | BZ2: =(1-2*BL2)^(3.5)*($BD$28-$BD$41*BL2)+BK2*1 -> 121.66535 | CA2: =BW2-BT2 -> 4.428407 | CB2: =BX2-BU2 -> -0.86124342 | CC2: =BZ2-BV2 -> 121.66535 | CD2: =(BW2+2*BZ2)/3 -> 160.94504 | CE2: =SQRT(BW2/BJ2) -> 6.2711633 | CF2: =SQRT(BX2/BJ2) -> 2.7616044 | CG2: =SQRT((0.33333334*(BW2+2*BZ2+4*BX2))/BJ2) -> 6.0494933 | CH2: =SQRT((0.3333334*(BW2-BZ2+BX2))/BJ2) -> 2.9986699 | CJ2: =(BW2-BZ2+3*BX2)/5 -> 51.434893 | CK2: =((5*(BW2-BZ2)*BX2)/(3*(BW2-BZ2)+4*BX2)) -> 50.74239 | CL2: =(CJ2+CK2)/2 -> 51.088641 | CN2: =CE2-BQ2 -> 0.05824702 | CO2: =CF2-BP2 -> -0.025486941 | CP2: =CG2-BN2 -> 0.11923308 | CQ2: =CH2-BO2 -> -0.0079612424 | CS2: 236.4308 | CT2: 46.82052 | CU2: 120.73087 | DW2: o | EP2: 0
A3: 0.12913291 | B3: 30 | C3: 0.2017768 | D3: 0.41395642 | E3: 0.12913291 | F3: 0.22474572 | G3: 0.50723365 | H3: =C3*0.704/0.607 -> 0.2340212 | I3: =D3*0.704/0.607 -> 0.48010762 | J3: =1/((1/(H3^2))-(1.33333333333333/(G3^2))) -> 0.076468796 | K3: =(J3*(E3-E2)+0.5*(E3-E2)*(J2-J3)) -> 0.010214304 | L3: =SUM(K$3:$K3) -> 0.010214304 | M3: =$B$38/((L3*$B$43+1)) -> 0.70379815 | N3: =(6*F3*G3*SQRT(9*(G3^6)*(0.0002^2)+16*(F3^6)*(0.0002)^2))/((4*F3^2 - 3*G3^2)^2) -> 0.00016605784 | O3: =(((E3-E2)/2)^2)*(N3^2+N4^2) -> 2.216109e-10 | P3: =SUM(O$2:$O3) -> 2.216109e-10 | Q3: =SQRT(((M30*0.001)^2)+((N30*0.02)^2)+((O30*P3)^2)) -> 0.0010002868 | R3: =M3^3 -> 0.34861363 | S3: =3*Q3/M3*R3 -> 0.0014864217 | T3: =R3/$R$2 -> 0.9991401 | U3: =T3*3*SQRT((Q3/M3)^2)+(0.001/$M$2)^2 -> 0.0042621594 | V3: =$B$40/((M3/$B$38)^3) -> 6.0952413 | W3: =(SQRT((0.02/$V$2)^2+(9*(0.001/$M$2)^2)+(9*(Q3/M3)^2))*V3) -> 0.041842138 | X3: =(1-((V3/$B$40)^0.66666667))/2 -> -0.00028683825 | Y3: =(SQRT((Q3/M3)^2 + (0.0002/F3)^2))*#REF! -> #REF! | Z3: =SQRT((Q3/M3)^2 + (0.0002/G3)^2)*AE3 -> 0.0040930513 | AA3: =SQRT((Q3/M3)^2 + (0.0002/H3)^2)*AC3 -> 0.0099751606 | AB3: =SQRT((Q3/M3)^2 + (0.0002/I3)^2)*AD3 -> 0.0043422247 | AC3: =2*M3/H3 -> 6.014824 | AD3: =2*M3/I3 -> 2.931835 | AE3: =2*M3/G3 -> 2.7750452 | AF3: =V3*AD3^2 -> 52.3926 | AG3: =V3*AC3*AC3 -> 220.51429 | AH3: =V3*AC3^2 -> 220.51429 | AI3: =V3*AD3^2 -> 52.3926 | AJ3: =V3*AE3^2 -> 46.938697 | AK3: =AH3-AI3-AJ3 -> 121.183 | AL3: =3*AI3+AK3-AJ3 -> 231.4221 | AN3: =M3 -> 0.70379815 | AO3: =AN3^3 -> 0.34861363 | AP3: =$AO$2/AO3 -> 1.0008606 | AQ3: =$AQ$2/((AN3/$AN$2)^3) -> 6.0952413 | AR3: =-3*$AZ$33*((1-2*AS3)^2.5)*(1+3*(4-$AZ$34)*AS3/2)*AS3 -> 0.13730337 | AS3: =0.5*(1-AP3^0.666666667) -> -0.00028683825 | AT3: =(1-2*AS3)^(3.5)*($AZ$27-$AZ$40*AS3)+AR3*3 -> 237.26408 | AU3: =(1-2*AS3)^(3.5)*($AZ$29-$AZ$42*AS3)+AR3*1 -> 46.819872 | AV3: =(1-2*AS3)^(3.5)*($AZ$28-$AZ$41*AS3)+AR3*1 -> 121.1838 | AW3: =AT3-AL3 -> 5.8419826 | AX3: =AU3-AJ3 -> -0.11882546 | AY3: =AV3-AK3 -> 0.00080018869 | AZ3: =AR3-A3 -> 0.0081704626 | BC3: 0.22474572 | BD3: 0.50723365 | BE3: 0.2340212 | BF3: 0.48010762 | BG3: 0.70379815 | BH3: =BG3^3 -> 0.34861363 | BI3: =$BH$2/BH3 -> 1.0008606 | BJ3: =$BJ$2/((BG3/$BG$2)^3) -> 6.0952413 | BK3: =-3*$BD$33*((1-2*BL3)^2.5)*(1+3*(4-$BD$34)*BL3/2)*BL3 -> 0.13868894 | BL3: =0.5*(1-BI3^0.666666667) -> -0.00028683825 | BM3: =BK3-E3 -> 0.0095560346 | BN3: =2*BG3/BE3 -> 6.014824 | BO3: =2*BG3/BF3 -> 2.931835 | BP3: =2*BG3/BD3 -> 2.7750452 | BQ3: =2*BG3/BC3 -> 6.2630617 | BR3: =BJ3*BN3^2 -> 220.51429 | BS3: =BJ3*BO3^2 -> 52.3926 | BT3: =BJ3*BQ3^2 -> 239.09158 | BU3: =BJ3*BP3^2 -> 46.938697 | BW3: =(1-2*BL3)^(3.5)*($BD$27-$BD$40*BL3)+BK3*3 -> 240.26801 | BX3: =(1-2*BL3)^(3.5)*($BD$29-$BD$42*BL3)+BK3*1 -> 46.482491 | BZ3: =(1-2*BL3)^(3.5)*($BD$28-$BD$41*BL3)+BK3*1 -> 122.0967 | CA3: =BW3-BT3 -> 1.1764321 | CB3: =BX3-BU3 -> -0.45620651 | CC3: =BZ3-BV3 -> 122.0967 | CD3: =(BW3+2*BZ3)/3 -> 161.48714 | CE3: =SQRT(BW3/BJ3) -> 6.2784512 | CF3: =SQRT(BX3/BJ3) -> 2.7615267 | CG3: =SQRT((0.33333334*(BW3+2*BZ3+4*BX3))/BJ3) -> 6.0549162 | CH3: =SQRT((0.3333334*(BW3-BZ3+BX3))/BJ3) -> 3.0007502 | CJ3: =(BW3-BZ3+3*BX3)/5 -> 51.523756 | CK3: =((5*(BW3-BZ3)*BX3)/(3*(BW3-BZ3)+4*BX3)) -> 50.818381 | CL3: =(CJ3+CK3)/2 -> 51.171069 | CN3: =CE3-BQ3 -> 0.015389555 | CO3: =CF3-BP3 -> -0.013518535 | CP3: =CG3-BN3 -> 0.040092212 | CQ3: =CH3-BO3 -> 0.068915205 | CS3: 237.21415 | CT3: 46.854444 | CU3: 121.16793
A4: 1.6356835 | B4: 60 | C4: 0.19870445 | D4: 0.40424966 | E4: 1.6356835 | F4: 0.22094572 | G4: 0.50583365 | H4: =C4*0.704/0.607 -> 0.23045788 | I4: =D4*0.704/0.607 -> 0.46884969 | J4: =1/((1/(H4^2))-(1.33333333333333/(G4^2))) -> 0.073434797 | K4: =(J4*(E4-E3)+0.5*(E4-E3)*(J3-J4)) -> 0.11291867 | L4: =SUM(K$3:$K4) -> 0.12313298 | M4: =$B$38/((L4*$B$43+1)) -> 0.70157443 | N4: =(6*F4*G4*SQRT(9*(G4^6)*(0.0002^2)+16*(F4^6)*(0.0002)^2))/((4*F4^2 - 3*G4^2)^2) -> 0.00015994952 | O4: =(((E4-E3)/2)^2)*(N4^2+N5^2) -> 2.8357893e-08 | P4: =SUM(O$2:$O4) -> 2.8579504e-08 | Q4: =SQRT(((M31*0.001)^2)+((N31*0.02)^2)+((O31*P4)^2)) -> 0.0010034531 | R4: =M4^3 -> 0.34531962 | S4: =3*Q4/M4*R4 -> 0.0014817189 | T4: =R4/$R$2 -> 0.98969933 | U4: =T4*3*SQRT((Q4/M4)^2)+(0.001/$M$2)^2 -> 0.0042486812 | V4: =$B$40/((M4/$B$38)^3) -> 6.153384 | W4: =(SQRT((0.02/$V$2)^2+(9*(0.001/$M$2)^2)+(9*(Q4/M4)^2))*V4) -> 0.042344873 | X4: =(1-((V4/$B$40)^0.66666667))/2 -> -0.0034633029 | Y4: =(SQRT((Q4/M4)^2 + (0.0002/F4)^2))*#REF! -> #REF! | Z4: =SQRT((Q4/M4)^2 + (0.0002/G4)^2)*AE4 -> 0.0041163274 | AA4: =SQRT((Q4/M4)^2 + (0.0002/H4)^2)*AC4 -> 0.010185986 | AB4: =SQRT((Q4/M4)^2 + (0.0002/I4)^2)*AD4 -> 0.0044668092 | AC4: =2*M4/H4 -> 6.0885262 | AD4: =2*M4/I4 -> 2.9927477 | AE4: =2*M4/G4 -> 2.7739334 | AF4: =V4*AD4^2 -> 55.113024 | AG4: =V4*AC4*AC4 -> 228.10687 | AH4: =V4*AC4^2 -> 228.10687 | AI4: =V4*AD4^2 -> 55.113024 | AJ4: =V4*AE4^2 -> 47.348484 | AK4: =AH4-AI4-AJ4 -> 125.64536 | AL4: =3*AI4+AK4-AJ4 -> 243.63595 | AN4: =M4 -> 0.70157443 | AO4: =AN4^3 -> 0.34531962 | AP4: =$AO$2/AO4 -> 1.0104079 | AQ4: =$AQ$2/((AN4/$AN$2)^3) -> 6.153384 | AR4: =-3*$AZ$33*((1-2*AS4)^2.5)*(1+3*(4-$AZ$34)*AS4/2)*AS4 -> 1.6839307 | AS4: =0.5*(1-AP4^0.666666667) -> -0.0034633029 | AT4: =(1-2*AS4)^(3.5)*($AZ$27-$AZ$40*AS4)+AR4*3 -> 245.89237 | AU4: =(1-2*AS4)^(3.5)*($AZ$29-$AZ$42*AS4)+AR4*1 -> 47.185778 | AV4: =(1-2*AS4)^(3.5)*($AZ$28-$AZ$41*AS4)+AR4*1 -> 126.00754 | AW4: =AT4-AL4 -> 2.2564208 | AX4: =AU4-AJ4 -> -0.162706 | AY4: =AV4-AK4 -> 0.36217462 | AZ4: =AR4-A4 -> 0.048247237 | BC4: 0.22094572 | BD4: 0.50583365 | BE4: 0.23045788 | BF4: 0.46884969 | BG4: 0.70157443 | BH4: =BG4^3 -> 0.34531962 | BI4: =$BH$2/BH4 -> 1.0104079 | BJ4: =$BJ$2/((BG4/$BG$2)^3) -> 6.153384 | BK4: =-3*$BD$33*((1-2*BL4)^2.5)*(1+3*(4-$BD$34)*BL4/2)*BL4 -> 1.7005197 | BL4: =0.5*(1-BI4^0.666666667) -> -0.0034633029 | BM4: =BK4-E4 -> 0.064836213 | BN4: =2*BG4/BE4 -> 6.0885262 | BO4: =2*BG4/BF4 -> 2.9927477 | BP4: =2*BG4/BD4 -> 2.7739334 | BQ4: =2*BG4/BC4 -> 6.3506496 | BR4: =BJ4*BN4^2 -> 228.10687 | BS4: =BJ4*BO4^2 -> 55.113024 | BT4: =BJ4*BQ4^2 -> 248.1706 | BU4: =BJ4*BP4^2 -> 47.348484 | BW4: =(1-2*BL4)^(3.5)*($BD$27-$BD$40*BL4)+BK4*3 -> 248.81227 | BX4: =(1-2*BL4)^(3.5)*($BD$29-$BD$42*BL4)+BK4*1 -> 46.878476 | BZ4: =(1-2*BL4)^(3.5)*($BD$28-$BD$41*BL4)+BK4*1 -> 126.93606 | CA4: =BW4-BT4 -> 0.64166994 | CB4: =BX4-BU4 -> -0.4700087 | CC4: =BZ4-BV4 -> 126.93606 | CD4: =(BW4+2*BZ4)/3 -> 167.56146 | CE4: =SQRT(BW4/BJ4) -> 6.3588545 | CF4: =SQRT(BX4/BJ4) -> 2.7601312 | CG4: =SQRT((0.33333334*(BW4+2*BZ4+4*BX4))/BJ4) -> 6.1146177 | CH4: =SQRT((0.3333334*(BW4-BZ4+BX4))/BJ4) -> 3.0235024 | CJ4: =(BW4-BZ4+3*BX4)/5 -> 52.502327 | CK4: =((5*(BW4-BZ4)*BX4)/(3*(BW4-BZ4)+4*BX4)) -> 51.644654 | CL4: =(CJ4+CK4)/2 -> 52.07349 | CN4: =CE4-BQ4 -> 0.0082048202 | CO4: =CF4-BP4 -> -0.013802179 | CP4: =CG4-BN4 -> 0.0260915 | CQ4: =CH4-BO4 -> 0.030754719 | CS4: 245.98659 | CT4: 47.212425 | CU4: 126.07344
A5: 2.4965696 | B5: 90 | C5: 0.19712307 | D5: 0.40093724 | E5: 2.4965696 | F5: 0.21874572 | G5: 0.50583365 | H5: =C5*0.704/0.607 -> 0.22862379 | I5: =D5*0.704/0.607 -> 0.46500794 | J5: =1/((1/(H5^2))-(1.33333333333333/(G5^2))) -> 0.071834787 | K5: =(J5*(E5-E4)+0.5*(E5-E4)*(J4-J5)) -> 0.06253028 | L5: =SUM(K$3:$K5) -> 0.18566326 | M5: =$B$38/((L5*$B$43+1)) -> 0.70034904 | N5: =(6*F5*G5*SQRT(9*(G5^6)*(0.0002^2)+16*(F5^6)*(0.0002)^2))/((4*F5^2 - 3*G5^2)^2) -> 0.00015618171 | O5: =(((E5-E4)/2)^2)*(N5^2+N6^2) -> 8.8434243e-09 | P5: =SUM(O$2:$O5) -> 3.7422929e-08 | Q5: =SQRT(((M32*0.001)^2)+((N32*0.02)^2)+((O32*P5)^2)) -> 0.001005203 | R5: =M5^3 -> 0.34351335 | S5: =3*Q5/M5*R5 -> 0.0014791224 | T5: =R5/$R$2 -> 0.9845225 | U5: =T5*3*SQRT((Q5/M5)^2)+(0.001/$M$2)^2 -> 0.0042412394 | V5: =$B$40/((M5/$B$38)^3) -> 6.1857398 | W5: =(SQRT((0.02/$V$2)^2+(9*(0.001/$M$2)^2)+(9*(Q5/M5)^2))*V5) -> 0.042625462 | X5: =(1-((V5/$B$40)^0.66666667))/2 -> -0.0052266388 | Y5: =(SQRT((Q5/M5)^2 + (0.0002/F5)^2))*#REF! -> #REF! | Z5: =SQRT((Q5/M5)^2 + (0.0002/G5)^2)*AE5 -> 0.0041224874 | AA5: =SQRT((Q5/M5)^2 + (0.0002/H5)^2)*AC5 -> 0.01029811 | AB5: =SQRT((Q5/M5)^2 + (0.0002/I5)^2)*AD5 -> 0.0045133204 | AC5: =2*M5/H5 -> 6.1266507 | AD5: =2*M5/I5 -> 3.0122025 | AE5: =2*M5/G5 -> 2.7690884 | AF5: =V5*AD5^2 -> 56.125469 | AG5: =V5*AC5*AC5 -> 232.18699 | AH5: =V5*AC5^2 -> 232.18699 | AI5: =V5*AD5^2 -> 56.125469 | AJ5: =V5*AE5^2 -> 47.431329 | AK5: =AH5-AI5-AJ5 -> 128.63019 | AL5: =3*AI5+AK5-AJ5 -> 249.57527 | AN5: =M5 -> 0.70034904 | AO5: =AN5^3 -> 0.34351335 | AP5: =$AO$2/AO5 -> 1.0157208 | AQ5: =$AQ$2/((AN5/$AN$2)^3) -> 6.1857398 | AR5: =-3*$AZ$33*((1-2*AS5)^2.5)*(1+3*(4-$AZ$34)*AS5/2)*AS5 -> 2.5633424 | AS5: =0.5*(1-AP5^0.666666667) -> -0.0052266388 | AT5: =(1-2*AS5)^(3.5)*($AZ$27-$AZ$40*AS5)+AR5*3 -> 250.75581 | AU5: =(1-2*AS5)^(3.5)*($AZ$29-$AZ$42*AS5)+AR5*1 -> 47.374279 | AV5: =(1-2*AS5)^(3.5)*($AZ$28-$AZ$41*AS5)+AR5*1 -> 128.73557 | AW5: =AT5-AL5 -> 1.1805397 | AX5: =AU5-AJ5 -> -0.057049684 | AY5: =AV5-AK5 -> 0.10537817 | AZ5: =AR5-A5 -> 0.066772834 | BC5: 0.21874572 | BD5: 0.50583365 | BE5: 0.22862379 | BF5: 0.46500794 | BG5: 0.70034904 | BH5: =BG5^3 -> 0.34351335 | BI5: =$BH$2/BH5 -> 1.0157208 | BJ5: =$BJ$2/((BG5/$BG$2)^3) -> 6.1857398 | BK5: =-3*$BD$33*((1-2*BL5)^2.5)*(1+3*(4-$BD$34)*BL5/2)*BL5 -> 2.5882532 | BL5: =0.5*(1-BI5^0.666666667) -> -0.0052266388 | BM5: =BK5-E5 -> 0.091683612 | BN5: =2*BG5/BE5 -> 6.1266507 | BO5: =2*BG5/BF5 -> 3.0122025 | BP5: =2*BG5/BD5 -> 2.7690884 | BQ5: =2*BG5/BC5 -> 6.4033166 | BR5: =BJ5*BN5^2 -> 232.18699 | BS5: =BJ5*BO5^2 -> 56.125469 | BT5: =BJ5*BQ5^2 -> 253.63057 | BU5: =BJ5*BP5^2 -> 47.431329 | BW5: =(1-2*BL5)^(3.5)*($BD$27-$BD$40*BL5)+BK5*3 -> 253.6254 | BX5: =(1-2*BL5)^(3.5)*($BD$29-$BD$42*BL5)+BK5*1 -> 47.083934 | BZ5: =(1-2*BL5)^(3.5)*($BD$28-$BD$41*BL5)+BK5*1 -> 129.6724 | CA5: =BW5-BT5 -> -0.005171065 | CB5: =BX5-BU5 -> -0.34739502 | CC5: =BZ5-BV5 -> 129.6724 | CD5: =(BW5+2*BZ5)/3 -> 170.99006 | CE5: =SQRT(BW5/BJ5) -> 6.4032513 | CF5: =SQRT(BX5/BJ5) -> 2.7589291 | CG5: =SQRT((0.33333334*(BW5+2*BZ5+4*BX5))/BJ5) -> 6.1474826 | CH5: =SQRT((0.3333334*(BW5-BZ5+BX5))/BJ5) -> 3.0359075 | CJ5: =(BW5-BZ5+3*BX5)/5 -> 53.04096 | CK5: =((5*(BW5-BZ5)*BX5)/(3*(BW5-BZ5)+4*BX5)) -> 52.090768 | CL5: =(CJ5+CK5)/2 -> 52.565864 | CN5: =CE5-BQ5 -> -6.527631e-05 | CO5: =CF5-BP5 -> -0.010159271 | CP5: =CG5-BN5 -> 0.020831912 | CQ5: =CH5-BO5 -> 0.023705003 | CS5: 250.9341 | CT5: 47.396786 | CU5: 128.84886
A6: 3.4435442 | B6: 120 | C6: 0.19552144 | D6: 0.39786989 | E6: 3.4435442 | F6: 0.21654572 | G6: 0.50523365 | H6: =C6*0.704/0.607 -> 0.22676622 | I6: =D6*0.704/0.607 -> 0.46145042 | J6: =1/((1/(H6^2))-(1.33333333333333/(G6^2))) -> 0.07030781 | K6: =(J6*(E6-E5)+0.5*(E6-E5)*(J5-J6)) -> 0.067302719 | L6: =SUM(K$3:$K6) -> 0.25296598 | M6: =$B$38/((L6*$B$43+1)) -> 0.69903491 | N6: =(6*F6*G6*SQRT(9*(G6^6)*(0.0002^2)+16*(F6^6)*(0.0002)^2))/((4*F6^2 - 3*G6^2)^2) -> 0.00015276458 | O6: =(((E6-E5)/2)^2)*(N6^2+N7^2) -> 1.0265501e-08 | P6: =SUM(O$2:$O6) -> 4.768843e-08 | Q6: =SQRT(((M33*0.001)^2)+((N33*0.02)^2)+((O33*P6)^2)) -> 0.0010070834 | R6: =M6^3 -> 0.34158328 | S6: =3*Q6/M6*R6 -> 0.0014763333 | T6: =R6/$R$2 -> 0.97899082 | U6: =T6*3*SQRT((Q6/M6)^2)+(0.001/$M$2)^2 -> 0.0042332457 | V6: =$B$40/((M6/$B$38)^3) -> 6.2206916 | W6: =(SQRT((0.02/$V$2)^2+(9*(0.001/$M$2)^2)+(9*(Q6/M6)^2))*V6) -> 0.042929216 | X6: =(1-((V6/$B$40)^0.66666667))/2 -> -0.0071280005 | Y6: =(SQRT((Q6/M6)^2 + (0.0002/F6)^2))*#REF! -> #REF! | Z6: =SQRT((Q6/M6)^2 + (0.0002/G6)^2)*AE6 -> 0.0041343591 | AA6: =SQRT((Q6/M6)^2 + (0.0002/H6)^2)*AC6 -> 0.010414365 | AB6: =SQRT((Q6/M6)^2 + (0.0002/I6)^2)*AD6 -> 0.0045581055 | AC6: =2*M6/H6 -> 6.1652473 | AD6: =2*M6/I6 -> 3.0297292 | AE6: =2*M6/G6 -> 2.7671748 | AF6: =V6*AD6^2 -> 57.101341 | AG6: =V6*AC6*AC6 -> 236.45019 | AH6: =V6*AC6^2 -> 236.45019 | AI6: =V6*AD6^2 -> 57.101341 | AJ6: =V6*AE6^2 -> 47.633431 | AK6: =AH6-AI6-AJ6 -> 131.71542 | AL6: =3*AI6+AK6-AJ6 -> 255.38601 | AN6: =M6 -> 0.69903491 | AO6: =AN6^3 -> 0.34158328 | AP6: =$AO$2/AO6 -> 1.02146 | AQ6: =$AQ$2/((AN6/$AN$2)^3) -> 6.2206916 | AR6: =-3*$AZ$33*((1-2*AS6)^2.5)*(1+3*(4-$AZ$34)*AS6/2)*AS6 -> 3.5284257 | AS6: =0.5*(1-AP6^0.666666667) -> -0.0071280005 | AT6: =(1-2*AS6)^(3.5)*($AZ$27-$AZ$40*AS6)+AR6*3 -> 256.05922 | AU6: =(1-2*AS6)^(3.5)*($AZ$29-$AZ$42*AS6)+AR6*1 -> 47.565461 | AV6: =(1-2*AS6)^(3.5)*($AZ$28-$AZ$41*AS6)+AR6*1 -> 131.71776 | AW6: =AT6-AL6 -> 0.67320088 | AX6: =AU6-AJ6 -> -0.067969763 | AY6: =AV6-AK6 -> 0.0023329727 | AZ6: =AR6-A6 -> 0.084881525 | BC6: 0.21654572 | BD6: 0.50523365 | BE6: 0.22676622 | BF6: 0.46145042 | BG6: 0.69919354 | BH6: =BG6^3 -> 0.34181587 | BI6: =$BH$2/BH6 -> 1.020765 | BJ6: =$BJ$2/((BG6/$BG$2)^3) -> 6.2164587 | BK6: =-3*$BD$33*((1-2*BL6)^2.5)*(1+3*(4-$BD$34)*BL6/2)*BL6 -> 3.4434241 | BL6: =0.5*(1-BI6^0.666666667) -> -0.0068979208 | BM6: =BK6-E6 -> -0.00012007968 | BN6: =2*BG6/BE6 -> 6.1666463 | BO6: =2*BG6/BF6 -> 3.0304168 | BP6: =2*BG6/BD6 -> 2.7678028 | BQ6: =2*BG6/BC6 -> 6.457699 | BR6: =BJ6*BN6^2 -> 236.39655 | BS6: =BJ6*BO6^2 -> 57.088386 | BT6: =BJ6*BQ6^2 -> 259.23799 | BU6: =BJ6*BP6^2 -> 47.622624 | BW6: =(1-2*BL6)^(3.5)*($BD$27-$BD$40*BL6)+BK6*3 -> 258.23361 | BX6: =(1-2*BL6)^(3.5)*($BD$29-$BD$42*BL6)+BK6*1 -> 47.2689 | BZ6: =(1-2*BL6)^(3.5)*($BD$28-$BD$41*BL6)+BK6*1 -> 132.29909 | CA6: =BW6-BT6 -> -1.0043815 | CB6: =BX6-BU6 -> -0.35372388 | CC6: =BZ6-BV6 -> 132.29909 | CD6: =(BW6+2*BZ6)/3 -> 174.27726 | CE6: =SQRT(BW6/BJ6) -> 6.4451771 | CF6: =SQRT(BX6/BJ6) -> 2.7575045 | CG6: =SQRT((0.33333334*(BW6+2*BZ6+4*BX6))/BJ6) -> 6.1784509 | CH6: =SQRT((0.3333334*(BW6-BZ6+BX6))/BJ6) -> 3.0475169 | CJ6: =(BW6-BZ6+3*BX6)/5 -> 53.548245 | CK6: =((5*(BW6-BZ6)*BX6)/(3*(BW6-BZ6)+4*BX6)) -> 52.504896 | CL6: =(CJ6+CK6)/2 -> 53.02657 | CN6: =CE6-BQ6 -> -0.012521868 | CO6: =CF6-BP6 -> -0.010298285 | CP6: =CG6-BN6 -> 0.011804567 | CQ6: =CH6-BO6 -> 0.017100167 | CS6: 255.47971 | CT6: 47.5552 | CU6: 131.40435
A7: 4.4335632 | B7: 150 | C7: 0.19396667 | D7: 0.39485534 | E7: 4.4335632 | F7: 0.21474572 | G7: 0.50523365 | H7: =C7*0.704/0.607 -> 0.224963 | I7: =D7*0.704/0.607 -> 0.45795413 | J7: =1/((1/(H7^2))-(1.33333333333333/(G7^2))) -> 0.068793893 | K7: =(J7*(E7-E6)+0.5*(E7-E6)*(J6-J7)) -> 0.068856661 | L7: =SUM(K$3:$K7) -> 0.32182264 | M7: =$B$38/((L7*$B$43+1)) -> 0.69769553 | N7: =(6*F7*G7*SQRT(9*(G7^6)*(0.0002^2)+16*(F7^6)*(0.0002)^2))/((4*F7^2 - 3*G7^2)^2) -> 0.00014984065 | O7: =(((E7-E6)/2)^2)*(N7^2+N8^2) -> 1.0840844e-08 | P7: =SUM(O$2:$O7) -> 5.8529274e-08 | Q7: =SQRT(((M34*0.001)^2)+((N34*0.02)^2)+((O34*P7)^2)) -> 0.0010090035 | R7: =M7^3 -> 0.33962357 | S7: =3*Q7/M7*R7 -> 0.0014734853 | T7: =R7/$R$2 -> 0.97337423 | U7: =T7*3*SQRT((Q7/M7)^2)+(0.001/$M$2)^2 -> 0.0042250832 | V7: =$B$40/((M7/$B$38)^3) -> 6.2565864 | W7: =(SQRT((0.02/$V$2)^2+(9*(0.001/$M$2)^2)+(9*(Q7/M7)^2))*V7) -> 0.043241866 | X7: =(1-((V7/$B$40)^0.66666667))/2 -> -0.0090769582 | Y7: =(SQRT((Q7/M7)^2 + (0.0002/F7)^2))*#REF! -> #REF! | Z7: =SQRT((Q7/M7)^2 + (0.0002/G7)^2)*AE7 -> 0.0041411342 | AA7: =SQRT((Q7/M7)^2 + (0.0002/H7)^2)*AC7 -> 0.010529832 | AB7: =SQRT((Q7/M7)^2 + (0.0002/I7)^2)*AD7 -> 0.0046031116 | AC7: =2*M7/H7 -> 6.2027582 | AD7: =2*M7/I7 -> 3.0470105 | AE7: =2*M7/G7 -> 2.7618728 | AF7: =V7*AD7^2 -> 58.087857 | AG7: =V7*AC7*AC7 -> 240.71721 | AH7: =V7*AC7^2 -> 240.71721 | AI7: =V7*AD7^2 -> 58.087857 | AJ7: =V7*AE7^2 -> 47.724874 | AK7: =AH7-AI7-AJ7 -> 134.90448 | AL7: =3*AI7+AK7-AJ7 -> 261.44318 | AN7: =M7 -> 0.69769553 | AO7: =AN7^3 -> 0.33962357 | AP7: =$AO$2/AO7 -> 1.0273541 | AQ7: =$AQ$2/((AN7/$AN$2)^3) -> 6.2565864 | AR7: =-3*$AZ$33*((1-2*AS7)^2.5)*(1+3*(4-$AZ$34)*AS7/2)*AS7 -> 4.5359445 | AS7: =0.5*(1-AP7^0.666666667) -> -0.0090769582 | AT7: =(1-2*AS7)^(3.5)*($AZ$27-$AZ$40*AS7)+AR7*3 -> 261.55952 | AU7: =(1-2*AS7)^(3.5)*($AZ$29-$AZ$42*AS7)+AR7*1 -> 47.74809 | AV7: =(1-2*AS7)^(3.5)*($AZ$28-$AZ$41*AS7)+AR7*1 -> 134.8187 | AW7: =AT7-AL7 -> 0.11634034 | AX7: =AU7-AJ7 -> 0.0232161 | AY7: =AV7-AK7 -> -0.085785868 | AZ7: =AR7-A7 -> 0.10238136 | BC7: 0.21474572 | BD7: 0.50523365 | BE7: 0.224963 | BF7: 0.45795413 | BG7: 0.69788513 | BH7: =BG7^3 -> 0.33990052 | BI7: =$BH$2/BH7 -> 1.026517 | BJ7: =$BJ$2/((BG7/$BG$2)^3) -> 6.2514886 | BK7: =-3*$BD$33*((1-2*BL7)^2.5)*(1+3*(4-$BD$34)*BL7/2)*BL7 -> 4.4333338 | BL7: =0.5*(1-BI7^0.666666667) -> -0.0088003907 | BM7: =BK7-E7 -> -0.00022941362 | BN7: =2*BG7/BE7 -> 6.2044437 | BO7: =2*BG7/BF7 -> 3.0478385 | BP7: =2*BG7/BD7 -> 2.7626233 | BQ7: =2*BG7/BC7 -> 6.4996418 | BR7: =BJ7*BN7^2 -> 240.65182 | BS7: =BJ7*BO7^2 -> 58.072076 | BT7: =BJ7*BQ7^2 -> 264.09628 | BU7: =BJ7*BP7^2 -> 47.711908 | BW7: =(1-2*BL7)^(3.5)*($BD$27-$BD$40*BL7)+BK7*3 -> 263.53439 | BX7: =(1-2*BL7)^(3.5)*($BD$29-$BD$42*BL7)+BK7*1 -> 47.467596 | BZ7: =(1-2*BL7)^(3.5)*($BD$28-$BD$41*BL7)+BK7*1 -> 135.32875 | CA7: =BW7-BT7 -> -0.56189495 | CB7: =BX7-BU7 -> -0.24431258 | CC7: =BZ7-BV7 -> 135.32875 | CD7: =(BW7+2*BZ7)/3 -> 178.06396 | CE7: =SQRT(BW7/BJ7) -> 6.4927237 | CF7: =SQRT(BX7/BJ7) -> 2.7555411 | CG7: =SQRT((0.33333334*(BW7+2*BZ7+4*BX7))/BJ7) -> 6.2134902 | CH7: =SQRT((0.3333334*(BW7-BZ7+BX7))/BJ7) -> 3.0605571 | CJ7: =(BW7-BZ7+3*BX7)/5 -> 54.121684 | CK7: =((5*(BW7-BZ7)*BX7)/(3*(BW7-BZ7)+4*BX7)) -> 52.965604 | CL7: =(CJ7+CK7)/2 -> 53.543644 | CN7: =CE7-BQ7 -> -0.0069180463 | CO7: =CF7-BP7 -> -0.0070821928 | CP7: =CG7-BN7 -> 0.009046449 | CQ7: =CH7-BO7 -> 0.012718578 | CS7: 261.45855 | CT7: 47.747765 | CU7: 134.77353
A8: 5.122272 | B8: 180 | C8: 0.19293671 | D8: 0.3928225 | E8: 5.122272 | F8: 0.21334572 | G8: 0.50523365 | H8: =C8*0.704/0.607 -> 0.22376844 | I8: =D8*0.704/0.607 -> 0.45559644 | J8: =1/((1/(H8^2))-(1.33333333333333/(G8^2))) -> 0.067807165 | K8: =(J8*(E8-E7)+0.5*(E8-E7)*(J7-J8)) -> 0.047039178 | L8: =SUM(K$3:$K8) -> 0.36886182 | M8: =$B$38/((L8*$B$43+1)) -> 0.69678348 | N8: =(6*F8*G8*SQRT(9*(G8^6)*(0.0002^2)+16*(F8^6)*(0.0002)^2))/((4*F8^2 - 3*G8^2)^2) -> 0.00014761407 | O8: =(((E8-E7)/2)^2)*(N8^2+N9^2) -> 5.0935318e-09 | P8: =SUM(O$2:$O8) -> 6.3622806e-08 | Q8: =SQRT(((M35*0.001)^2)+((N35*0.02)^2)+((O35*P8)^2)) -> 0.0010103129 | R8: =M8^3 -> 0.33829342 | S8: =3*Q8/M8*R8 -> 0.0014715427 | T8: =R8/$R$2 -> 0.96956196 | U8: =T8*3*SQRT((Q8/M8)^2)+(0.001/$M$2)^2 -> 0.0042195156 | V8: =$B$40/((M8/$B$38)^3) -> 6.281187 | W8: =(SQRT((0.02/$V$2)^2+(9*(0.001/$M$2)^2)+(9*(Q8/M8)^2))*V8) -> 0.043456547 | X8: =(1-((V8/$B$40)^0.66666667))/2 -> -0.010410531 | Y8: =(SQRT((Q8/M8)^2 + (0.0002/F8)^2))*#REF! -> #REF! | Z8: =SQRT((Q8/M8)^2 + (0.0002/G8)^2)*AE8 -> 0.0041457574 | AA8: =SQRT((Q8/M8)^2 + (0.0002/H8)^2)*AC8 -> 0.010607705 | AB8: =SQRT((Q8/M8)^2 + (0.0002/I8)^2)*AD8 -> 0.0046339294 | AC8: =2*M8/H8 -> 6.2277189 | AD8: =2*M8/I8 -> 3.0587749 | AE8: =2*M8/G8 -> 2.7582624 | AF8: =V8*AD8^2 -> 58.767439 | AG8: =V8*AC8*AC8 -> 243.61259 | AH8: =V8*AC8^2 -> 243.61259 | AI8: =V8*AD8^2 -> 58.767439 | AJ8: =V8*AE8^2 -> 47.787343 | AK8: =AH8-AI8-AJ8 -> 137.05781 | AL8: =3*AI8+AK8-AJ8 -> 265.57278 | AN8: =M8 -> 0.69678348 | AO8: =AN8^3 -> 0.33829342 | AP8: =$AO$2/AO8 -> 1.0313936 | AQ8: =$AQ$2/((AN8/$AN$2)^3) -> 6.281187 | AR8: =-3*$AZ$33*((1-2*AS8)^2.5)*(1+3*(4-$AZ$34)*AS8/2)*AS8 -> 5.2360789 | AS8: =0.5*(1-AP8^0.666666667) -> -0.010410531 | AT8: =(1-2*AS8)^(3.5)*($AZ$27-$AZ$40*AS8)+AR8*3 -> 265.36068 | AU8: =(1-2*AS8)^(3.5)*($AZ$29-$AZ$42*AS8)+AR8*1 -> 47.865089 | AV8: =(1-2*AS8)^(3.5)*($AZ$28-$AZ$41*AS8)+AR8*1 -> 136.96644 | AW8: =AT8-AL8 -> -0.21210676 | AX8: =AU8-AJ8 -> 0.077746641 | AY8: =AV8-AK8 -> -0.091370767 | AZ8: =AR8-A8 -> 0.11380683 | BC8: 0.21334572 | BD8: 0.50523365 | BE8: 0.22376844 | BF8: 0.45559644 | BG8: 0.69699221 | BH8: =BG8^3 -> 0.33859752 | BI8: =$BH$2/BH8 -> 1.0304673 | BJ8: =$BJ$2/((BG8/$BG$2)^3) -> 6.2755457 | BK8: =-3*$BD$33*((1-2*BL8)^2.5)*(1+3*(4-$BD$34)*BL8/2)*BL8 -> 5.1222801 | BL8: =0.5*(1-BI8^0.666666667) -> -0.010104876 | BM8: =BK8-E8 -> 8.1073846e-06 | BN8: =2*BG8/BE8 -> 6.2295844 | BO8: =2*BG8/BF8 -> 3.0596912 | BP8: =2*BG8/BD8 -> 2.7590886 | BQ8: =2*BG8/BC8 -> 6.5339226 | BR8: =BJ8*BN8^2 -> 243.53964 | BS8: =BJ8*BO8^2 -> 58.74984 | BT8: =BJ8*BQ8^2 -> 267.9165 | BU8: =BJ8*BP8^2 -> 47.773032 | BW8: =(1-2*BL8)^(3.5)*($BD$27-$BD$40*BL8)+BK8*3 -> 267.20305 | BX8: =(1-2*BL8)^(3.5)*($BD$29-$BD$42*BL8)+BK8*1 -> 47.596376 | BZ8: =(1-2*BL8)^(3.5)*($BD$28-$BD$41*BL8)+BK8*1 -> 137.43069 | CA8: =BW8-BT8 -> -0.71345559 | CB8: =BX8-BU8 -> -0.17665604 | CC8: =BZ8-BV8 -> 137.43069 | CD8: =(BW8+2*BZ8)/3 -> 180.68814 | CE8: =SQRT(BW8/BJ8) -> 6.5252169 | CF8: =SQRT(BX8/BJ8) -> 2.7539826 | CG8: =SQRT((0.33333334*(BW8+2*BZ8+4*BX8))/BJ8) -> 6.2373857 | CH8: =SQRT((0.3333334*(BW8-BZ8+BX8))/BJ8) -> 3.0693909 | CJ8: =(BW8-BZ8+3*BX8)/5 -> 54.512297 | CK8: =((5*(BW8-BZ8)*BX8)/(3*(BW8-BZ8)+4*BX8)) -> 53.274681 | CL8: =(CJ8+CK8)/2 -> 53.893489 | CN8: =CE8-BQ8 -> -0.0087056436 | CO8: =CF8-BP8 -> -0.0051060303 | CP8: =CG8-BN8 -> 0.0078012549 | CQ8: =CH8-BO8 -> 0.0096997027 | CS8: 265.52084 | CT8: 47.868486 | CU8: 137.06782
A9: 5.7679366 | B9: 210 | C9: 0.1919993 | D9: 0.39099582 | E9: 5.7679366 | F9: 0.21174572 | G9: 0.50423365 | H9: =C9*0.704/0.607 -> 0.22268123 | I9: =D9*0.704/0.607 -> 0.45347786 | J9: =1/((1/(H9^2))-(1.33333333333333/(G9^2))) -> 0.067013107 | K9: =(J9*(E9-E8)+0.5*(E9-E8)*(J8-J9)) -> 0.043524335 | L9: =SUM(K$3:$K9) -> 0.41238615 | M9: =$B$38/((L9*$B$43+1)) -> 0.69594171 | N9: =(6*F9*G9*SQRT(9*(G9^6)*(0.0002^2)+16*(F9^6)*(0.0002)^2))/((4*F9^2 - 3*G9^2)^2) -> 0.00014548021 | O9: =(((E9-E8)/2)^2)*(N9^2+N10^2) -> 4.3650511e-09 | P9: =SUM(O$2:$O9) -> 6.7987857e-08 | Q9: =SQRT(((M36*0.001)^2)+((N36*0.02)^2)+((O36*P9)^2)) -> 0.0010115228 | R9: =M9^3 -> 0.33706883 | S9: =3*Q9/M9*R9 -> 0.0014697472 | T9: =R9/$R$2 -> 0.96605226 | U9: =T9*3*SQRT((Q9/M9)^2)+(0.001/$M$2)^2 -> 0.0042143698 | V9: =$B$40/((M9/$B$38)^3) -> 6.3040068 | W9: =(SQRT((0.02/$V$2)^2+(9*(0.001/$M$2)^2)+(9*(Q9/M9)^2))*V9) -> 0.043655982 | X9: =(1-((V9/$B$40)^0.66666667))/2 -> -0.01164601 | Y9: =(SQRT((Q9/M9)^2 + (0.0002/F9)^2))*#REF! -> #REF! | Z9: =SQRT((Q9/M9)^2 + (0.0002/G9)^2)*AE9 -> 0.0041588313 | AA9: =SQRT((Q9/M9)^2 + (0.0002/H9)^2)*AC9 -> 0.010679519 | AB9: =SQRT((Q9/M9)^2 + (0.0002/I9)^2)*AD9 -> 0.0046620381 | AC9: =2*M9/H9 -> 6.2505645 | AD9: =2*M9/I9 -> 3.0693525 | AE9: =2*M9/G9 -> 2.7603938 | AF9: =V9*AD9^2 -> 59.389576 | AG9: =V9*AC9*AC9 -> 246.29475 | AH9: =V9*AC9^2 -> 246.29475 | AI9: =V9*AD9^2 -> 59.389576 | AJ9: =V9*AE9^2 -> 48.035106 | AK9: =AH9-AI9-AJ9 -> 138.87007 | AL9: =3*AI9+AK9-AJ9 -> 269.00369 | AN9: =M9 -> 0.69594171 | AO9: =AN9^3 -> 0.33706883 | AP9: =$AO$2/AO9 -> 1.0351407 | AQ9: =$AQ$2/((AN9/$AN$2)^3) -> 6.3040068 | AR9: =-3*$AZ$33*((1-2*AS9)^2.5)*(1+3*(4-$AZ$34)*AS9/2)*AS9 -> 5.8925514 | AS9: =0.5*(1-AP9^0.666666667) -> -0.01164601 | AT9: =(1-2*AS9)^(3.5)*($AZ$27-$AZ$40*AS9)+AR9*3 -> 268.90959 | AU9: =(1-2*AS9)^(3.5)*($AZ$29-$AZ$42*AS9)+AR9*1 -> 47.967592 | AV9: =(1-2*AS9)^(3.5)*($AZ$28-$AZ$41*AS9)+AR9*1 -> 138.97512 | AW9: =AT9-AL9 -> -0.094105217 | AX9: =AU9-AJ9 -> -0.067514132 | AY9: =AV9-AK9 -> 0.10505041 | AZ9: =AR9-A9 -> 0.12461482 | BC9: 0.21174572 | BD9: 0.50423365 | BE9: 0.22268123 | BF9: 0.45347786 | BG9: 0.69616709 | BH9: =BG9^3 -> 0.33739642 | BI9: =$BH$2/BH9 -> 1.0341356 | BJ9: =$BJ$2/((BG9/$BG$2)^3) -> 6.297886 | BK9: =-3*$BD$33*((1-2*BL9)^2.5)*(1+3*(4-$BD$34)*BL9/2)*BL9 -> 5.7687227 | BL9: =0.5*(1-BI9^0.666666667) -> -0.011314774 | BM9: =BK9-E9 -> 0.00078618576 | BN9: =2*BG9/BE9 -> 6.2525888 | BO9: =2*BG9/BF9 -> 3.0703466 | BP9: =2*BG9/BD9 -> 2.7612877 | BQ9: =2*BG9/BC9 -> 6.575501 | BR9: =BJ9*BN9^2 -> 246.21501 | BS9: =BJ9*BO9^2 -> 59.370348 | BT9: =BJ9*BQ9^2 -> 272.30304 | BU9: =BJ9*BP9^2 -> 48.019555 | BW9: =(1-2*BL9)^(3.5)*($BD$27-$BD$40*BL9)+BK9*3 -> 270.63052 | BX9: =(1-2*BL9)^(3.5)*($BD$29-$BD$42*BL9)+BK9*1 -> 47.710284 | BZ9: =(1-2*BL9)^(3.5)*($BD$28-$BD$41*BL9)+BK9*1 -> 139.39819 | CA9: =BW9-BT9 -> -1.6725179 | CB9: =BX9-BU9 -> -0.30927091 | CC9: =BZ9-BV9 -> 139.39819 | CD9: =(BW9+2*BZ9)/3 -> 183.1423 | CE9: =SQRT(BW9/BJ9) -> 6.5552761 | CF9: =SQRT(BX9/BJ9) -> 2.7523813 | CG9: =SQRT((0.33333334*(BW9+2*BZ9+4*BX9))/BJ9) -> 6.2594543 | CH9: =SQRT((0.3333334*(BW9-BZ9+BX9))/BJ9) -> 3.077506 | CJ9: =(BW9-BZ9+3*BX9)/5 -> 54.872637 | CK9: =((5*(BW9-BZ9)*BX9)/(3*(BW9-BZ9)+4*BX9)) -> 53.556231 | CL9: =(CJ9+CK9)/2 -> 54.214434 | CN9: =CE9-BQ9 -> -0.020224861 | CO9: =CF9-BP9 -> -0.0089064285 | CP9: =CG9-BN9 -> 0.0068655511 | CQ9: =CH9-BO9 -> 0.0071594292 | CS9: 268.88151 | CT9: 47.962234 | CU9: 138.96893
A10: 6.5857783 | B10: 240 | C10: 0.19084422 | D10: 0.38885471 | E10: 6.5857783 | F10: 0.21074572 | G10: 0.50423365 | H10: =C10*0.704/0.607 -> 0.22134157 | I10: =D10*0.704/0.607 -> 0.45099459 | J10: =1/((1/(H10^2))-(1.33333333333333/(G10^2))) -> 0.065931277 | K10: =(J10*(E10-E9)+0.5*(E10-E9)*(J9-J10)) -> 0.054363734 | L10: =SUM(K$3:$K10) -> 0.46674988 | M10: =$B$38/((L10*$B$43+1)) -> 0.69489315 | N10: =(6*F10*G10*SQRT(9*(G10^6)*(0.0002^2)+16*(F10^6)*(0.0002)^2))/((4*F10^2 - 3*G10^2)^2) -> 0.00014393848 | O10: =(((E10-E9)/2)^2)*(N10^2+N11^2) -> 6.8066341e-09 | P10: =SUM(O$2:$O10) -> 7.4794491e-08 | Q10: =SQRT(((M37*0.001)^2)+((N37*0.02)^2)+((O37*P10)^2)) -> 0.0010130314 | R10: =M10^3 -> 0.33554756 | S10: =3*Q10/M10*R10 -> 0.0014675072 | T10: =R10/$R$2 -> 0.96169224 | U10: =T10*3*SQRT((Q10/M10)^2)+(0.001/$M$2)^2 -> 0.0042079497 | V10: =$B$40/((M10/$B$38)^3) -> 6.3325872 | W10: =(SQRT((0.02/$V$2)^2+(9*(0.001/$M$2)^2)+(9*(Q10/M10)^2))*V10) -> 0.043906156 | X10: =(1-((V10/$B$40)^0.66666667))/2 -> -0.013191274 | Y10: =(SQRT((Q10/M10)^2 + (0.0002/F10)^2))*#REF! -> #REF! | Z10: =SQRT((Q10/M10)^2 + (0.0002/G10)^2)*AE10 -> 0.0041641711 | AA10: =SQRT((Q10/M10)^2 + (0.0002/H10)^2)*AC10 -> 0.010769232 | AB10: =SQRT((Q10/M10)^2 + (0.0002/I10)^2)*AD10 -> 0.004695689 | AC10: =2*M10/H10 -> 6.2789213 | AD10: =2*M10/I10 -> 3.0816031 | AE10: =2*M10/G10 -> 2.7562347 | AF10: =V10*AD10^2 -> 60.136005 | AG10: =V10*AC10*AC10 -> 249.66132 | AH10: =V10*AC10^2 -> 249.66132 | AI10: =V10*AD10^2 -> 60.136005 | AJ10: =V10*AE10^2 -> 48.107589 | AK10: =AH10-AI10-AJ10 -> 141.41772 | AL10: =3*AI10+AK10-AJ10 -> 273.71815 | AN10: =M10 -> 0.69489315 | AO10: =AN10^3 -> 0.33554756 | AP10: =$AO$2/AO10 -> 1.0398337 | AQ10: =$AQ$2/((AN10/$AN$2)^3) -> 6.3325872 | AR10: =-3*$AZ$33*((1-2*AS10)^2.5)*(1+3*(4-$AZ$34)*AS10/2)*AS10 -> 6.7243002 | AS10: =0.5*(1-AP10^0.666666667) -> -0.013191274 | AT10: =(1-2*AS10)^(3.5)*($AZ$27-$AZ$40*AS10)+AR10*3 -> 273.38551 | AU10: =(1-2*AS10)^(3.5)*($AZ$29-$AZ$42*AS10)+AR10*1 -> 48.087675 | AV10: =(1-2*AS10)^(3.5)*($AZ$28-$AZ$41*AS10)+AR10*1 -> 141.51324 | AW10: =AT10-AL10 -> -0.33263799 | AX10: =AU10-AJ10 -> -0.019913456 | AY10: =AV10-AK10 -> 0.095515332 | AZ10: =AR10-A10 -> 0.13852186 | BC10: 0.21074572 | BD10: 0.50423365 | BE10: 0.22134157 | BF10: 0.45099459 | BG10: 0.69514129 | BH10: =BG10^3 -> 0.33590716 | BI10: =$BH$2/BH10 -> 1.0387205 | BJ10: =$BJ$2/((BG10/$BG$2)^3) -> 6.325808 | BK10: =-3*$BD$33*((1-2*BL10)^2.5)*(1+3*(4-$BD$34)*BL10/2)*BL10 -> 6.5857198 | BL10: =0.5*(1-BI10^0.666666667) -> -0.012824951 | BM10: =BK10-E10 -> -5.8548984e-05 | BN10: =2*BG10/BE10 -> 6.2811635 | BO10: =2*BG10/BF10 -> 3.0827035 | BP10: =2*BG10/BD10 -> 2.757219 | BQ10: =2*BG10/BC10 -> 6.5969671 | BR10: =BJ10*BN10^2 -> 249.5722 | BS10: =BJ10*BO10^2 -> 60.114538 | BT10: =BJ10*BQ10^2 -> 275.29901 | BU10: =BJ10*BP10^2 -> 48.090416 | BW10: =(1-2*BL10)^(3.5)*($BD$27-$BD$40*BL10)+BK10*3 -> 274.94226 | BX10: =(1-2*BL10)^(3.5)*($BD$29-$BD$42*BL10)+BK10*1 -> 47.844851 | BZ10: =(1-2*BL10)^(3.5)*($BD$28-$BD$41*BL10)+BK10*1 -> 141.8784 | CA10: =BW10-BT10 -> -0.35675146 | CB10: =BX10-BU10 -> -0.24556414 | CC10: =BZ10-BV10 -> 141.8784 | CD10: =(BW10+2*BZ10)/3 -> 186.23302 | CE10: =SQRT(BW10/BJ10) -> 6.5926913 | CF10: =SQRT(BX10/BJ10) -> 2.7501704 | CG10: =SQRT((0.33333334*(BW10+2*BZ10+4*BX10))/BJ10) -> 6.2868735 | CH10: =SQRT((0.3333334*(BW10-BZ10+BX10))/BJ10) -> 3.0875297 | CJ10: =(BW10-BZ10+3*BX10)/5 -> 55.319682 | CK10: =((5*(BW10-BZ10)*BX10)/(3*(BW10-BZ10)+4*BX10)) -> 53.900553 | CL10: =(CJ10+CK10)/2 -> 54.610117 | CN10: =CE10-BQ10 -> -0.0042757884 | CO10: =CF10-BP10 -> -0.0070486047 | CP10: =CG10-BN10 -> 0.0057100189 | CQ10: =CH10-BO10 -> 0.0048262206 | CS10: 273.54667 | CT10: 48.083272 | CU10: 141.6126
A11: 7.2744872 | B11: 270 | C11: 0.18989876 | D11: 0.38724285 | E11: 7.2744872 | F11: 0.20914572 | G11: 0.50463365 | H11: =C11*0.704/0.607 -> 0.22024501 | I11: =D11*0.704/0.607 -> 0.44912515 | J11: =1/((1/(H11^2))-(1.33333333333333/(G11^2))) -> 0.065022155 | K11: =(J11*(E11-E10)+0.5*(E11-E10)*(J10-J11)) -> 0.045094393 | L11: =SUM(K$3:$K11) -> 0.51184428 | M11: =$B$38/((L11*$B$43+1)) -> 0.69402577 | N11: =(6*F11*G11*SQRT(9*(G11^6)*(0.0002^2)+16*(F11^6)*(0.0002)^2))/((4*F11^2 - 3*G11^2)^2) -> 0.00014137639 | O11: =(((E11-E10)/2)^2)*(N11^2+N12^2) -> 4.6994312e-09 | P11: =SUM(O$2:$O11) -> 7.9493922e-08 | Q11: =SQRT(((M38*0.001)^2)+((N38*0.02)^2)+((O38*P11)^2)) -> 0.0010142807 | R11: =M11^3 -> 0.33429262 | S11: =3*Q11/M11*R11 -> 0.0014656511 | T11: =R11/$R$2 -> 0.95809552 | U11: =T11*3*SQRT((Q11/M11)^2)+(0.001/$M$2)^2 -> 0.0042026301 | V11: =$B$40/((M11/$B$38)^3) -> 6.35636 | W11: =(SQRT((0.02/$V$2)^2+(9*(0.001/$M$2)^2)+(9*(Q11/M11)^2))*V11) -> 0.044114581 | X11: =(1-((V11/$B$40)^0.66666667))/2 -> -0.014474829 | Y11: =(SQRT((Q11/M11)^2 + (0.0002/F11)^2))*#REF! -> #REF! | Z11: =SQRT((Q11/M11)^2 + (0.0002/G11)^2)*AE11 -> 0.0041650642 | AA11: =SQRT((Q11/M11)^2 + (0.0002/H11)^2)*AC11 -> 0.010843687 | AB11: =SQRT((Q11/M11)^2 + (0.0002/I11)^2)*AD11 -> 0.0047217188 | AC11: =2*M11/H11 -> 6.3023063 | AD11: =2*M11/I11 -> 3.0905674 | AE11: =2*M11/G11 -> 2.7506123 | AF11: =V11*AD11^2 -> 60.713451 | AG11: =V11*AC11*AC11 -> 252.46867 | AH11: =V11*AC11^2 -> 252.46867 | AI11: =V11*AD11^2 -> 60.713451 | AJ11: =V11*AE11^2 -> 48.091382 | AK11: =AH11-AI11-AJ11 -> 143.66384 | AL11: =3*AI11+AK11-AJ11 -> 277.71281 | AN11: =M11 -> 0.69402577 | AO11: =AN11^3 -> 0.33429262 | AP11: =$AO$2/AO11 -> 1.0437373 | AQ11: =$AQ$2/((AN11/$AN$2)^3) -> 6.35636 | AR11: =-3*$AZ$33*((1-2*AS11)^2.5)*(1+3*(4-$AZ$34)*AS11/2)*AS11 -> 7.424252 | AS11: =0.5*(1-AP11^0.666666667) -> -0.014474829 | AT11: =(1-2*AS11)^(3.5)*($AZ$27-$AZ$40*AS11)+AR11*3 -> 277.1349 | AU11: =(1-2*AS11)^(3.5)*($AZ$29-$AZ$42*AS11)+AR11*1 -> 48.180437 | AV11: =(1-2*AS11)^(3.5)*($AZ$28-$AZ$41*AS11)+AR11*1 -> 143.64341 | AW11: =AT11-AL11 -> -0.57791028 | AX11: =AU11-AJ11 -> 0.089055392 | AY11: =AV11-AK11 -> -0.020427828 | AZ11: =AR11-A11 -> 0.14976482 | BC11: 0.20914572 | BD11: 0.50463365 | BE11: 0.22024501 | BF11: 0.44912515 | BG11: 0.69429003 | BH11: =BG11^3 -> 0.33467463 | BI11: =$BH$2/BH11 -> 1.0425459 | BJ11: =$BJ$2/((BG11/$BG$2)^3) -> 6.3491046 | BK11: =-3*$BD$33*((1-2*BL11)^2.5)*(1+3*(4-$BD$34)*BL11/2)*BL11 -> 7.2750846 | BL11: =0.5*(1-BI11^0.666666667) -> -0.014083264 | BM11: =BK11-E11 -> 0.00059741533 | BN11: =2*BG11/BE11 -> 6.304706 | BO11: =2*BG11/BF11 -> 3.0917442 | BP11: =2*BG11/BD11 -> 2.7516597 | BQ11: =2*BG11/BC11 -> 6.6392946 | BR11: =BJ11*BN11^2 -> 252.37257 | BS11: =BJ11*BO11^2 -> 60.690342 | BT11: =BJ11*BQ11^2 -> 279.87001 | BU11: =BJ11*BP11^2 -> 48.073077 | BW11: =(1-2*BL11)^(3.5)*($BD$27-$BD$40*BL11)+BK11*3 -> 278.56347 | BX11: =(1-2*BL11)^(3.5)*($BD$29-$BD$42*BL11)+BK11*1 -> 47.950408 | BZ11: =(1-2*BL11)^(3.5)*($BD$28-$BD$41*BL11)+BK11*1 -> 143.96579 | CA11: =BW11-BT11 -> -1.3065439 | CB11: =BX11-BU11 -> -0.12266955 | CC11: =BZ11-BV11 -> 143.96579 | CD11: =(BW11+2*BZ11)/3 -> 188.83168 | CE11: =SQRT(BW11/BJ11) -> 6.6237791 | CF11: =SQRT(BX11/BJ11) -> 2.7481467 | CG11: =SQRT((0.33333334*(BW11+2*BZ11+4*BX11))/BJ11) -> 6.3096128 | CH11: =SQRT((0.3333334*(BW11-BZ11+BX11))/BJ11) -> 3.0957923 | CJ11: =(BW11-BZ11+3*BX11)/5 -> 55.689781 | CK11: =((5*(BW11-BZ11)*BX11)/(3*(BW11-BZ11)+4*BX11)) -> 54.181258 | CL11: =(CJ11+CK11)/2 -> 54.93552 | CN11: =CE11-BQ11 -> -0.015515555 | CO11: =CF11-BP11 -> -0.0035129898 | CP11: =CG11-BN11 -> 0.0049068643 | CQ11: =CH11-BO11 -> 0.0040481839 | CS11: 277.53827 | CT11: 48.178514 | CU11: 143.8788
A12: 7.8340631 | B12: 300 | C12: 0.18915085 | D12: 0.3860701 | E12: 7.8340631 | F12: 0.20814572 | G12: 0.50383365 | H12: =C12*0.704/0.607 -> 0.2193776 | I12: =D12*0.704/0.607 -> 0.44776499 | J12: =1/((1/(H12^2))-(1.33333333333333/(G12^2))) -> 0.064407756 | K12: =(J12*(E12-E11)+0.5*(E12-E11)*(J11-J12)) -> 0.036212932 | L12: =SUM(K$3:$K12) -> 0.54805721 | M12: =$B$38/((L12*$B$43+1)) -> 0.69333079 | N12: =(6*F12*G12*SQRT(9*(G12^6)*(0.0002^2)+16*(F12^6)*(0.0002)^2))/((4*F12^2 - 3*G12^2)^2) -> 0.00014015569 | O12: =(((E12-E11)/2)^2)*(N12^2+N13^2) -> 3.0482081e-09 | P12: =SUM(O$2:$O12) -> 8.254213e-08 | Q12: =SQRT(((M39*0.001)^2)+((N39*0.02)^2)+((O39*P12)^2)) -> 0.0010152824 | R12: =M12^3 -> 0.33328937 | S12: =3*Q12/M12*R12 -> 0.0014641618 | T12: =R12/$R$2 -> 0.95522016 | U12: =T12*3*SQRT((Q12/M12)^2)+(0.001/$M$2)^2 -> 0.0041983618 | V12: =$B$40/((M12/$B$38)^3) -> 6.3754936 | W12: =(SQRT((0.02/$V$2)^2+(9*(0.001/$M$2)^2)+(9*(Q12/M12)^2))*V12) -> 0.044282551 | X12: =(1-((V12/$B$40)^0.66666667))/2 -> -0.015506745 | Y12: =(SQRT((Q12/M12)^2 + (0.0002/F12)^2))*#REF! -> #REF! | Z12: =SQRT((Q12/M12)^2 + (0.0002/G12)^2)*AE12 -> 0.0041756825 | AA12: =SQRT((Q12/M12)^2 + (0.0002/H12)^2)*AC12 -> 0.010903265 | AB12: =SQRT((Q12/M12)^2 + (0.0002/I12)^2)*AD12 -> 0.0047411601 | AC12: =2*M12/H12 -> 6.3208896 | AD12: =2*M12/I12 -> 3.0968513 | AE12: =2*M12/G12 -> 2.7522211 | AF12: =V12*AD12^2 -> 61.144093 | AG12: =V12*AC12*AC12 -> 254.72421 | AH12: =V12*AC12^2 -> 254.72421 | AI12: =V12*AD12^2 -> 61.144093 | AJ12: =V12*AE12^2 -> 48.292584 | AK12: =AH12-AI12-AJ12 -> 145.28754 | AL12: =3*AI12+AK12-AJ12 -> 280.42723 | AN12: =M12 -> 0.69333079 | AO12: =AN12^3 -> 0.33328937 | AP12: =$AO$2/AO12 -> 1.0468791 | AQ12: =$AQ$2/((AN12/$AN$2)^3) -> 6.3754936 | AR12: =-3*$AZ$33*((1-2*AS12)^2.5)*(1+3*(4-$AZ$34)*AS12/2)*AS12 -> 7.9929799 | AS12: =0.5*(1-AP12^0.666666667) -> -0.015506745 | AT12: =(1-2*AS12)^(3.5)*($AZ$27-$AZ$40*AS12)+AR12*3 -> 280.17002 | AU12: =(1-2*AS12)^(3.5)*($AZ$29-$AZ$42*AS12)+AR12*1 -> 48.250342 | AV12: =(1-2*AS12)^(3.5)*($AZ$28-$AZ$41*AS12)+AR12*1 -> 145.37046 | AW12: =AT12-AL12 -> -0.25721382 | AX12: =AU12-AJ12 -> -0.042242088 | AY12: =AV12-AK12 -> 0.082925923 | AZ12: =AR12-A12 -> 0.15891676 | BC12: 0.20814572 | BD12: 0.50383365 | BE12: 0.2193776 | BF12: 0.44776499 | BG12: 0.69360832 | BH12: =BG12^3 -> 0.33368977 | BI12: =$BH$2/BH12 -> 1.0456229 | BJ12: =$BJ$2/((BG12/$BG$2)^3) -> 6.3678435 | BK12: =-3*$BD$33*((1-2*BL12)^2.5)*(1+3*(4-$BD$34)*BL12/2)*BL12 -> 7.834681 | BL12: =0.5*(1-BI12^0.666666667) -> -0.015094285 | BM12: =BK12-E12 -> 0.00061793891 | BN12: =2*BG12/BE12 -> 6.3234198 | BO12: =2*BG12/BF12 -> 3.0980909 | BP12: =2*BG12/BD12 -> 2.7533228 | BQ12: =2*BG12/BC12 -> 6.6646417 | BR12: =BJ12*BN12^2 -> 254.62229 | BS12: =BJ12*BO12^2 -> 61.119627 | BT12: =BJ12*BQ12^2 -> 282.84336 | BU12: =BJ12*BP12^2 -> 48.27326 | BW12: =(1-2*BL12)^(3.5)*($BD$27-$BD$40*BL12)+BK12*3 -> 281.4919 | BX12: =(1-2*BL12)^(3.5)*($BD$29-$BD$42*BL12)+BK12*1 -> 48.030822 | BZ12: =(1-2*BL12)^(3.5)*($BD$28-$BD$41*BL12)+BK12*1 -> 145.65673 | CA12: =BW12-BT12 -> -1.3514693 | CB12: =BX12-BU12 -> -0.24243871 | CC12: =BZ12-BV12 -> 145.65673 | CD12: =(BW12+2*BZ12)/3 -> 190.93512 | CE12: =SQRT(BW12/BJ12) -> 6.6487003 | CF12: =SQRT(BX12/BJ12) -> 2.7464002 | CG12: =SQRT((0.33333334*(BW12+2*BZ12+4*BX12))/BJ12) -> 6.3278132 | CH12: =SQRT((0.3333334*(BW12-BZ12+BX12))/BJ12) -> 3.1023724 | CJ12: =(BW12-BZ12+3*BX12)/5 -> 55.985526 | CK12: =((5*(BW12-BZ12)*BX12)/(3*(BW12-BZ12)+4*BX12)) -> 54.402613 | CL12: =(CJ12+CK12)/2 -> 55.19407 | CN12: =CE12-BQ12 -> -0.015941409 | CO12: =CF12-BP12 -> -0.0069225925 | CP12: =CG12-BN12 -> 0.00439333 | CQ12: =CH12-BO12 -> 0.004281443 | CS12: 280.26394 | CT12: 48.239179 | CU12: 145.42849
A13: 8.5227719 | B13: 330 | C13: 0.18825875 | D13: 0.38477686 | E13: 8.5227719 | F13: 0.20734572 | G13: 0.50403365 | H13: =C13*0.704/0.607 -> 0.21834293 | I13: =D13*0.704/0.607 -> 0.44626509 | J13: =1/((1/(H13^2))-(1.33333333333333/(G13^2))) -> 0.063582325 | K13: =(J13*(E13-E12)+0.5*(E13-E12)*(J12-J13)) -> 0.044073951 | L13: =SUM(K$3:$K13) -> 0.59213116 | M13: =$B$38/((L13*$B$43+1)) -> 0.69248682 | N13: =(6*F13*G13*SQRT(9*(G13^6)*(0.0002^2)+16*(F13^6)*(0.0002)^2))/((4*F13^2 - 3*G13^2)^2) -> 0.00013890838 | O13: =(((E13-E12)/2)^2)*(N13^2+N14^2) -> 4.5241559e-09 | P13: =SUM(O$2:$O13) -> 8.7066286e-08 | Q13: =SQRT(((M40*0.001)^2)+((N40*0.02)^2)+((O40*P13)^2)) -> 0.0010164997 | R13: =M13^3 -> 0.33207374 | S13: =3*Q13/M13*R13 -> 0.0014623506 | T13: =R13/$R$2 -> 0.95173612 | U13: =T13*3*SQRT((Q13/M13)^2)+(0.001/$M$2)^2 -> 0.0041931709 | V13: =$B$40/((M13/$B$38)^3) -> 6.3988325 | W13: =(SQRT((0.02/$V$2)^2+(9*(0.001/$M$2)^2)+(9*(Q13/M13)^2))*V13) -> 0.0444877 | X13: =(1-((V13/$B$40)^0.66666667))/2 -> -0.016764062 | Y13: =(SQRT((Q13/M13)^2 + (0.0002/F13)^2))*#REF! -> #REF! | Z13: =SQRT((Q13/M13)^2 + (0.0002/G13)^2)*AE13 -> 0.0041782275 | AA13: =SQRT((Q13/M13)^2 + (0.0002/H13)^2)*AC13 -> 0.010975162 | AB13: =SQRT((Q13/M13)^2 + (0.0002/I13)^2)*AD13 -> 0.0047631798 | AC13: =2*M13/H13 -> 6.3431118 | AD13: =2*M13/I13 -> 3.1034774 | AE13: =2*M13/G13 -> 2.7477801 | AF13: =V13*AD13^2 -> 61.630817 | AG13: =V13*AC13*AC13 -> 257.45745 | AH13: =V13*AC13^2 -> 257.45745 | AI13: =V13*AD13^2 -> 61.630817 | AJ13: =V13*AE13^2 -> 48.313077 | AK13: =AH13-AI13-AJ13 -> 147.51356 | AL13: =3*AI13+AK13-AJ13 -> 284.09293 | AN13: =M13 -> 0.69248682 | AO13: =AN13^3 -> 0.33207374 | AP13: =$AO$2/AO13 -> 1.0507114 | AQ13: =$AQ$2/((AN13/$AN$2)^3) -> 6.3988325 | AR13: =-3*$AZ$33*((1-2*AS13)^2.5)*(1+3*(4-$AZ$34)*AS13/2)*AS13 -> 8.693199 | AS13: =0.5*(1-AP13^0.666666667) -> -0.016764061 | AT13: =(1-2*AS13)^(3.5)*($AZ$27-$AZ$40*AS13)+AR13*3 -> 283.89323 | AU13: =(1-2*AS13)^(3.5)*($AZ$29-$AZ$42*AS13)+AR13*1 -> 48.329801 | AV13: =(1-2*AS13)^(3.5)*($AZ$28-$AZ$41*AS13)+AR13*1 -> 147.49231 | AW13: =AT13-AL13 -> -0.19970356 | AX13: =AU13-AJ13 -> 0.016724389 | AY13: =AV13-AK13 -> -0.021247334 | AZ13: =AR13-A13 -> 0.17042703 | BC13: 0.20734572 | BD13: 0.50403365 | BE13: 0.21834293 | BF13: 0.44626509 | BG13: 0.69278132 | BH13: =BG13^3 -> 0.3324976 | BI13: =$BH$2/BH13 -> 1.049372 | BJ13: =$BJ$2/((BG13/$BG$2)^3) -> 6.3906754 | BK13: =-3*$BD$33*((1-2*BL13)^2.5)*(1+3*(4-$BD$34)*BL13/2)*BL13 -> 8.5226596 | BL13: =0.5*(1-BI13^0.666666667) -> -0.016324794 | BM13: =BK13-E13 -> -0.00011231548 | BN13: =2*BG13/BE13 -> 6.3458094 | BO13: =2*BG13/BF13 -> 3.1047973 | BP13: =2*BG13/BD13 -> 2.7489487 | BQ13: =2*BG13/BC13 -> 6.6823788 | BR13: =BJ13*BN13^2 -> 257.348 | BS13: =BJ13*BO13^2 -> 61.604617 | BT13: =BJ13*BQ13^2 -> 285.37041 | BU13: =BJ13*BP13^2 -> 48.292538 | BW13: =(1-2*BL13)^(3.5)*($BD$27-$BD$40*BL13)+BK13*3 -> 285.07881 | BX13: =(1-2*BL13)^(3.5)*($BD$29-$BD$42*BL13)+BK13*1 -> 48.123325 | BZ13: =(1-2*BL13)^(3.5)*($BD$28-$BD$41*BL13)+BK13*1 -> 147.73143 | CA13: =BW13-BT13 -> -0.29159663 | CB13: =BX13-BU13 -> -0.16921382 | CC13: =BZ13-BV13 -> 147.73143 | CD13: =(BW13+2*BZ13)/3 -> 193.51389 | CE13: =SQRT(BW13/BJ13) -> 6.6789639 | CF13: =SQRT(BX13/BJ13) -> 2.7441284 | CG13: =SQRT((0.33333334*(BW13+2*BZ13+4*BX13))/BJ13) -> 6.3498807 | CH13: =SQRT((0.3333334*(BW13-BZ13+BX13))/BJ13) -> 3.1103102 | CJ13: =(BW13-BZ13+3*BX13)/5 -> 56.343472 | CK13: =((5*(BW13-BZ13)*BX13)/(3*(BW13-BZ13)+4*BX13)) -> 54.666875 | CL13: =(CJ13+CK13)/2 -> 55.505173 | CN13: =CE13-BQ13 -> -0.0034149602 | CO13: =CF13-BP13 -> -0.0048202923 | CP13: =CG13-BN13 -> 0.004071334 | CQ13: =CH13-BO13 -> 0.0055128983 | CS13: 283.98207 | CT13: 48.316258 | CU13: 147.54533
A14: 9.1253922 | B14: 360 | C14: 0.18750572 | D14: 0.38374368 | E14: 9.1253922 | F14: 0.20634572 | G14: 0.50443365 | H14: =C14*0.704/0.607 -> 0.21746957 | I14: =D14*0.704/0.607 -> 0.44506681 | J14: =1/((1/(H14^2))-(1.33333333333333/(G14^2))) -> 0.062874178 | K14: =(J14*(E14-E13)+0.5*(E14-E13)*(J13-J14)) -> 0.038102624 | L14: =SUM(K$3:$K14) -> 0.63023378 | M14: =$B$38/((L14*$B$43+1)) -> 0.69175885 | N14: =(6*F14*G14*SQRT(9*(G14^6)*(0.0002^2)+16*(F14^6)*(0.0002)^2))/((4*F14^2 - 3*G14^2)^2) -> 0.00013732168 | O14: =(((E14-E13)/2)^2)*(N14^2+N15^2) -> 3.4000951e-09 | P14: =SUM(O$2:$O14) -> 9.0466381e-08 | Q14: =SQRT(((M41*0.001)^2)+((N41*0.02)^2)+((O41*P14)^2)) -> 0.0010175503 | R14: =M14^3 -> 0.33102757 | S14: =3*Q14/M14*R14 -> 0.001460786 | T14: =R14/$R$2 -> 0.94873776 | U14: =T14*3*SQRT((Q14/M14)^2)+(0.001/$M$2)^2 -> 0.0041886867 | V14: =$B$40/((M14/$B$38)^3) -> 6.4190552 | W14: =(SQRT((0.02/$V$2)^2+(9*(0.001/$M$2)^2)+(9*(Q14/M14)^2))*V14) -> 0.044665689 | X14: =(1-((V14/$B$40)^0.66666667))/2 -> -0.017852266 | Y14: =(SQRT((Q14/M14)^2 + (0.0002/F14)^2))*#REF! -> #REF! | Z14: =SQRT((Q14/M14)^2 + (0.0002/G14)^2)*AE14 -> 0.0041784128 | AA14: =SQRT((Q14/M14)^2 + (0.0002/H14)^2)*AC14 -> 0.011036584 | AB14: =SQRT((Q14/M14)^2 + (0.0002/I14)^2)*AD14 -> 0.004781187 | AC14: =2*M14/H14 -> 6.3618911 | AD14: =2*M14/I14 -> 3.1085618 | AE14: =2*M14/G14 -> 2.7427149 | AF14: =V14*AD14^2 -> 62.028336 | AG14: =V14*AC14*AC14 -> 259.80264 | AH14: =V14*AC14^2 -> 259.80264 | AI14: =V14*AD14^2 -> 62.028336 | AJ14: =V14*AE14^2 -> 48.287247 | AK14: =AH14-AI14-AJ14 -> 149.48706 | AL14: =3*AI14+AK14-AJ14 -> 287.28482 | AN14: =M14 -> 0.69175885 | AO14: =AN14^3 -> 0.33102757 | AP14: =$AO$2/AO14 -> 1.054032 | AQ14: =$AQ$2/((AN14/$AN$2)^3) -> 6.4190552 | AR14: =-3*$AZ$33*((1-2*AS14)^2.5)*(1+3*(4-$AZ$34)*AS14/2)*AS14 -> 9.3057089 | AS14: =0.5*(1-AP14^0.666666667) -> -0.017852266 | AT14: =(1-2*AS14)^(3.5)*($AZ$27-$AZ$40*AS14)+AR14*3 -> 287.138 | AU14: =(1-2*AS14)^(3.5)*($AZ$29-$AZ$42*AS14)+AR14*1 -> 48.393433 | AV14: =(1-2*AS14)^(3.5)*($AZ$28-$AZ$41*AS14)+AR14*1 -> 149.34441 | AW14: =AT14-AL14 -> -0.14681631 | AX14: =AU14-AJ14 -> 0.10618585 | AY14: =AV14-AK14 -> -0.14264584 | AZ14: =AR14-A14 -> 0.18031672 | BC14: 0.20634572 | BD14: 0.50443365 | BE14: 0.21746957 | BF14: 0.44506681 | BG14: 0.6920668 | BH14: =BG14^3 -> 0.33146986 | BI14: =$BH$2/BH14 -> 1.0526256 | BJ14: =$BJ$2/((BG14/$BG$2)^3) -> 6.4104899 | BK14: =-3*$BD$33*((1-2*BL14)^2.5)*(1+3*(4-$BD$34)*BL14/2)*BL14 -> 9.1252105 | BL14: =0.5*(1-BI14^0.666666667) -> -0.017391502 | BM14: =BK14-E14 -> -0.00018166014 | BN14: =2*BG14/BE14 -> 6.3647232 | BO14: =2*BG14/BF14 -> 3.1099457 | BP14: =2*BG14/BD14 -> 2.7439359 | BQ14: =2*BG14/BC14 -> 6.7078377 | BR14: =BJ14*BN14^2 -> 259.68704 | BS14: =BJ14*BO14^2 -> 62.000735 | BT14: =BJ14*BQ14^2 -> 288.44055 | BU14: =BJ14*BP14^2 -> 48.26576 | BW14: =(1-2*BL14)^(3.5)*($BD$27-$BD$40*BL14)+BK14*3 -> 288.20851 | BX14: =(1-2*BL14)^(3.5)*($BD$29-$BD$42*BL14)+BK14*1 -> 48.198676 | BZ14: =(1-2*BL14)^(3.5)*($BD$28-$BD$41*BL14)+BK14*1 -> 149.54482 | CA14: =BW14-BT14 -> -0.23204491 | CB14: =BX14-BU14 -> -0.067084386 | CC14: =BZ14-BV14 -> 149.54482 | CD14: =(BW14+2*BZ14)/3 -> 195.76605 | CE14: =SQRT(BW14/BJ14) -> 6.705139 | CF14: =SQRT(BX14/BJ14) -> 2.7420284 | CG14: =SQRT((0.33333334*(BW14+2*BZ14+4*BX14))/BJ14) -> 6.3689364 | CH14: =SQRT((0.3333334*(BW14-BZ14+BX14))/BJ14) -> 3.1171286 | CJ14: =(BW14-BZ14+3*BX14)/5 -> 56.651943 | CK14: =((5*(BW14-BZ14)*BX14)/(3*(BW14-BZ14)+4*BX14)) -> 54.891281 | CL14: =(CJ14+CK14)/2 -> 55.771612 | CN14: =CE14-BQ14 -> -0.0026987065 | CO14: =CF14-BP14 -> -0.0019075558 | CP14: =CG14-BN14 -> 0.0042131623 | CQ14: =CH14-BO14 -> 0.0071829409 | CS14: 287.23461 | CT14: 48.378354 | CU14: 149.39981
... A23: 12.482848 | B23: 630 | C23: 0.18327563 | D23: 0.377551 | E23: 12.482848 | F23: 0.19974572 | G23: 0.50683365 | H23: =C23*0.704/0.607 -> 0.21256349 | I23: =D23*0.704/0.607 -> 0.43788452 | J23: =1/((1/(H23^2))-(1.33333333333333/(G23^2))) -> 0.059026243 | K23: =(J23*(E23-E22)+0.5*(E23-E22)*(J22-J23)) -> 0.01018118 | L23: =SUM(K$3:$K23) -> 0.83525486 | M23: =$B$38/((L23*$B$43+1)) -> 0.68786793 | N23: =(6*F23*G23*SQRT(9*(G23^6)*(0.0002^2)+16*(F23^6)*(0.0002)^2))/((4*F23^2 - 3*G23^2)^2) -> 0.00012750678 | O23: =(((E23-E22)/2)^2)*(N23^2+N24^2) -> 1.2049191e-10 | P23: =SUM(O$2:$O23) -> 1.0272515e-07 | Q23: =SQRT(((M50*0.001)^2)+((N50*0.02)^2)+((O50*P23)^2)) -> 0.001023175 | R23: =M23^3 -> 0.32547317 | S23: =3*Q23/M23*R23 -> 0.0014523835 | T23: =R23/$R$2 -> 0.93281863 | U23: =T23*3*SQRT((Q23/M23)^2)+(0.001/$M$2)^2 -> 0.0041646046 | V23: =$B$40/((M23/$B$38)^3) -> 6.5286003 | W23: =(SQRT((0.02/$V$2)^2+(9*(0.001/$M$2)^2)+(9*(Q23/M23)^2))*V23) -> 0.045633536 | X23: =(1-((V23/$B$40)^0.66666667))/2 -> -0.023727281 | Y23: =(SQRT((Q23/M23)^2 + (0.0002/F23)^2))*#REF! -> #REF! | Z23: =SQRT((Q23/M23)^2 + (0.0002/G23)^2)*AE23 -> 0.0041771795 | AA23: =SQRT((Q23/M23)^2 + (0.0002/H23)^2)*AC23 -> 0.011391325 | AB23: =SQRT((Q23/M23)^2 + (0.0002/I23)^2)*AD23 -> 0.0048886158 | AC23: =2*M23/H23 -> 6.4721173 | AD23: =2*M23/I23 -> 3.1417778 | AE23: =2*M23/G23 -> 2.7143736 | AF23: =V23*AD23^2 -> 64.442298 | AG23: =V23*AC23*AC23 -> 273.47198 | AH23: =V23*AC23^2 -> 273.47198 | AI23: =V23*AD23^2 -> 64.442298 | AJ23: =V23*AE23^2 -> 48.101578 | AK23: =AH23-AI23-AJ23 -> 160.92811 | AL23: =3*AI23+AK23-AJ23 -> 306.15343 | AN23: =M23 -> 0.68786793 | AO23: =AN23^3 -> 0.32547317 | AP23: =$AO$2/AO23 -> 1.0720198 | AQ23: =$AQ$2/((AN23/$AN$2)^3) -> 6.5286003 | AR23: =-3*$AZ$33*((1-2*AS23)^2.5)*(1+3*(4-$AZ$34)*AS23/2)*AS23 -> 12.717451 | AS23: =0.5*(1-AP23^0.666666667) -> -0.023727281 | AT23: =(1-2*AS23)^(3.5)*($AZ$27-$AZ$40*AS23)+AR23*3 -> 305.01651 | AU23: =(1-2*AS23)^(3.5)*($AZ$29-$AZ$42*AS23)+AR23*1 -> 48.651726 | AV23: =(1-2*AS23)^(3.5)*($AZ$28-$AZ$41*AS23)+AR23*1 -> 159.59736 | AW23: =AT23-AL23 -> -1.1369138 | AX23: =AU23-AJ23 -> 0.55014824 | AY23: =AV23-AK23 -> -1.3307465 | AZ23: =AR23-A23 -> 0.23460349 | BC23: 0.19974572 | BD23: 0.50683365 | BE23: 0.21256349 | BF23: 0.43788452 | BG23: 0.68786793 | BH23: =BG23^3 -> 0.32547317 | BI23: =$BH$2/BH23 -> 1.0720198 | BJ23: =$BJ$2/((BG23/$BG$2)^3) -> 6.5286003 | BK23: =-3*$BD$33*((1-2*BL23)^2.5)*(1+3*(4-$BD$34)*BL23/2)*BL23 -> 12.823239 | BL23: =0.5*(1-BI23^0.666666667) -> -0.023727281 | BM23: =BK23-E23 -> 0.34039091 | BN23: =2*BG23/BE23 -> 6.4721173 | BO23: =2*BG23/BF23 -> 3.1417778 | BP23: =2*BG23/BD23 -> 2.7143736 | BQ23: =2*BG23/BC23 -> 6.887436 | BR23: =BJ23*BN23^2 -> 273.47198 | BS23: =BJ23*BO23^2 -> 64.442298 | BT23: =BJ23*BQ23^2 -> 309.69574 | BU23: =BJ23*BP23^2 -> 48.101578 | BW23: =(1-2*BL23)^(3.5)*($BD$27-$BD$40*BL23)+BK23*3 -> 307.18739 | BX23: =(1-2*BL23)^(3.5)*($BD$29-$BD$42*BL23)+BK23*1 -> 48.550177 | BZ23: =(1-2*BL23)^(3.5)*($BD$28-$BD$41*BL23)+BK23*1 -> 160.6036 | CA23: =BW23-BT23 -> -2.5083503 | CB23: =BX23-BU23 -> 0.44859964 | CC23: =BZ23-BV23 -> 160.6036 | CD23: =(BW23+2*BZ23)/3 -> 209.46487 | CE23: =SQRT(BW23/BJ23) -> 6.8594872 | CF23: =SQRT(BX23/BJ23) -> 2.7270015 | CG23: =SQRT((0.33333334*(BW23+2*BZ23+4*BX23))/BJ23) -> 6.480708 | CH23: =SQRT((0.3333334*(BW23-BZ23+BX23))/BJ23) -> 3.1564274 | CJ23: =(BW23-BZ23+3*BX23)/5 -> 58.446864 | CK23: =((5*(BW23-BZ23)*BX23)/(3*(BW23-BZ23)+4*BX23)) -> 56.129392 | CL23: =(CJ23+CK23)/2 -> 57.288128 | CN23: =CE23-BQ23 -> -0.027948763 | CO23: =CF23-BP23 -> 0.012627872 | CP23: =CG23-BN23 -> 0.0085906432 | CQ23: =CH23-BO23 -> 0.014649608 | CS23: 306.26429 | CT23: 48.643794 | CU23: 160.29975
E25: =0.2/E5*100 -> 8.0109925 | F25: =0.0002/F23*100 -> 0.1001273 | M25: =0.001/0.704*100 -> 0.14204545 | V25: =0.04/6.09*100 -> 0.65681445
AG26: %uncert min | AY26: CK No Vp100 | BC26: FS No Vp100 | BL26: NO VP100
B27: v111 | AG27: %uncert max | AY27: C11 | AZ27: 236.4933 | BC27: C11 | BD27: 239.50441 | BF27: 235 | BG27: 200 | BH27: 260 | BI27: 100 | BJ27: 200 | BK27: 235
A28: Width then radius | B28: 2.34 | J28: D | K28: K | L28: I | M28: L term | N28: rho term | O28: Int term | X28: =1.42/0.2298 -> 6.1792863 | AK28: =235*3 -> 705 | AY28: C12 | AZ28: 120.75389 | BC28: C12 | BD28: 121.66535 | BF28: 120 | BG28: 100 | BH28: 140 | BI28: 100 | BJ28: 200 | BK28: 120
A29: Length initial | B29: 0.623 | C29: 0.607 | J29: =12*$B$31*$B$38^2+$K$29*L2 -> 36.219617 | K29: =C34 -> 1.016974 | L29: sum cook | M29: =36*$B$40*($B$38^2)*(4*$B$40*$B$38^2 + $K$29*L2)/J29^2 -> 1 | N29: =36*$B$40*($B$38^2)*(4*$B$40*$B$38^2 + $K$29*M2)/K29^2 -> 1343.6535 | O29: =-(12*$B$40*$K$29*$D$38^3)/(J29^2) -> -0.019766904 | AK29: =165*2 -> 330 | AY29: C44 | AZ29: 46.785203 | BC29: C44 | BD29: 46.445135 | BF29: 45 | BG29: 40 | BH29: 60 | BI29: 100 | BJ29: 200 | BK29: 46
A30: alpha thermal expansion | B30: =0.000046 -> 4.6e-05 | F30: Value | G30: VP100 or 110 or VS110 | H30: bench | J30: =12*$B$31*$B$38^2+$K$29*L3 -> 36.230005 | M30: =36*$B$40*($B$38^2)*(4*$B$40*$B$38^2 + $K$29*L3)/J30^2 -> 1.0002866 | N30: =(12*$K$29*L3*$D$38^3)/(J30^2) -> 3.313455e-05 | O30: =-(12*$B$40*$K$29*$D$38^3)/(J30^2) -> -0.019755571 | AK30: =235*2+235 -> 705 | AY30: C11' | AZ30: 5.6166349 | BC30: C11' | BD30: 5.5088143 | BF30: 5 | BG30: 4 | BH30: 2 | BI30: 2 | BJ30: 1 | BK30: 5.5
A31: density OG | B31: 6.09 | E31: C11 | F31: 231 | G31: 6.1588176 | H31: 0.23121321 | J31: =12*$B$31*$B$38^2+$K$29*L4 -> 36.34484 | M31: =36*$B$40*($B$38^2)*(4*$B$40*$B$38^2 + $K$29*L4)/J31^2 -> 1.0034217 | N31: =(12*$K$29*L4*$D$38^3)/(J31^2) -> 0.00039691538 | O31: =-(12*$B$40*$K$29*$D$38^3)/(J31^2) -> -0.019630928 | AK31: =330+642 -> 972 | AY31: C12' | AZ31: 3.1320662 | BC31: C12' | BD31: 3.1112012 | BF31: 3 | BG31: 1 | BH31: 2 | BI31: 2 | BJ31: 1 | BK31: 3
A32: Gamma gruneisen | B32: 1.23 | E32: C12 VP | F32: 120 | G32: 5.9398555 | H32: 0.23973647 | J32: =12*$B$31*$B$38^2+$K$29*L5 -> 36.408432 | M32: =36*$B$40*($B$38^2)*(4*$B$40*$B$38^2 + $K$29*L5)/J32^2 -> 1.0051322 | N32: =(12*$K$29*L5*$D$38^3)/(J32^2) -> 0.00059639101 | O32: =-(12*$B$40*$K$29*$D$38^3)/(J32^2) -> -0.019562413 | AK32: =AK31-AK30 -> 267 | AY32: C44' | AZ32: 0.25382393 | BC32: C44' | BD32: 0.27066092 | BF32: 0.2 | BG32: 1 | BH32: 2 | BI32: 2 | BJ32: 1 | BK32: 0.2
A33: T temp K | B33: 300 | E33: C12 VS | F33: 120 | G33: 2.9070625 | H33: 0.48984154 | J33: =12*$B$31*$B$38^2+$K$29*L6 -> 36.476877 | M33: =36*$B$40*($B$38^2)*(4*$B$40*$B$38^2 + $K$29*L6)/J33^2 -> 1.0069532 | N33: =(12*$K$29*L6*$D$38^3)/(J33^2) -> 0.00080953548 | O33: =-(12*$B$40*$K$29*$D$38^3)/(J33^2) -> -0.019489068 | AY33: KS0 | AZ33: =(AZ27+2*AZ28)/3 -> 159.3337 | BC33: KS0 | BD33: =(BD27+2*BD28)/3 -> 160.94504 | BF33: 239.41295 | BG33: 239.81063 | BH33: 239.3304 | BI33: 240.99872 | BJ33: 240.77197 | BK33: 239.50456 | BL33: 236.4308
A34: >scalar> | B34: =C34/C35 -> 0.035853802 | C34: =1+B30*B32*B33 -> 1.016974 | E34: C44 | F34: 43.4 | G34: 2.6695387 | H34: 0.5334255 | J34: =12*$B$31*$B$38^2+$K$29*L7 -> 36.546903 | M34: =36*$B$40*($B$38^2)*(4*$B$40*$B$38^2 + $K$29*L7)/J34^2 -> 1.0087948 | N34: =(12*$K$29*L7*$D$38^3)/(J34^2) -> 0.001025946 | O34: =-(12*$B$40*$K$29*$D$38^3)/(J34^2) -> -0.019414456 | AY34: K'S0 | AZ34: =(AZ30+2*AZ31)/3 -> 3.9602557 | BC34: K'S0 | BD34: =(BD30+2*BD31)/3 -> 3.9104055 | BF34: 121.25174 | BG34: 121.62264 | BH34: 121.00127 | BI34: 128.19979 | BJ34: 131.44859 | BK34: 121.66542 | BL34: 120.73087
C35: =12*B31*(B29^2) -> 28.364467 | J35: =12*$B$31*$B$38^2+$K$29*L8 -> 36.59474 | M35: =36*$B$40*($B$38^2)*(4*$B$40*$B$38^2 + $K$29*L8)/J35^2 -> 1.0100406 | N35: =(12*$K$29*L8*$D$38^3)/(J35^2) -> 0.001172831 | O35: =-(12*$B$40*$K$29*$D$38^3)/(J35^2) -> -0.019363731 | AY35: All sumsq | AZ35: =AZ39+AZ37+AZ38+AZ36 -> 2.0863166 | BC35: All sumsq | BD35: =BD39+BD37+BD38+BD36 -> 226418.67 | BF35: 46.308635 | BG35: 46.320612 | BH35: 46.450926 | BI35: 45.769308 | BJ35: 45.964669 | BK35: 46.445135 | BL35: 46.82052
B36: V100 | J36: =12*$B$31*$B$38^2+$K$29*L9 -> 36.639003 | M36: =36*$B$40*($B$38^2)*(4*$B$40*$B$38^2 + $K$29*L9)/J36^2 -> 1.0111844 | N36: =(12*$K$29*L9*$D$38^3)/(J36^2) -> 0.0013080545 | O36: =-(12*$B$40*$K$29*$D$38^3)/(J36^2) -> -0.019316973 | AY36: FSP | AZ36: =SUMSQ(AZ6:AZ16) -> 0.24879468 | BC36: FSP | BD36: =SUMSQ(BM6:BM16) -> 1.5149787e-06 | BF36: 5.5251396 | BG36: 5.4676446 | BH36: 5.5416222 | BI36: 5.2609687 | BJ36: 5.2688268 | BK36: 5.5088145 | BL36: 5.7092963
A37: Width then radius | B37: 2.34 | C37: =B37/2 -> 1.17 | J37: =12*$B$31*$B$38^2+$K$29*L10 -> 36.69429 | M37: =36*$B$40*($B$38^2)*(4*$B$40*$B$38^2 + $K$29*L10)/J37^2 -> 1.0126012 | N37: =(12*$K$29*L10*$D$38^3)/(J37^2) -> 0.0014760339 | O37: =-(12*$B$40*$K$29*$D$38^3)/(J37^2) -> -0.019258808 | AY37: C11 | AZ37: =SUMSQ(AW6:AW16) -> 1.715565 | BC37: C11 | BD37: =SUMSQ(CA6:CA16) -> 8.6624831 | BF37: 3.1712401 | BG37: 3.1257255 | BH37: 3.2089756 | BI37: 2.1833803 | BJ37: 1.7406861 | BK37: 3.1112012 | BL37: 3.1848805
A38: Length initial | B38: 0.704 | C38: mm | D38: 0.704 | J38: =12*$B$31*$B$38^2+$K$29*L11 -> 36.74015 | M38: =36*$B$40*($B$38^2)*(4*$B$40*$B$38^2 + $K$29*L11)/J38^2 -> 1.0137665 | N38: =(12*$K$29*L11*$D$38^3)/(J38^2) -> 0.0016146005 | O38: =-(12*$B$40*$K$29*$D$38^3)/(J38^2) -> -0.019210759 | AY38: C12 | AZ38: =SUMSQ(AY6:AY16) -> 0.071503159 | BC38: C12 | BD38: =SUMSQ(CC6:CC16) -> 226409.43 | BF38: 0.2891672 | BG38: 0.28755684 | BH38: 0.26876319 | BI38: 0.3695593 | BJ38: 0.34773349 | BK38: 0.27066092 | BL38: 0.24843305
A39: alpha thermal expansion | B39: =0.000046 -> 4.6e-05 | C39: m/m C | J39: =12*$B$31*$B$38^2+$K$29*L12 -> 36.776977 | M39: =36*$B$40*($B$38^2)*(4*$B$40*$B$38^2 + $K$29*L12)/J39^2 -> 1.0146958 | N39: =(12*$K$29*L12*$D$38^3)/(J39^2) -> 0.0017253726 | O39: =-(12*$B$40*$K$29*$D$38^3)/(J39^2) -> -0.019172304 | AY39: C44 | AZ39: =SUMSQ(AX6:AX16) -> 0.050453778 | BC39: C44 | BD39: =SUMSQ(CB6:CB16) -> 0.5775294
A40: density OG | B40: 6.09 | C40: g/cm^3 | J40: =12*$B$31*$B$38^2+$K$29*L13 -> 36.821799 | M40: =36*$B$40*($B$38^2)*(4*$B$40*$B$38^2 + $K$29*L13)/J40^2 -> 1.015819 | N40: =(12*$K$29*L13*$D$38^3)/(J40^2) -> 0.001859589 | O40: =-(12*$B$40*$K$29*$D$38^3)/(J40^2) -> -0.019125657 | AY40: C11a | AZ40: =3*AZ33*(AZ30-3)-7*AZ27 -> -404.69879 | BC40: C11a | BD40: =3*BD33*(BD30-3)-7*BD27 -> -465.18722 | BF40: We minimzed the difference in velocities and pressure by fitting the length and Cij0 and Cij0'
A41: Gamma gruneisen | B41: 1.23 | J41: =12*$B$31*$B$38^2+$K$29*L14 -> 36.860549 | M41: =36*$B$40*($B$38^2)*(4*$B$40*$B$38^2 + $K$29*L14)/J41^2 -> 1.0167833 | N41: =(12*$K$29*L14*$D$38^3)/(J41^2) -> 0.0019750912 | O41: =-(12*$B$40*$K$29*$D$38^3)/(J41^2) -> -0.019085466 | AY41: C12a | AZ41: =3*AZ33*(AZ31-1)-7*AZ28 -> 173.8527 | BC41: C12a | BD41: =3*BD33*(BD31-1)-7*BD28 -> 167.70459
A42: T temp K | B42: 300 | J42: =12*$B$31*$B$38^2+$K$29*L15 -> 36.887981 | M42: =36*$B$40*($B$38^2)*(4*$B$40*$B$38^2 + $K$29*L15)/J42^2 -> 1.0174622 | N42: =(12*$K$29*L15*$D$38^3)/(J42^2) -> 0.0020565637 | O42: =-(12*$B$40*$K$29*$D$38^3)/(J42^2) -> -0.019057091 | AY42: C44a | AZ42: =3*AZ33*(AZ32-1)-7*AZ29 -> -684.16939 | BC42: C44a | BD42: =3*BD33*(BD32-1)-7*BD29 -> -677.26646
A43: >scalar> | B43: =C43/C44 -> 0.028077989 | C43: =1+B39*B41*B42 -> 1.016974 | J43: =12*$B$31*$B$38^2+$K$29*L16 -> 36.923371 | M43: =36*$B$40*($B$38^2)*(4*$B$40*$B$38^2 + $K$29*L16)/J43^2 -> 1.0183333 | N43: =(12*$K$29*L16*$D$38^3)/(J43^2) -> 0.0021613096 | O43: =-(12*$B$40*$K$29*$D$38^3)/(J43^2) -> -0.019020577 | BC43: VP100
C44: =12*B40*(B38^2) -> 36.219617 | J44: =12*$B$31*$B$38^2+$K$29*L17 -> 36.955732 | M44: =36*$B$40*($B$38^2)*(4*$B$40*$B$38^2 + $K$29*L17)/J44^2 -> 1.0191253 | N44: =(12*$K$29*L17*$D$38^3)/(J44^2) -> 0.0022567364 | O44: =-(12*$B$40*$K$29*$D$38^3)/(J44^2) -> -0.01898728 | BC44: VS100
A45: delta C11 | B45: 3 | J45: =12*$B$31*$B$38^2+$K$29*L18 -> 36.974455 | M45: =36*$B$40*($B$38^2)*(4*$B$40*$B$38^2 + $K$29*L18)/J45^2 -> 1.0195816 | N45: =(12*$K$29*L18*$D$38^3)/(J45^2) -> 0.002311796 | O45: =-(12*$B$40*$K$29*$D$38^3)/(J45^2) -> -0.018968055 | BC45: VP111
A46: delta C12/C44 | B46: 1 | J46: =12*$B$31*$B$38^2+$K$29*L19 -> 36.987761 | M46: =36*$B$40*($B$38^2)*(4*$B$40*$B$38^2 + $K$29*L19)/J46^2 -> 1.0199049 | N46: =(12*$K$29*L19*$D$38^3)/(J46^2) -> 0.002350854 | O46: =-(12*$B$40*$K$29*$D$38^3)/(J46^2) -> -0.01895441 | BC46: VS111
